Workbook

Sheet Deckbl.
A5: ICRA Schwap e.U.
B8: Verkehrszählungsort : | C8: Karl-Wurmb-Straße / Fanny-von-Lehnert-Straße (Salzburg)
B10: Lfd. Nummer :
B11: Zählzeit : | C11: 7-19 | H11: Datum : | I11: 44817
B12: Sachbearbeiter : | C12: ICRA / Schwap | H12: Wetter : | I12: Sonnig 10-26°
B14: Anmerkungen :

Sheet R1
A3: ICRA Schwap e.U.
A4: VERKEHRSZÄHLUNG - PKW-Einheiten
A5: Datum : | J5: Lfd. Nummer : | K5: 0
A6: ='Deckbl.'!I11 -> 44817 | J6: Wetter : | K6: ='Deckbl.'!I12 -> Sonnig 10-26°
B7: Verkehrszählung : | C7: ='Deckbl.'!C8 -> Karl-Wurmb-Straße / Fanny-von-Lehnert-Straße (Salzburg)
B8: Zählstelle : | I8: Sachbearbeiter : | J8: ICRA / Schwap
B9: Richtung : | C9: R1 | I9: Uhrzeit : | J9: ='Deckbl.'!C11 -> 7-19
B10: Bemerkung : | I10: Dateiname:
A11: Faktoren | B11: 0.5 | C11: 1 | D11: ='Faktoren PKW-E'!B16 -> 1 | E11: 1.5 | F11: 1.5 | G11: 1.5 | H11: 2 | I11: 1.5
C12: einsp. | D12: PKW | E12: Lin. | F12: Reis. | H12: LKW + | I12: sonst. | J12: PKW-E | K12: PKW-E | L12: PKW-E | M12: KFZ
A13: Zeit | B13: Rad | C13: KFZ | D13: Kombi | E13: Bus | F13: Bus | G13: LKW | H13: Anh. | I13: KFZ | J13: / 15 min | K13: / 30 min | L13: / 1 Std. | M13: / 1 Std.
A14: 6:00-6:15 | J14: =SUMPRODUCT(B14:I14,$B$11:$I$11) -> 0
A15: 6:15-6:30 | J15: =SUMPRODUCT(B15:I15,$B$11:$I$11) -> 0 | K15: =J15+J14 -> 0
A16: 6:30-6:45 | J16: =SUMPRODUCT(B16:I16,$B$11:$I$11) -> 0
A17: 6:45-7:00 | J17: =SUMPRODUCT(B17:I17,$B$11:$I$11) -> 0 | K17: =J17+J16 -> 0 | L17: =SUM(J14:J17) -> 0 | M17: =SUM(C14:I17) -> 0
A18: 7:00-7:15 | B18: 1 | C18: 1 | D18: 35 | E18: 0 | F18: 0 | G18: 0 | H18: 0 | I18: 0 | J18: =SUMPRODUCT(B18:I18,$B$11:$I$11) -> 36.5
A19: 7:15-7:30 | B19: 1 | C19: 3 | D19: 25 | E19: 0 | F19: 0 | G19: 0 | H19: 0 | I19: 0 | J19: =SUMPRODUCT(B19:I19,$B$11:$I$11) -> 28.5 | K19: =J19+J18 -> 65
A20: 7:30-7:45 | B20: 2 | C20: 2 | D20: 33 | E20: 0 | F20: 0 | G20: 1 | H20: 0 | I20: 0 | J20: =SUMPRODUCT(B20:I20,$B$11:$I$11) -> 37.5
A21: 7:45-8:00 | B21: 2 | C21: 1 | D21: 34 | E21: 0 | F21: 0 | G21: 2 | H21: 0 | I21: 0 | J21: =SUMPRODUCT(B21:I21,$B$11:$I$11) -> 39 | K21: =J21+J20 -> 76.5 | L21: =SUM(J18:J21) -> 141.5 | M21: =SUM(C18:I21) -> 137
A22: 8:00-8:15 | B22: 1 | C22: 0 | D22: 39 | E22: 1 | F22: 0 | G22: 0 | H22: 0 | I22: 0 | J22: =SUMPRODUCT(B22:I22,$B$11:$I$11) -> 41
A23: 8:15-8:30 | B23: 2 | C23: 0 | D23: 36 | E23: 0 | F23: 0 | G23: 1 | H23: 0 | I23: 0 | J23: =SUMPRODUCT(B23:I23,$B$11:$I$11) -> 38.5 | K23: =J23+J22 -> 79.5
A24: 8:30-8:45 | B24: 1 | C24: 1 | D24: 32 | E24: 2 | F24: 1 | G24: 1 | H24: 0 | I24: 0 | J24: =SUMPRODUCT(B24:I24,$B$11:$I$11) -> 39.5
A25: 8:45-9:00 | B25: 1 | C25: 0 | D25: 24 | E25: 0 | F25: 0 | G25: 1 | H25: 0 | I25: 0 | J25: =SUMPRODUCT(B25:I25,$B$11:$I$11) -> 26 | K25: =J25+J24 -> 65.5 | L25: =SUM(J22:J25) -> 145 | M25: =SUM(C22:I25) -> 139
A26: 9:00-9:15 | B26: 0 | C26: 0 | D26: 21 | E26: 0 | F26: 0 | G26: 1 | H26: 0 | I26: 0 | J26: =SUMPRODUCT(B26:I26,$B$11:$I$11) -> 22.5
A27: 9:15-9:30 | B27: 0 | C27: 0 | D27: 39 | E27: 0 | F27: 0 | G27: 1 | H27: 0 | I27: 0 | J27: =SUMPRODUCT(B27:I27,$B$11:$I$11) -> 40.5 | K27: =J27+J26 -> 63
A28: 9:30-9:45 | B28: 0 | C28: 2 | D28: 25 | E28: 0 | F28: 0 | G28: 0 | H28: 0 | I28: 0 | J28: =SUMPRODUCT(B28:I28,$B$11:$I$11) -> 27
A29: 9:45-10:00 | B29: 0 | C29: 0 | D29: 35 | E29: 0 | F29: 0 | G29: 0 | H29: 0 | I29: 0 | J29: =SUMPRODUCT(B29:I29,$B$11:$I$11) -> 35 | K29: =J29+J28 -> 62 | L29: =SUM(J26:J29) -> 125 | M29: =SUM(C26:I29) -> 124
A30: 10:00-10:15 | B30: 1 | C30: 0 | D30: 21 | E30: 0 | F30: 0 | G30: 1 | H30: 0 | I30: 0 | J30: =SUMPRODUCT(B30:I30,$B$11:$I$11) -> 23
A31: 10:15-10:30 | B31: 0 | C31: 0 | D31: 30 | E31: 0 | F31: 0 | G31: 0 | H31: 0 | I31: 0 | J31: =SUMPRODUCT(B31:I31,$B$11:$I$11) -> 30 | K31: =J31+J30 -> 53
A32: 10:30-10:45 | B32: 1 | C32: 0 | D32: 21 | E32: 1 | F32: 0 | G32: 1 | H32: 0 | I32: 0 | J32: =SUMPRODUCT(B32:I32,$B$11:$I$11) -> 24.5
A33: 10:45-11:00 | B33: 2 | C33: 1 | D33: 19 | E33: 0 | F33: 0 | G33: 1 | H33: 0 | I33: 0 | J33: =SUMPRODUCT(B33:I33,$B$11:$I$11) -> 22.5 | K33: =J33+J32 -> 47 | L33: =SUM(J30:J33) -> 100 | M33: =SUM(C30:I33) -> 96
A34: 11:00-11:15 | B34: 0 | C34: 0 | D34: 22 | E34: 0 | F34: 0 | G34: 0 | H34: 0 | I34: 0 | J34: =SUMPRODUCT(B34:I34,$B$11:$I$11) -> 22
A35: 11:15-11:30 | B35: 0 | C35: 0 | D35: 31 | E35: 0 | F35: 0 | G35: 2 | H35: 0 | I35: 0 | J35: =SUMPRODUCT(B35:I35,$B$11:$I$11) -> 34 | K35: =J35+J34 -> 56
A36: 11:30-11:45 | B36: 0 | C36: 3 | D36: 31 | E36: 0 | F36: 0 | G36: 0 | H36: 0 | I36: 0 | J36: =SUMPRODUCT(B36:I36,$B$11:$I$11) -> 34
A37: 11:45-12:00 | B37: 1 | C37: 3 | D37: 25 | E37: 0 | F37: 0 | G37: 0 | H37: 0 | I37: 0 | J37: =SUMPRODUCT(B37:I37,$B$11:$I$11) -> 28.5 | K37: =J37+J36 -> 62.5 | L37: =SUM(J34:J37) -> 118.5 | M37: =SUM(C34:I37) -> 117
A38: 12:00-12:15 | B38: 1 | C38: 1 | D38: 24 | E38: 0 | F38: 0 | G38: 0 | H38: 0 | I38: 0 | J38: =SUMPRODUCT(B38:I38,$B$11:$I$11) -> 25.5
A39: 12:15-12:30 | B39: 1 | C39: 0 | D39: 23 | E39: 0 | F39: 0 | G39: 0 | H39: 0 | I39: 0 | J39: =SUMPRODUCT(B39:I39,$B$11:$I$11) -> 23.5 | K39: =J39+J38 -> 49
A40: 12:30-12:45 | B40: 2 | C40: 3 | D40: 33 | E40: 0 | F40: 0 | G40: 0 | H40: 0 | I40: 0 | J40: =SUMPRODUCT(B40:I40,$B$11:$I$11) -> 37
A41: 12:45-13:00 | B41: 2 | C41: 1 | D41: 19 | E41: 0 | F41: 0 | G41: 1 | H41: 0 | I41: 0 | J41: =SUMPRODUCT(B41:I41,$B$11:$I$11) -> 22.5 | K41: =J41+J40 -> 59.5 | L41: =SUM(J38:J41) -> 108.5 | M41: =SUM(C38:I41) -> 105
A42: 13:00-13:15 | B42: 2 | C42: 2 | D42: 24 | E42: 0 | F42: 0 | G42: 0 | H42: 0 | I42: 0 | J42: =SUMPRODUCT(B42:I42,$B$11:$I$11) -> 27
...

Sheet R2
A3: ICRA Schwap e.U.
A4: VERKEHRSZÄHLUNG - PKW-Einheiten
A5: Datum : | J5: Lfd. Nummer : | K5: 0
A6: ='Deckbl.'!I11 -> 44817 | J6: Wetter : | K6: ='Deckbl.'!I12 -> Sonnig 10-26°
B7: Verkehrszählung : | C7: ='Deckbl.'!C8 -> Karl-Wurmb-Straße / Fanny-von-Lehnert-Straße (Salzburg)
B8: Zählstelle : | I8: Sachbearbeiter : | J8: ICRA / Schwap
B9: Richtung : | C9: R2 | I9: Uhrzeit : | J9: ='Deckbl.'!C11 -> 7-19
B10: Bemerkung : | I10: Dateiname:
A11: Faktoren | B11: 0.5 | C11: 1 | D11: ='Faktoren PKW-E'!B16 -> 1 | E11: 1.5 | F11: 1.5 | G11: 1.5 | H11: 2 | I11: 1.5
C12: einsp. | D12: PKW | E12: Lin. | F12: Reis. | H12: LKW + | I12: sonst. | J12: PKW-E | K12: PKW-E | L12: PKW-E | M12: KFZ
A13: Zeit | B13: Rad | C13: KFZ | D13: Kombi | E13: Bus | F13: Bus | G13: LKW | H13: Anh. | I13: KFZ | J13: / 15 min | K13: / 30 min | L13: / 1 Std. | M13: / 1 Std.
A14: 6:00-6:15 | J14: =SUMPRODUCT(B14:I14,$B$11:$I$11) -> 0
A15: 6:15-6:30 | J15: =SUMPRODUCT(B15:I15,$B$11:$I$11) -> 0 | K15: =J15+J14 -> 0
A16: 6:30-6:45 | J16: =SUMPRODUCT(B16:I16,$B$11:$I$11) -> 0
A17: 6:45-7:00 | J17: =SUMPRODUCT(B17:I17,$B$11:$I$11) -> 0 | K17: =J17+J16 -> 0 | L17: =SUM(J14:J17) -> 0 | M17: =SUM(C14:I17) -> 0
A18: 7:00-7:15 | B18: 1 | C18: 0 | D18: 9 | E18: 0 | F18: 0 | G18: 0 | H18: 0 | I18: 0 | J18: =SUMPRODUCT(B18:I18,$B$11:$I$11) -> 9.5
A19: 7:15-7:30 | B19: 0 | C19: 0 | D19: 5 | E19: 0 | F19: 0 | G19: 0 | H19: 0 | I19: 0 | J19: =SUMPRODUCT(B19:I19,$B$11:$I$11) -> 5 | K19: =J19+J18 -> 14.5
A20: 7:30-7:45 | B20: 0 | C20: 2 | D20: 4 | E20: 0 | F20: 0 | G20: 0 | H20: 0 | I20: 0 | J20: =SUMPRODUCT(B20:I20,$B$11:$I$11) -> 6
A21: 7:45-8:00 | B21: 1 | C21: 1 | D21: 4 | E21: 1 | F21: 0 | G21: 1 | H21: 0 | I21: 0 | J21: =SUMPRODUCT(B21:I21,$B$11:$I$11) -> 8.5 | K21: =J21+J20 -> 14.5 | L21: =SUM(J18:J21) -> 29 | M21: =SUM(C18:I21) -> 27
A22: 8:00-8:15 | B22: 0 | C22: 0 | D22: 5 | E22: 0 | F22: 0 | G22: 0 | H22: 0 | I22: 0 | J22: =SUMPRODUCT(B22:I22,$B$11:$I$11) -> 5
A23: 8:15-8:30 | B23: 2 | C23: 0 | D23: 6 | E23: 0 | F23: 0 | G23: 1 | H23: 0 | I23: 0 | J23: =SUMPRODUCT(B23:I23,$B$11:$I$11) -> 8.5 | K23: =J23+J22 -> 13.5
A24: 8:30-8:45 | B24: 2 | C24: 0 | D24: 5 | E24: 0 | F24: 0 | G24: 2 | H24: 0 | I24: 0 | J24: =SUMPRODUCT(B24:I24,$B$11:$I$11) -> 9
A25: 8:45-9:00 | B25: 2 | C25: 0 | D25: 4 | E25: 0 | F25: 1 | G25: 0 | H25: 0 | I25: 0 | J25: =SUMPRODUCT(B25:I25,$B$11:$I$11) -> 6.5 | K25: =J25+J24 -> 15.5 | L25: =SUM(J22:J25) -> 29 | M25: =SUM(C22:I25) -> 24
A26: 9:00-9:15 | B26: 6 | C26: 0 | D26: 6 | E26: 0 | F26: 0 | G26: 0 | H26: 0 | I26: 0 | J26: =SUMPRODUCT(B26:I26,$B$11:$I$11) -> 9
A27: 9:15-9:30 | B27: 2 | C27: 0 | D27: 7 | E27: 0 | F27: 0 | G27: 0 | H27: 0 | I27: 0 | J27: =SUMPRODUCT(B27:I27,$B$11:$I$11) -> 8 | K27: =J27+J26 -> 17
A28: 9:30-9:45 | B28: 2 | C28: 1 | D28: 8 | E28: 0 | F28: 0 | G28: 0 | H28: 0 | I28: 0 | J28: =SUMPRODUCT(B28:I28,$B$11:$I$11) -> 10
A29: 9:45-10:00 | B29: 2 | C29: 0 | D29: 5 | E29: 0 | F29: 0 | G29: 1 | H29: 0 | I29: 0 | J29: =SUMPRODUCT(B29:I29,$B$11:$I$11) -> 7.5 | K29: =J29+J28 -> 17.5 | L29: =SUM(J26:J29) -> 34.5 | M29: =SUM(C26:I29) -> 28
A30: 10:00-10:15 | B30: 0 | C30: 2 | D30: 6 | E30: 0 | F30: 0 | G30: 0 | H30: 0 | I30: 0 | J30: =SUMPRODUCT(B30:I30,$B$11:$I$11) -> 8
A31: 10:15-10:30 | B31: 2 | C31: 0 | D31: 8 | E31: 0 | F31: 0 | G31: 1 | H31: 0 | I31: 0 | J31: =SUMPRODUCT(B31:I31,$B$11:$I$11) -> 10.5 | K31: =J31+J30 -> 18.5
A32: 10:30-10:45 | B32: 1 | C32: 0 | D32: 7 | E32: 0 | F32: 0 | G32: 0 | H32: 0 | I32: 0 | J32: =SUMPRODUCT(B32:I32,$B$11:$I$11) -> 7.5
A33: 10:45-11:00 | B33: 5 | C33: 1 | D33: 11 | E33: 0 | F33: 0 | G33: 0 | H33: 0 | I33: 0 | J33: =SUMPRODUCT(B33:I33,$B$11:$I$11) -> 14.5 | K33: =J33+J32 -> 22 | L33: =SUM(J30:J33) -> 40.5 | M33: =SUM(C30:I33) -> 36
A34: 11:00-11:15 | B34: 2 | C34: 0 | D34: 8 | E34: 0 | F34: 0 | G34: 0 | H34: 0 | I34: 0 | J34: =SUMPRODUCT(B34:I34,$B$11:$I$11) -> 9
A35: 11:15-11:30 | B35: 1 | C35: 0 | D35: 13 | E35: 0 | F35: 0 | G35: 0 | H35: 0 | I35: 0 | J35: =SUMPRODUCT(B35:I35,$B$11:$I$11) -> 13.5 | K35: =J35+J34 -> 22.5
A36: 11:30-11:45 | B36: 2 | C36: 1 | D36: 4 | E36: 0 | F36: 0 | G36: 0 | H36: 0 | I36: 0 | J36: =SUMPRODUCT(B36:I36,$B$11:$I$11) -> 6
A37: 11:45-12:00 | B37: 2 | C37: 0 | D37: 7 | E37: 0 | F37: 0 | G37: 0 | H37: 0 | I37: 0 | J37: =SUMPRODUCT(B37:I37,$B$11:$I$11) -> 8 | K37: =J37+J36 -> 14 | L37: =SUM(J34:J37) -> 36.5 | M37: =SUM(C34:I37) -> 33
A38: 12:00-12:15 | B38: 1 | C38: 0 | D38: 6 | E38: 0 | F38: 0 | G38: 0 | H38: 0 | I38: 0 | J38: =SUMPRODUCT(B38:I38,$B$11:$I$11) -> 6.5
A39: 12:15-12:30 | B39: 0 | C39: 0 | D39: 8 | E39: 0 | F39: 0 | G39: 0 | H39: 0 | I39: 0 | J39: =SUMPRODUCT(B39:I39,$B$11:$I$11) -> 8 | K39: =J39+J38 -> 14.5
A40: 12:30-12:45 | B40: 3 | C40: 0 | D40: 5 | E40: 0 | F40: 0 | G40: 1 | H40: 0 | I40: 0 | J40: =SUMPRODUCT(B40:I40,$B$11:$I$11) -> 8
A41: 12:45-13:00 | B41: 0 | C41: 0 | D41: 2 | E41: 0 | F41: 0 | G41: 0 | H41: 0 | I41: 0 | J41: =SUMPRODUCT(B41:I41,$B$11:$I$11) -> 2 | K41: =J41+J40 -> 10 | L41: =SUM(J38:J41) -> 24.5 | M41: =SUM(C38:I41) -> 22
A42: 13:00-13:15 | B42: 1 | C42: 0 | D42: 9 | E42: 0 | F42: 0 | G42: 0 | H42: 0 | I42: 0 | J42: =SUMPRODUCT(B42:I42,$B$11:$I$11) -> 9.5
...

Sheet R3
A3: ICRA Schwap e.U.
A4: VERKEHRSZÄHLUNG - PKW-Einheiten
A5: Datum : | J5: Lfd. Nummer : | K5: 0
A6: ='Deckbl.'!I11 -> 44817 | J6: Wetter : | K6: ='Deckbl.'!I12 -> Sonnig 10-26°
B7: Verkehrszählung : | C7: ='Deckbl.'!C8 -> Karl-Wurmb-Straße / Fanny-von-Lehnert-Straße (Salzburg)
B8: Zählstelle : | I8: Sachbearbeiter : | J8: ICRA / Schwap
B9: Richtung : | C9: R3 | I9: Uhrzeit : | J9: ='Deckbl.'!C11 -> 7-19
B10: Bemerkung : | I10: Dateiname:
A11: Faktoren | B11: 0.5 | C11: 1 | D11: ='Faktoren PKW-E'!B16 -> 1 | E11: 1.5 | F11: 1.5 | G11: 1.5 | H11: 2 | I11: 1.5
C12: einsp. | D12: PKW | E12: Lin. | F12: Reis. | H12: LKW + | I12: sonst. | J12: PKW-E | K12: PKW-E | L12: PKW-E | M12: KFZ
A13: Zeit | B13: Rad | C13: KFZ | D13: Kombi | E13: Bus | F13: Bus | G13: LKW | H13: Anh. | I13: KFZ | J13: / 15 min | K13: / 30 min | L13: / 1 Std. | M13: / 1 Std.
A14: 6:00-6:15 | J14: =SUMPRODUCT(B14:I14,$B$11:$I$11) -> 0
A15: 6:15-6:30 | J15: =SUMPRODUCT(B15:I15,$B$11:$I$11) -> 0 | K15: =J15+J14 -> 0
A16: 6:30-6:45 | J16: =SUMPRODUCT(B16:I16,$B$11:$I$11) -> 0
A17: 6:45-7:00 | J17: =SUMPRODUCT(B17:I17,$B$11:$I$11) -> 0 | K17: =J17+J16 -> 0 | L17: =SUM(J14:J17) -> 0 | M17: =SUM(C14:I17) -> 0
A18: 7:00-7:15 | B18: 0 | C18: 0 | D18: 9 | E18: 0 | F18: 0 | G18: 1 | H18: 0 | I18: 0 | J18: =SUMPRODUCT(B18:I18,$B$11:$I$11) -> 10.5
A19: 7:15-7:30 | B19: 0 | C19: 0 | D19: 7 | E19: 0 | F19: 0 | G19: 0 | H19: 0 | I19: 0 | J19: =SUMPRODUCT(B19:I19,$B$11:$I$11) -> 7 | K19: =J19+J18 -> 17.5
A20: 7:30-7:45 | B20: 0 | C20: 0 | D20: 4 | E20: 0 | F20: 0 | G20: 0 | H20: 0 | I20: 0 | J20: =SUMPRODUCT(B20:I20,$B$11:$I$11) -> 4
A21: 7:45-8:00 | B21: 1 | C21: 0 | D21: 10 | E21: 0 | F21: 0 | G21: 0 | H21: 0 | I21: 0 | J21: =SUMPRODUCT(B21:I21,$B$11:$I$11) -> 10.5 | K21: =J21+J20 -> 14.5 | L21: =SUM(J18:J21) -> 32 | M21: =SUM(C18:I21) -> 31
A22: 8:00-8:15 | B22: 1 | C22: 0 | D22: 8 | E22: 0 | F22: 0 | G22: 0 | H22: 0 | I22: 0 | J22: =SUMPRODUCT(B22:I22,$B$11:$I$11) -> 8.5
A23: 8:15-8:30 | B23: 0 | C23: 0 | D23: 8 | E23: 0 | F23: 0 | G23: 0 | H23: 0 | I23: 0 | J23: =SUMPRODUCT(B23:I23,$B$11:$I$11) -> 8 | K23: =J23+J22 -> 16.5
A24: 8:30-8:45 | B24: 0 | C24: 0 | D24: 2 | E24: 0 | F24: 0 | G24: 0 | H24: 0 | I24: 0 | J24: =SUMPRODUCT(B24:I24,$B$11:$I$11) -> 2
A25: 8:45-9:00 | B25: 0 | C25: 0 | D25: 3 | E25: 0 | F25: 0 | G25: 0 | H25: 0 | I25: 0 | J25: =SUMPRODUCT(B25:I25,$B$11:$I$11) -> 3 | K25: =J25+J24 -> 5 | L25: =SUM(J22:J25) -> 21.5 | M25: =SUM(C22:I25) -> 21
A26: 9:00-9:15 | B26: 1 | C26: 0 | D26: 6 | E26: 0 | F26: 0 | G26: 0 | H26: 0 | I26: 0 | J26: =SUMPRODUCT(B26:I26,$B$11:$I$11) -> 6.5
A27: 9:15-9:30 | B27: 0 | C27: 0 | D27: 1 | E27: 0 | F27: 0 | G27: 0 | H27: 0 | I27: 0 | J27: =SUMPRODUCT(B27:I27,$B$11:$I$11) -> 1 | K27: =J27+J26 -> 7.5
A28: 9:30-9:45 | B28: 0 | C28: 0 | D28: 3 | E28: 0 | F28: 0 | G28: 0 | H28: 0 | I28: 0 | J28: =SUMPRODUCT(B28:I28,$B$11:$I$11) -> 3
A29: 9:45-10:00 | B29: 0 | C29: 0 | D29: 2 | E29: 0 | F29: 0 | G29: 0 | H29: 0 | I29: 0 | J29: =SUMPRODUCT(B29:I29,$B$11:$I$11) -> 2 | K29: =J29+J28 -> 5 | L29: =SUM(J26:J29) -> 12.5 | M29: =SUM(C26:I29) -> 12
A30: 10:00-10:15 | B30: 0 | C30: 0 | D30: 4 | E30: 0 | F30: 0 | G30: 0 | H30: 0 | I30: 0 | J30: =SUMPRODUCT(B30:I30,$B$11:$I$11) -> 4
A31: 10:15-10:30 | B31: 0 | C31: 0 | D31: 1 | E31: 0 | F31: 0 | G31: 0 | H31: 0 | I31: 0 | J31: =SUMPRODUCT(B31:I31,$B$11:$I$11) -> 1 | K31: =J31+J30 -> 5
A32: 10:30-10:45 | B32: 0 | C32: 0 | D32: 2 | E32: 0 | F32: 0 | G32: 0 | H32: 0 | I32: 0 | J32: =SUMPRODUCT(B32:I32,$B$11:$I$11) -> 2
A33: 10:45-11:00 | B33: 1 | C33: 0 | D33: 3 | E33: 0 | F33: 0 | G33: 0 | H33: 0 | I33: 0 | J33: =SUMPRODUCT(B33:I33,$B$11:$I$11) -> 3.5 | K33: =J33+J32 -> 5.5 | L33: =SUM(J30:J33) -> 10.5 | M33: =SUM(C30:I33) -> 10
A34: 11:00-11:15 | B34: 2 | C34: 0 | D34: 4 | E34: 0 | F34: 0 | G34: 0 | H34: 0 | I34: 0 | J34: =SUMPRODUCT(B34:I34,$B$11:$I$11) -> 5
A35: 11:15-11:30 | B35: 0 | C35: 0 | D35: 6 | E35: 0 | F35: 0 | G35: 0 | H35: 0 | I35: 0 | J35: =SUMPRODUCT(B35:I35,$B$11:$I$11) -> 6 | K35: =J35+J34 -> 11
A36: 11:30-11:45 | B36: 0 | C36: 0 | D36: 6 | E36: 0 | F36: 0 | G36: 0 | H36: 0 | I36: 0 | J36: =SUMPRODUCT(B36:I36,$B$11:$I$11) -> 6
A37: 11:45-12:00 | B37: 0 | C37: 0 | D37: 4 | E37: 0 | F37: 0 | G37: 0 | H37: 0 | I37: 0 | J37: =SUMPRODUCT(B37:I37,$B$11:$I$11) -> 4 | K37: =J37+J36 -> 10 | L37: =SUM(J34:J37) -> 21 | M37: =SUM(C34:I37) -> 20
A38: 12:00-12:15 | B38: 0 | C38: 0 | D38: 3 | E38: 0 | F38: 0 | G38: 0 | H38: 0 | I38: 0 | J38: =SUMPRODUCT(B38:I38,$B$11:$I$11) -> 3
A39: 12:15-12:30 | B39: 0 | C39: 0 | D39: 4 | E39: 0 | F39: 0 | G39: 0 | H39: 0 | I39: 0 | J39: =SUMPRODUCT(B39:I39,$B$11:$I$11) -> 4 | K39: =J39+J38 -> 7
A40: 12:30-12:45 | B40: 0 | C40: 0 | D40: 7 | E40: 0 | F40: 0 | G40: 0 | H40: 0 | I40: 0 | J40: =SUMPRODUCT(B40:I40,$B$11:$I$11) -> 7
A41: 12:45-13:00 | B41: 0 | C41: 0 | D41: 3 | E41: 0 | F41: 0 | G41: 0 | H41: 0 | I41: 0 | J41: =SUMPRODUCT(B41:I41,$B$11:$I$11) -> 3 | K41: =J41+J40 -> 10 | L41: =SUM(J38:J41) -> 17 | M41: =SUM(C38:I41) -> 17
A42: 13:00-13:15 | B42: 0 | C42: 0 | D42: 5 | E42: 0 | F42: 0 | G42: 0 | H42: 0 | I42: 0 | J42: =SUMPRODUCT(B42:I42,$B$11:$I$11) -> 5
...

Sheet R4
A3: ICRA Schwap e.U.
A4: VERKEHRSZÄHLUNG - PKW-Einheiten
A5: Datum : | J5: Lfd. Nummer : | K5: 0
A6: ='Deckbl.'!I11 -> 44817 | J6: Wetter : | K6: ='Deckbl.'!I12 -> Sonnig 10-26°
B7: Verkehrszählung : | C7: ='Deckbl.'!C8 -> Karl-Wurmb-Straße / Fanny-von-Lehnert-Straße (Salzburg)
B8: Zählstelle : | I8: Sachbearbeiter : | J8: ICRA / Schwap
B9: Richtung : | C9: R4 | I9: Uhrzeit : | J9: ='Deckbl.'!C11 -> 7-19
B10: Bemerkung : | I10: Dateiname:
A11: Faktoren | B11: 0.5 | C11: 1 | D11: ='Faktoren PKW-E'!B16 -> 1 | E11: 1.5 | F11: 1.5 | G11: 1.5 | H11: 2 | I11: 1.5
C12: einsp. | D12: PKW | E12: Lin. | F12: Reis. | H12: LKW + | I12: sonst. | J12: PKW-E | K12: PKW-E | L12: PKW-E | M12: KFZ
A13: Zeit | B13: Rad | C13: KFZ | D13: Kombi | E13: Bus | F13: Bus | G13: LKW | H13: Anh. | I13: KFZ | J13: / 15 min | K13: / 30 min | L13: / 1 Std. | M13: / 1 Std.
A14: 6:00-6:15 | J14: =SUMPRODUCT(B14:I14,$B$11:$I$11) -> 0
A15: 6:15-6:30 | J15: =SUMPRODUCT(B15:I15,$B$11:$I$11) -> 0 | K15: =J15+J14 -> 0
A16: 6:30-6:45 | J16: =SUMPRODUCT(B16:I16,$B$11:$I$11) -> 0
A17: 6:45-7:00 | J17: =SUMPRODUCT(B17:I17,$B$11:$I$11) -> 0 | K17: =J17+J16 -> 0 | L17: =SUM(J14:J17) -> 0 | M17: =SUM(C14:I17) -> 0
A18: 7:00-7:15 | B18: 0 | C18: 0 | D18: 0 | E18: 0 | F18: 0 | G18: 0 | H18: 0 | I18: 0 | J18: =SUMPRODUCT(B18:I18,$B$11:$I$11) -> 0
A19: 7:15-7:30 | B19: 0 | C19: 0 | D19: 1 | E19: 0 | F19: 0 | G19: 0 | H19: 0 | I19: 0 | J19: =SUMPRODUCT(B19:I19,$B$11:$I$11) -> 1 | K19: =J19+J18 -> 1
A20: 7:30-7:45 | B20: 0 | C20: 0 | D20: 2 | E20: 0 | F20: 0 | G20: 0 | H20: 0 | I20: 0 | J20: =SUMPRODUCT(B20:I20,$B$11:$I$11) -> 2
A21: 7:45-8:00 | B21: 0 | C21: 2 | D21: 0 | E21: 0 | F21: 0 | G21: 0 | H21: 0 | I21: 0 | J21: =SUMPRODUCT(B21:I21,$B$11:$I$11) -> 2 | K21: =J21+J20 -> 4 | L21: =SUM(J18:J21) -> 5 | M21: =SUM(C18:I21) -> 5
A22: 8:00-8:15 | B22: 0 | C22: 0 | D22: 0 | E22: 0 | F22: 0 | G22: 0 | H22: 0 | I22: 0 | J22: =SUMPRODUCT(B22:I22,$B$11:$I$11) -> 0
A23: 8:15-8:30 | B23: 0 | C23: 0 | D23: 0 | E23: 0 | F23: 0 | G23: 0 | H23: 0 | I23: 0 | J23: =SUMPRODUCT(B23:I23,$B$11:$I$11) -> 0 | K23: =J23+J22 -> 0
A24: 8:30-8:45 | B24: 0 | C24: 0 | D24: 0 | E24: 0 | F24: 0 | G24: 0 | H24: 0 | I24: 0 | J24: =SUMPRODUCT(B24:I24,$B$11:$I$11) -> 0
A25: 8:45-9:00 | B25: 0 | C25: 0 | D25: 2 | E25: 0 | F25: 0 | G25: 0 | H25: 0 | I25: 0 | J25: =SUMPRODUCT(B25:I25,$B$11:$I$11) -> 2 | K25: =J25+J24 -> 2 | L25: =SUM(J22:J25) -> 2 | M25: =SUM(C22:I25) -> 2
A26: 9:00-9:15 | B26: 0 | C26: 0 | D26: 2 | E26: 0 | F26: 0 | G26: 0 | H26: 0 | I26: 0 | J26: =SUMPRODUCT(B26:I26,$B$11:$I$11) -> 2
A27: 9:15-9:30 | B27: 0 | C27: 0 | D27: 0 | E27: 0 | F27: 0 | G27: 0 | H27: 0 | I27: 0 | J27: =SUMPRODUCT(B27:I27,$B$11:$I$11) -> 0 | K27: =J27+J26 -> 2
A28: 9:30-9:45 | B28: 0 | C28: 0 | D28: 0 | E28: 0 | F28: 0 | G28: 0 | H28: 0 | I28: 0 | J28: =SUMPRODUCT(B28:I28,$B$11:$I$11) -> 0
A29: 9:45-10:00 | B29: 0 | C29: 0 | D29: 1 | E29: 0 | F29: 0 | G29: 0 | H29: 0 | I29: 0 | J29: =SUMPRODUCT(B29:I29,$B$11:$I$11) -> 1 | K29: =J29+J28 -> 1 | L29: =SUM(J26:J29) -> 3 | M29: =SUM(C26:I29) -> 3
A30: 10:00-10:15 | B30: 0 | C30: 0 | D30: 2 | E30: 0 | F30: 0 | G30: 0 | H30: 0 | I30: 0 | J30: =SUMPRODUCT(B30:I30,$B$11:$I$11) -> 2
A31: 10:15-10:30 | B31: 0 | C31: 0 | D31: 3 | E31: 0 | F31: 0 | G31: 0 | H31: 0 | I31: 0 | J31: =SUMPRODUCT(B31:I31,$B$11:$I$11) -> 3 | K31: =J31+J30 -> 5
A32: 10:30-10:45 | B32: 0 | C32: 0 | D32: 2 | E32: 0 | F32: 0 | G32: 0 | H32: 0 | I32: 0 | J32: =SUMPRODUCT(B32:I32,$B$11:$I$11) -> 2
A33: 10:45-11:00 | B33: 0 | C33: 0 | D33: 4 | E33: 0 | F33: 0 | G33: 0 | H33: 0 | I33: 0 | J33: =SUMPRODUCT(B33:I33,$B$11:$I$11) -> 4 | K33: =J33+J32 -> 6 | L33: =SUM(J30:J33) -> 11 | M33: =SUM(C30:I33) -> 11
A34: 11:00-11:15 | B34: 0 | C34: 0 | D34: 4 | E34: 0 | F34: 0 | G34: 0 | H34: 0 | I34: 0 | J34: =SUMPRODUCT(B34:I34,$B$11:$I$11) -> 4
A35: 11:15-11:30 | B35: 0 | C35: 0 | D35: 0 | E35: 0 | F35: 0 | G35: 0 | H35: 0 | I35: 0 | J35: =SUMPRODUCT(B35:I35,$B$11:$I$11) -> 0 | K35: =J35+J34 -> 4
A36: 11:30-11:45 | B36: 0 | C36: 0 | D36: 3 | E36: 0 | F36: 0 | G36: 0 | H36: 0 | I36: 0 | J36: =SUMPRODUCT(B36:I36,$B$11:$I$11) -> 3
A37: 11:45-12:00 | B37: 0 | C37: 0 | D37: 2 | E37: 0 | F37: 0 | G37: 0 | H37: 0 | I37: 0 | J37: =SUMPRODUCT(B37:I37,$B$11:$I$11) -> 2 | K37: =J37+J36 -> 5 | L37: =SUM(J34:J37) -> 9 | M37: =SUM(C34:I37) -> 9
A38: 12:00-12:15 | B38: 0 | C38: 0 | D38: 5 | E38: 0 | F38: 0 | G38: 0 | H38: 0 | I38: 0 | J38: =SUMPRODUCT(B38:I38,$B$11:$I$11) -> 5
A39: 12:15-12:30 | B39: 0 | C39: 0 | D39: 4 | E39: 0 | F39: 0 | G39: 0 | H39: 0 | I39: 0 | J39: =SUMPRODUCT(B39:I39,$B$11:$I$11) -> 4 | K39: =J39+J38 -> 9
A40: 12:30-12:45 | B40: 0 | C40: 0 | D40: 2 | E40: 0 | F40: 0 | G40: 0 | H40: 0 | I40: 0 | J40: =SUMPRODUCT(B40:I40,$B$11:$I$11) -> 2
A41: 12:45-13:00 | B41: 0 | C41: 0 | D41: 10 | E41: 0 | F41: 0 | G41: 0 | H41: 0 | I41: 0 | J41: =SUMPRODUCT(B41:I41,$B$11:$I$11) -> 10 | K41: =J41+J40 -> 12 | L41: =SUM(J38:J41) -> 21 | M41: =SUM(C38:I41) -> 21
A42: 13:00-13:15 | B42: 0 | C42: 0 | D42: 1 | E42: 0 | F42: 0 | G42: 0 | H42: 0 | I42: 0 | J42: =SUMPRODUCT(B42:I42,$B$11:$I$11) -> 1
...

Sheet R5
A3: ICRA Schwap e.U.
A4: VERKEHRSZÄHLUNG - PKW-Einheiten
A5: Datum : | J5: Lfd. Nummer : | K5: 0
A6: ='Deckbl.'!I11 -> 44817 | J6: Wetter : | K6: ='Deckbl.'!I12 -> Sonnig 10-26°
B7: Verkehrszählung : | C7: ='Deckbl.'!C8 -> Karl-Wurmb-Straße / Fanny-von-Lehnert-Straße (Salzburg)
B8: Zählstelle : | I8: Sachbearbeiter : | J8: ICRA / Schwap
B9: Richtung : | C9: R5 | I9: Uhrzeit : | J9: ='Deckbl.'!C11 -> 7-19
B10: Bemerkung : | I10: Dateiname:
A11: Faktoren | B11: 0.5 | C11: 1 | D11: ='Faktoren PKW-E'!B16 -> 1 | E11: 1.5 | F11: 1.5 | G11: 1.5 | H11: 2 | I11: 1.5
C12: einsp. | D12: PKW | E12: Lin. | F12: Reis. | H12: LKW + | I12: sonst. | J12: PKW-E | K12: PKW-E | L12: PKW-E | M12: KFZ
A13: Zeit | B13: Rad | C13: KFZ | D13: Kombi | E13: Bus | F13: Bus | G13: LKW | H13: Anh. | I13: KFZ | J13: / 15 min | K13: / 30 min | L13: / 1 Std. | M13: / 1 Std.
A14: 6:00-6:15 | J14: =SUMPRODUCT(B14:I14,$B$11:$I$11) -> 0
A15: 6:15-6:30 | J15: =SUMPRODUCT(B15:I15,$B$11:$I$11) -> 0 | K15: =J15+J14 -> 0
A16: 6:30-6:45 | J16: =SUMPRODUCT(B16:I16,$B$11:$I$11) -> 0
A17: 6:45-7:00 | J17: =SUMPRODUCT(B17:I17,$B$11:$I$11) -> 0 | K17: =J17+J16 -> 0 | L17: =SUM(J14:J17) -> 0 | M17: =SUM(C14:I17) -> 0
A18: 7:00-7:15 | B18: 1 | C18: 0 | D18: 0 | E18: 0 | F18: 0 | G18: 0 | H18: 0 | I18: 0 | J18: =SUMPRODUCT(B18:I18,$B$11:$I$11) -> 0.5
A19: 7:15-7:30 | B19: 3 | C19: 0 | D19: 1 | E19: 0 | F19: 0 | G19: 0 | H19: 0 | I19: 0 | J19: =SUMPRODUCT(B19:I19,$B$11:$I$11) -> 2.5 | K19: =J19+J18 -> 3
A20: 7:30-7:45 | B20: 2 | C20: 0 | D20: 0 | E20: 0 | F20: 0 | G20: 0 | H20: 0 | I20: 0 | J20: =SUMPRODUCT(B20:I20,$B$11:$I$11) -> 1
A21: 7:45-8:00 | B21: 3 | C21: 0 | D21: 0 | E21: 0 | F21: 0 | G21: 0 | H21: 0 | I21: 0 | J21: =SUMPRODUCT(B21:I21,$B$11:$I$11) -> 1.5 | K21: =J21+J20 -> 2.5 | L21: =SUM(J18:J21) -> 5.5 | M21: =SUM(C18:I21) -> 1
A22: 8:00-8:15 | B22: 0 | C22: 0 | D22: 0 | E22: 0 | F22: 0 | G22: 0 | H22: 0 | I22: 0 | J22: =SUMPRODUCT(B22:I22,$B$11:$I$11) -> 0
A23: 8:15-8:30 | B23: 3 | C23: 1 | D23: 0 | E23: 0 | F23: 0 | G23: 0 | H23: 0 | I23: 0 | J23: =SUMPRODUCT(B23:I23,$B$11:$I$11) -> 2.5 | K23: =J23+J22 -> 2.5
A24: 8:30-8:45 | B24: 2 | C24: 0 | D24: 6 | E24: 0 | F24: 0 | G24: 0 | H24: 0 | I24: 0 | J24: =SUMPRODUCT(B24:I24,$B$11:$I$11) -> 7
A25: 8:45-9:00 | B25: 0 | C25: 0 | D25: 2 | E25: 0 | F25: 0 | G25: 0 | H25: 0 | I25: 0 | J25: =SUMPRODUCT(B25:I25,$B$11:$I$11) -> 2 | K25: =J25+J24 -> 9 | L25: =SUM(J22:J25) -> 11.5 | M25: =SUM(C22:I25) -> 9
A26: 9:00-9:15 | B26: 0 | C26: 0 | D26: 1 | E26: 0 | F26: 0 | G26: 0 | H26: 0 | I26: 0 | J26: =SUMPRODUCT(B26:I26,$B$11:$I$11) -> 1
A27: 9:15-9:30 | B27: 0 | C27: 0 | D27: 1 | E27: 0 | F27: 0 | G27: 0 | H27: 0 | I27: 0 | J27: =SUMPRODUCT(B27:I27,$B$11:$I$11) -> 1 | K27: =J27+J26 -> 2
A28: 9:30-9:45 | B28: 1 | C28: 0 | D28: 2 | E28: 0 | F28: 0 | G28: 0 | H28: 0 | I28: 0 | J28: =SUMPRODUCT(B28:I28,$B$11:$I$11) -> 2.5
A29: 9:45-10:00 | B29: 1 | C29: 1 | D29: 3 | E29: 0 | F29: 0 | G29: 0 | H29: 0 | I29: 0 | J29: =SUMPRODUCT(B29:I29,$B$11:$I$11) -> 4.5 | K29: =J29+J28 -> 7 | L29: =SUM(J26:J29) -> 9 | M29: =SUM(C26:I29) -> 8
A30: 10:00-10:15 | B30: 4 | C30: 0 | D30: 1 | E30: 0 | F30: 0 | G30: 0 | H30: 0 | I30: 0 | J30: =SUMPRODUCT(B30:I30,$B$11:$I$11) -> 3
A31: 10:15-10:30 | B31: 0 | C31: 0 | D31: 5 | E31: 0 | F31: 0 | G31: 0 | H31: 0 | I31: 0 | J31: =SUMPRODUCT(B31:I31,$B$11:$I$11) -> 5 | K31: =J31+J30 -> 8
A32: 10:30-10:45 | B32: 2 | C32: 0 | D32: 3 | E32: 0 | F32: 0 | G32: 0 | H32: 0 | I32: 0 | J32: =SUMPRODUCT(B32:I32,$B$11:$I$11) -> 4
A33: 10:45-11:00 | B33: 2 | C33: 0 | D33: 4 | E33: 0 | F33: 0 | G33: 0 | H33: 0 | I33: 0 | J33: =SUMPRODUCT(B33:I33,$B$11:$I$11) -> 5 | K33: =J33+J32 -> 9 | L33: =SUM(J30:J33) -> 17 | M33: =SUM(C30:I33) -> 13
A34: 11:00-11:15 | B34: 2 | C34: 0 | D34: 10 | E34: 0 | F34: 0 | G34: 0 | H34: 0 | I34: 0 | J34: =SUMPRODUCT(B34:I34,$B$11:$I$11) -> 11
A35: 11:15-11:30 | B35: 3 | C35: 0 | D35: 5 | E35: 0 | F35: 0 | G35: 0 | H35: 0 | I35: 0 | J35: =SUMPRODUCT(B35:I35,$B$11:$I$11) -> 6.5 | K35: =J35+J34 -> 17.5
A36: 11:30-11:45 | B36: 4 | C36: 0 | D36: 4 | E36: 0 | F36: 0 | G36: 0 | H36: 0 | I36: 0 | J36: =SUMPRODUCT(B36:I36,$B$11:$I$11) -> 6
A37: 11:45-12:00 | B37: 7 | C37: 0 | D37: 8 | E37: 0 | F37: 0 | G37: 0 | H37: 0 | I37: 0 | J37: =SUMPRODUCT(B37:I37,$B$11:$I$11) -> 11.5 | K37: =J37+J36 -> 17.5 | L37: =SUM(J34:J37) -> 35 | M37: =SUM(C34:I37) -> 27
A38: 12:00-12:15 | B38: 3 | C38: 0 | D38: 4 | E38: 0 | F38: 0 | G38: 0 | H38: 0 | I38: 0 | J38: =SUMPRODUCT(B38:I38,$B$11:$I$11) -> 5.5
A39: 12:15-12:30 | B39: 1 | C39: 0 | D39: 3 | E39: 0 | F39: 0 | G39: 0 | H39: 0 | I39: 0 | J39: =SUMPRODUCT(B39:I39,$B$11:$I$11) -> 3.5 | K39: =J39+J38 -> 9
A40: 12:30-12:45 | B40: 3 | C40: 0 | D40: 3 | E40: 0 | F40: 0 | G40: 0 | H40: 0 | I40: 0 | J40: =SUMPRODUCT(B40:I40,$B$11:$I$11) -> 4.5
A41: 12:45-13:00 | B41: 5 | C41: 0 | D41: 3 | E41: 0 | F41: 0 | G41: 0 | H41: 0 | I41: 0 | J41: =SUMPRODUCT(B41:I41,$B$11:$I$11) -> 5.5 | K41: =J41+J40 -> 10 | L41: =SUM(J38:J41) -> 19 | M41: =SUM(C38:I41) -> 13
A42: 13:00-13:15 | B42: 1 | C42: 0 | D42: 0 | E42: 0 | F42: 0 | G42: 0 | H42: 0 | I42: 0 | J42: =SUMPRODUCT(B42:I42,$B$11:$I$11) -> 0.5
...

Sheet R6
A3: ICRA Schwap e.U.
A4: VERKEHRSZÄHLUNG - PKW-Einheiten
A5: Datum : | J5: Lfd. Nummer : | K5: 0
A6: ='Deckbl.'!I11 -> 44817 | J6: Wetter : | K6: ='Deckbl.'!I12 -> Sonnig 10-26°
B7: Verkehrszählung : | C7: ='Deckbl.'!C8 -> Karl-Wurmb-Straße / Fanny-von-Lehnert-Straße (Salzburg)
B8: Zählstelle : | I8: Sachbearbeiter : | J8: ICRA / Schwap
B9: Richtung : | C9: R6 | I9: Uhrzeit : | J9: ='Deckbl.'!C11 -> 7-19
B10: Bemerkung : | I10: Dateiname:
A11: Faktoren | B11: 0.5 | C11: 1 | D11: ='Faktoren PKW-E'!B16 -> 1 | E11: 1.5 | F11: 1.5 | G11: 1.5 | H11: 2 | I11: 1.5
C12: einsp. | D12: PKW | E12: Lin. | F12: Reis. | H12: LKW + | I12: sonst. | J12: PKW-E | K12: PKW-E | L12: PKW-E | M12: KFZ
A13: Zeit | B13: Rad | C13: KFZ | D13: Kombi | E13: Bus | F13: Bus | G13: LKW | H13: Anh. | I13: KFZ | J13: / 15 min | K13: / 30 min | L13: / 1 Std. | M13: / 1 Std.
A14: 6:00-6:15 | J14: =SUMPRODUCT(B14:I14,$B$11:$I$11) -> 0
A15: 6:15-6:30 | J15: =SUMPRODUCT(B15:I15,$B$11:$I$11) -> 0 | K15: =J15+J14 -> 0
A16: 6:30-6:45 | J16: =SUMPRODUCT(B16:I16,$B$11:$I$11) -> 0
A17: 6:45-7:00 | J17: =SUMPRODUCT(B17:I17,$B$11:$I$11) -> 0 | K17: =J17+J16 -> 0 | L17: =SUM(J14:J17) -> 0 | M17: =SUM(C14:I17) -> 0
A18: 7:00-7:15 | B18: 0 | C18: 0 | D18: 0 | E18: 0 | F18: 0 | G18: 0 | H18: 0 | I18: 0 | J18: =SUMPRODUCT(B18:I18,$B$11:$I$11) -> 0
A19: 7:15-7:30 | B19: 0 | C19: 0 | D19: 0 | E19: 0 | F19: 0 | G19: 0 | H19: 0 | I19: 0 | J19: =SUMPRODUCT(B19:I19,$B$11:$I$11) -> 0 | K19: =J19+J18 -> 0
A20: 7:30-7:45 | B20: 0 | C20: 0 | D20: 0 | E20: 0 | F20: 0 | G20: 0 | H20: 0 | I20: 0 | J20: =SUMPRODUCT(B20:I20,$B$11:$I$11) -> 0
A21: 7:45-8:00 | B21: 0 | C21: 0 | D21: 0 | E21: 0 | F21: 0 | G21: 0 | H21: 0 | I21: 0 | J21: =SUMPRODUCT(B21:I21,$B$11:$I$11) -> 0 | K21: =J21+J20 -> 0 | L21: =SUM(J18:J21) -> 0 | M21: =SUM(C18:I21) -> 0
A22: 8:00-8:15 | B22: 0 | C22: 0 | D22: 0 | E22: 0 | F22: 0 | G22: 0 | H22: 0 | I22: 0 | J22: =SUMPRODUCT(B22:I22,$B$11:$I$11) -> 0
A23: 8:15-8:30 | B23: 0 | C23: 0 | D23: 0 | E23: 0 | F23: 0 | G23: 0 | H23: 0 | I23: 0 | J23: =SUMPRODUCT(B23:I23,$B$11:$I$11) -> 0 | K23: =J23+J22 -> 0
A24: 8:30-8:45 | B24: 0 | C24: 0 | D24: 1 | E24: 0 | F24: 0 | G24: 0 | H24: 0 | I24: 0 | J24: =SUMPRODUCT(B24:I24,$B$11:$I$11) -> 1
A25: 8:45-9:00 | B25: 0 | C25: 0 | D25: 0 | E25: 0 | F25: 0 | G25: 0 | H25: 0 | I25: 0 | J25: =SUMPRODUCT(B25:I25,$B$11:$I$11) -> 0 | K25: =J25+J24 -> 1 | L25: =SUM(J22:J25) -> 1 | M25: =SUM(C22:I25) -> 1
A26: 9:00-9:15 | B26: 0 | C26: 0 | D26: 0 | E26: 0 | F26: 0 | G26: 0 | H26: 0 | I26: 0 | J26: =SUMPRODUCT(B26:I26,$B$11:$I$11) -> 0
A27: 9:15-9:30 | B27: 0 | C27: 0 | D27: 1 | E27: 0 | F27: 0 | G27: 0 | H27: 0 | I27: 0 | J27: =SUMPRODUCT(B27:I27,$B$11:$I$11) -> 1 | K27: =J27+J26 -> 1
A28: 9:30-9:45 | B28: 0 | C28: 1 | D28: 0 | E28: 0 | F28: 0 | G28: 0 | H28: 0 | I28: 0 | J28: =SUMPRODUCT(B28:I28,$B$11:$I$11) -> 1
A29: 9:45-10:00 | B29: 0 | C29: 0 | D29: 0 | E29: 0 | F29: 0 | G29: 0 | H29: 0 | I29: 0 | J29: =SUMPRODUCT(B29:I29,$B$11:$I$11) -> 0 | K29: =J29+J28 -> 1 | L29: =SUM(J26:J29) -> 2 | M29: =SUM(C26:I29) -> 2
A30: 10:00-10:15 | B30: 0 | C30: 0 | D30: 0 | E30: 0 | F30: 0 | G30: 0 | H30: 0 | I30: 0 | J30: =SUMPRODUCT(B30:I30,$B$11:$I$11) -> 0
A31: 10:15-10:30 | B31: 0 | C31: 0 | D31: 0 | E31: 0 | F31: 0 | G31: 0 | H31: 0 | I31: 0 | J31: =SUMPRODUCT(B31:I31,$B$11:$I$11) -> 0 | K31: =J31+J30 -> 0
A32: 10:30-10:45 | B32: 0 | C32: 0 | D32: 0 | E32: 0 | F32: 0 | G32: 0 | H32: 0 | I32: 0 | J32: =SUMPRODUCT(B32:I32,$B$11:$I$11) -> 0
A33: 10:45-11:00 | B33: 1 | C33: 0 | D33: 0 | E33: 0 | F33: 0 | G33: 0 | H33: 0 | I33: 0 | J33: =SUMPRODUCT(B33:I33,$B$11:$I$11) -> 0.5 | K33: =J33+J32 -> 0.5 | L33: =SUM(J30:J33) -> 0.5 | M33: =SUM(C30:I33) -> 0
A34: 11:00-11:15 | B34: 0 | C34: 0 | D34: 0 | E34: 0 | F34: 0 | G34: 0 | H34: 0 | I34: 0 | J34: =SUMPRODUCT(B34:I34,$B$11:$I$11) -> 0
A35: 11:15-11:30 | B35: 0 | C35: 0 | D35: 0 | E35: 0 | F35: 0 | G35: 0 | H35: 0 | I35: 0 | J35: =SUMPRODUCT(B35:I35,$B$11:$I$11) -> 0 | K35: =J35+J34 -> 0
A36: 11:30-11:45 | B36: 0 | C36: 0 | D36: 0 | E36: 0 | F36: 0 | G36: 0 | H36: 0 | I36: 0 | J36: =SUMPRODUCT(B36:I36,$B$11:$I$11) -> 0
A37: 11:45-12:00 | B37: 0 | C37: 0 | D37: 0 | E37: 0 | F37: 0 | G37: 0 | H37: 0 | I37: 0 | J37: =SUMPRODUCT(B37:I37,$B$11:$I$11) -> 0 | K37: =J37+J36 -> 0 | L37: =SUM(J34:J37) -> 0 | M37: =SUM(C34:I37) -> 0
A38: 12:00-12:15 | B38: 0 | C38: 0 | D38: 0 | E38: 0 | F38: 0 | G38: 0 | H38: 0 | I38: 0 | J38: =SUMPRODUCT(B38:I38,$B$11:$I$11) -> 0
A39: 12:15-12:30 | B39: 0 | C39: 0 | D39: 0 | E39: 0 | F39: 0 | G39: 0 | H39: 0 | I39: 0 | J39: =SUMPRODUCT(B39:I39,$B$11:$I$11) -> 0 | K39: =J39+J38 -> 0
A40: 12:30-12:45 | B40: 0 | C40: 0 | D40: 0 | E40: 0 | F40: 0 | G40: 0 | H40: 0 | I40: 0 | J40: =SUMPRODUCT(B40:I40,$B$11:$I$11) -> 0
A41: 12:45-13:00 | B41: 0 | C41: 0 | D41: 0 | E41: 0 | F41: 0 | G41: 0 | H41: 0 | I41: 0 | J41: =SUMPRODUCT(B41:I41,$B$11:$I$11) -> 0 | K41: =J41+J40 -> 0 | L41: =SUM(J38:J41) -> 0 | M41: =SUM(C38:I41) -> 0
A42: 13:00-13:15 | B42: 0 | C42: 0 | D42: 1 | E42: 0 | F42: 0 | G42: 0 | H42: 0 | I42: 0 | J42: =SUMPRODUCT(B42:I42,$B$11:$I$11) -> 1
...

Sheet R7
A3: ICRA Schwap e.U.
A4: VERKEHRSZÄHLUNG - PKW-Einheiten
A5: Datum : | J5: Lfd. Nummer : | K5: 0
A6: ='Deckbl.'!I11 -> 44817 | J6: Wetter : | K6: ='Deckbl.'!I12 -> Sonnig 10-26°
B7: Verkehrszählung : | C7: ='Deckbl.'!C8 -> Karl-Wurmb-Straße / Fanny-von-Lehnert-Straße (Salzburg)
B8: Zählstelle : | I8: Sachbearbeiter : | J8: ICRA / Schwap
B9: Richtung : | C9: R7 | I9: Uhrzeit : | J9: ='Deckbl.'!C11 -> 7-19
B10: Bemerkung : | I10: Dateiname:
A11: Faktoren | B11: 0.5 | C11: 1 | D11: ='Faktoren PKW-E'!B16 -> 1 | E11: 1.5 | F11: 1.5 | G11: 1.5 | H11: 2 | I11: 1.5
C12: einsp. | D12: PKW | E12: Lin. | F12: Reis. | H12: LKW + | I12: sonst. | J12: PKW-E | K12: PKW-E | L12: PKW-E | M12: KFZ
A13: Zeit | B13: Rad | C13: KFZ | D13: Kombi | E13: Bus | F13: Bus | G13: LKW | H13: Anh. | I13: KFZ | J13: / 15 min | K13: / 30 min | L13: / 1 Std. | M13: / 1 Std.
A14: 6:00-6:15 | J14: =SUMPRODUCT(B14:I14,$B$11:$I$11) -> 0
A15: 6:15-6:30 | J15: =SUMPRODUCT(B15:I15,$B$11:$I$11) -> 0 | K15: =J15+J14 -> 0
A16: 6:30-6:45 | J16: =SUMPRODUCT(B16:I16,$B$11:$I$11) -> 0
A17: 6:45-7:00 | J17: =SUMPRODUCT(B17:I17,$B$11:$I$11) -> 0 | K17: =J17+J16 -> 0 | L17: =SUM(J14:J17) -> 0 | M17: =SUM(C14:I17) -> 0
A18: 7:00-7:15 | B18: 0 | C18: 0 | D18: 4 | E18: 0 | F18: 0 | G18: 0 | H18: 0 | I18: 0 | J18: =SUMPRODUCT(B18:I18,$B$11:$I$11) -> 4
A19: 7:15-7:30 | B19: 0 | C19: 0 | D19: 8 | E19: 1 | F19: 0 | G19: 0 | H19: 0 | I19: 0 | J19: =SUMPRODUCT(B19:I19,$B$11:$I$11) -> 9.5 | K19: =J19+J18 -> 13.5
A20: 7:30-7:45 | B20: 0 | C20: 0 | D20: 5 | E20: 0 | F20: 0 | G20: 0 | H20: 0 | I20: 0 | J20: =SUMPRODUCT(B20:I20,$B$11:$I$11) -> 5
A21: 7:45-8:00 | B21: 0 | C21: 0 | D21: 10 | E21: 1 | F21: 0 | G21: 0 | H21: 0 | I21: 0 | J21: =SUMPRODUCT(B21:I21,$B$11:$I$11) -> 11.5 | K21: =J21+J20 -> 16.5 | L21: =SUM(J18:J21) -> 30 | M21: =SUM(C18:I21) -> 29
A22: 8:00-8:15 | B22: 1 | C22: 1 | D22: 9 | E22: 0 | F22: 0 | G22: 0 | H22: 0 | I22: 0 | J22: =SUMPRODUCT(B22:I22,$B$11:$I$11) -> 10.5
A23: 8:15-8:30 | B23: 2 | C23: 0 | D23: 7 | E23: 1 | F23: 1 | G23: 0 | H23: 0 | I23: 0 | J23: =SUMPRODUCT(B23:I23,$B$11:$I$11) -> 11 | K23: =J23+J22 -> 21.5
A24: 8:30-8:45 | B24: 0 | C24: 0 | D24: 8 | E24: 1 | F24: 0 | G24: 0 | H24: 0 | I24: 0 | J24: =SUMPRODUCT(B24:I24,$B$11:$I$11) -> 9.5
A25: 8:45-9:00 | B25: 0 | C25: 0 | D25: 11 | E25: 1 | F25: 0 | G25: 0 | H25: 0 | I25: 0 | J25: =SUMPRODUCT(B25:I25,$B$11:$I$11) -> 12.5 | K25: =J25+J24 -> 22 | L25: =SUM(J22:J25) -> 43.5 | M25: =SUM(C22:I25) -> 40
A26: 9:00-9:15 | B26: 0 | C26: 1 | D26: 7 | E26: 1 | F26: 0 | G26: 0 | H26: 0 | I26: 0 | J26: =SUMPRODUCT(B26:I26,$B$11:$I$11) -> 9.5
A27: 9:15-9:30 | B27: 0 | C27: 1 | D27: 7 | E27: 2 | F27: 0 | G27: 0 | H27: 0 | I27: 0 | J27: =SUMPRODUCT(B27:I27,$B$11:$I$11) -> 11 | K27: =J27+J26 -> 20.5
A28: 9:30-9:45 | B28: 0 | C28: 0 | D28: 8 | E28: 0 | F28: 0 | G28: 0 | H28: 0 | I28: 0 | J28: =SUMPRODUCT(B28:I28,$B$11:$I$11) -> 8
A29: 9:45-10:00 | B29: 0 | C29: 0 | D29: 12 | E29: 1 | F29: 0 | G29: 0 | H29: 0 | I29: 0 | J29: =SUMPRODUCT(B29:I29,$B$11:$I$11) -> 13.5 | K29: =J29+J28 -> 21.5 | L29: =SUM(J26:J29) -> 42 | M29: =SUM(C26:I29) -> 40
A30: 10:00-10:15 | B30: 0 | C30: 0 | D30: 17 | E30: 0 | F30: 0 | G30: 0 | H30: 0 | I30: 0 | J30: =SUMPRODUCT(B30:I30,$B$11:$I$11) -> 17
A31: 10:15-10:30 | B31: 1 | C31: 0 | D31: 14 | E31: 1 | F31: 0 | G31: 1 | H31: 0 | I31: 0 | J31: =SUMPRODUCT(B31:I31,$B$11:$I$11) -> 17.5 | K31: =J31+J30 -> 34.5
A32: 10:30-10:45 | B32: 0 | C32: 0 | D32: 13 | E32: 0 | F32: 0 | G32: 0 | H32: 0 | I32: 0 | J32: =SUMPRODUCT(B32:I32,$B$11:$I$11) -> 13
A33: 10:45-11:00 | B33: 0 | C33: 2 | D33: 7 | E33: 1 | F33: 0 | G33: 0 | H33: 0 | I33: 0 | J33: =SUMPRODUCT(B33:I33,$B$11:$I$11) -> 10.5 | K33: =J33+J32 -> 23.5 | L33: =SUM(J30:J33) -> 58 | M33: =SUM(C30:I33) -> 56
A34: 11:00-11:15 | B34: 0 | C34: 0 | D34: 14 | E34: 1 | F34: 0 | G34: 1 | H34: 0 | I34: 0 | J34: =SUMPRODUCT(B34:I34,$B$11:$I$11) -> 17
A35: 11:15-11:30 | B35: 0 | C35: 0 | D35: 8 | E35: 1 | F35: 0 | G35: 0 | H35: 0 | I35: 0 | J35: =SUMPRODUCT(B35:I35,$B$11:$I$11) -> 9.5 | K35: =J35+J34 -> 26.5
A36: 11:30-11:45 | B36: 0 | C36: 1 | D36: 11 | E36: 0 | F36: 0 | G36: 0 | H36: 0 | I36: 0 | J36: =SUMPRODUCT(B36:I36,$B$11:$I$11) -> 12
A37: 11:45-12:00 | B37: 0 | C37: 0 | D37: 13 | E37: 1 | F37: 0 | G37: 0 | H37: 0 | I37: 0 | J37: =SUMPRODUCT(B37:I37,$B$11:$I$11) -> 14.5 | K37: =J37+J36 -> 26.5 | L37: =SUM(J34:J37) -> 53 | M37: =SUM(C34:I37) -> 51
A38: 12:00-12:15 | B38: 0 | C38: 0 | D38: 11 | E38: 0 | F38: 0 | G38: 0 | H38: 0 | I38: 0 | J38: =SUMPRODUCT(B38:I38,$B$11:$I$11) -> 11
A39: 12:15-12:30 | B39: 0 | C39: 0 | D39: 7 | E39: 1 | F39: 0 | G39: 0 | H39: 0 | I39: 0 | J39: =SUMPRODUCT(B39:I39,$B$11:$I$11) -> 8.5 | K39: =J39+J38 -> 19.5
A40: 12:30-12:45 | B40: 1 | C40: 0 | D40: 5 | E40: 1 | F40: 0 | G40: 0 | H40: 0 | I40: 0 | J40: =SUMPRODUCT(B40:I40,$B$11:$I$11) -> 7
A41: 12:45-13:00 | B41: 3 | C41: 0 | D41: 9 | E41: 1 | F41: 0 | G41: 0 | H41: 0 | I41: 0 | J41: =SUMPRODUCT(B41:I41,$B$11:$I$11) -> 12 | K41: =J41+J40 -> 19 | L41: =SUM(J38:J41) -> 38.5 | M41: =SUM(C38:I41) -> 35
A42: 13:00-13:15 | B42: 0 | C42: 0 | D42: 10 | E42: 1 | F42: 0 | G42: 0 | H42: 0 | I42: 0 | J42: =SUMPRODUCT(B42:I42,$B$11:$I$11) -> 11.5
...

Sheet R8
A3: ICRA Schwap e.U.
A4: VERKEHRSZÄHLUNG - PKW-Einheiten
A5: Datum : | J5: Lfd. Nummer : | K5: 0
A6: ='Deckbl.'!I11 -> 44817 | J6: Wetter : | K6: ='Deckbl.'!I12 -> Sonnig 10-26°
B7: Verkehrszählung : | C7: ='Deckbl.'!C8 -> Karl-Wurmb-Straße / Fanny-von-Lehnert-Straße (Salzburg)
B8: Zählstelle : | I8: Sachbearbeiter : | J8: ICRA / Schwap
B9: Richtung : | C9: R8 | I9: Uhrzeit : | J9: ='Deckbl.'!C11 -> 7-19
B10: Bemerkung : | I10: Dateiname:
A11: Faktoren | B11: 0.5 | C11: 1 | D11: ='Faktoren PKW-E'!B16 -> 1 | E11: 1.5 | F11: 1.5 | G11: 1.5 | H11: 2 | I11: 1.5
C12: einsp. | D12: PKW | E12: Lin. | F12: Reis. | H12: LKW + | I12: sonst. | J12: PKW-E | K12: PKW-E | L12: PKW-E | M12: KFZ
A13: Zeit | B13: Rad | C13: KFZ | D13: Kombi | E13: Bus | F13: Bus | G13: LKW | H13: Anh. | I13: KFZ | J13: / 15 min | K13: / 30 min | L13: / 1 Std. | M13: / 1 Std.
A14: 6:00-6:15 | J14: =SUMPRODUCT(B14:I14,$B$11:$I$11) -> 0
A15: 6:15-6:30 | J15: =SUMPRODUCT(B15:I15,$B$11:$I$11) -> 0 | K15: =J15+J14 -> 0
A16: 6:30-6:45 | J16: =SUMPRODUCT(B16:I16,$B$11:$I$11) -> 0
A17: 6:45-7:00 | J17: =SUMPRODUCT(B17:I17,$B$11:$I$11) -> 0 | K17: =J17+J16 -> 0 | L17: =SUM(J14:J17) -> 0 | M17: =SUM(C14:I17) -> 0
A18: 7:00-7:15 | B18: 0 | C18: 2 | D18: 29 | E18: 1 | F18: 0 | G18: 0 | H18: 1 | I18: 0 | J18: =SUMPRODUCT(B18:I18,$B$11:$I$11) -> 34.5
A19: 7:15-7:30 | B19: 0 | C19: 2 | D19: 33 | E19: 1 | F19: 0 | G19: 0 | H19: 0 | I19: 0 | J19: =SUMPRODUCT(B19:I19,$B$11:$I$11) -> 36.5 | K19: =J19+J18 -> 71
A20: 7:30-7:45 | B20: 1 | C20: 1 | D20: 32 | E20: 6 | F20: 1 | G20: 1 | H20: 0 | I20: 0 | J20: =SUMPRODUCT(B20:I20,$B$11:$I$11) -> 45.5
A21: 7:45-8:00 | B21: 6 | C21: 5 | D21: 45 | E21: 3 | F21: 1 | G21: 0 | H21: 0 | I21: 0 | J21: =SUMPRODUCT(B21:I21,$B$11:$I$11) -> 59 | K21: =J21+J20 -> 104.5 | L21: =SUM(J18:J21) -> 175.5 | M21: =SUM(C18:I21) -> 164
A22: 8:00-8:15 | B22: 1 | C22: 0 | D22: 40 | E22: 2 | F22: 0 | G22: 1 | H22: 0 | I22: 0 | J22: =SUMPRODUCT(B22:I22,$B$11:$I$11) -> 45
A23: 8:15-8:30 | B23: 0 | C23: 3 | D23: 37 | E23: 3 | F23: 0 | G23: 1 | H23: 0 | I23: 0 | J23: =SUMPRODUCT(B23:I23,$B$11:$I$11) -> 46 | K23: =J23+J22 -> 91
A24: 8:30-8:45 | B24: 0 | C24: 3 | D24: 41 | E24: 2 | F24: 0 | G24: 0 | H24: 0 | I24: 0 | J24: =SUMPRODUCT(B24:I24,$B$11:$I$11) -> 47
A25: 8:45-9:00 | B25: 0 | C25: 3 | D25: 35 | E25: 3 | F25: 0 | G25: 2 | H25: 0 | I25: 0 | J25: =SUMPRODUCT(B25:I25,$B$11:$I$11) -> 45.5 | K25: =J25+J24 -> 92.5 | L25: =SUM(J22:J25) -> 183.5 | M25: =SUM(C22:I25) -> 176
A26: 9:00-9:15 | B26: 0 | C26: 6 | D26: 29 | E26: 5 | F26: 0 | G26: 0 | H26: 0 | I26: 0 | J26: =SUMPRODUCT(B26:I26,$B$11:$I$11) -> 42.5
A27: 9:15-9:30 | B27: 1 | C27: 12 | D27: 42 | E27: 4 | F27: 0 | G27: 2 | H27: 0 | I27: 0 | J27: =SUMPRODUCT(B27:I27,$B$11:$I$11) -> 63.5 | K27: =J27+J26 -> 106
A28: 9:30-9:45 | B28: 1 | C28: 14 | D28: 31 | E28: 2 | F28: 0 | G28: 1 | H28: 0 | I28: 0 | J28: =SUMPRODUCT(B28:I28,$B$11:$I$11) -> 50
A29: 9:45-10:00 | B29: 2 | C29: 1 | D29: 37 | E29: 2 | F29: 0 | G29: 0 | H29: 0 | I29: 0 | J29: =SUMPRODUCT(B29:I29,$B$11:$I$11) -> 42 | K29: =J29+J28 -> 92 | L29: =SUM(J26:J29) -> 198 | M29: =SUM(C26:I29) -> 188
A30: 10:00-10:15 | B30: 2 | C30: 2 | D30: 34 | E30: 3 | F30: 0 | G30: 0 | H30: 0 | I30: 0 | J30: =SUMPRODUCT(B30:I30,$B$11:$I$11) -> 41.5
A31: 10:15-10:30 | B31: 1 | C31: 2 | D31: 38 | E31: 3 | F31: 0 | G31: 0 | H31: 0 | I31: 0 | J31: =SUMPRODUCT(B31:I31,$B$11:$I$11) -> 45 | K31: =J31+J30 -> 86.5
A32: 10:30-10:45 | B32: 0 | C32: 1 | D32: 37 | E32: 1 | F32: 1 | G32: 0 | H32: 1 | I32: 0 | J32: =SUMPRODUCT(B32:I32,$B$11:$I$11) -> 43
A33: 10:45-11:00 | B33: 1 | C33: 2 | D33: 33 | E33: 3 | F33: 1 | G33: 0 | H33: 0 | I33: 0 | J33: =SUMPRODUCT(B33:I33,$B$11:$I$11) -> 41.5 | K33: =J33+J32 -> 84.5 | L33: =SUM(J30:J33) -> 171 | M33: =SUM(C30:I33) -> 162
A34: 11:00-11:15 | B34: 1 | C34: 1 | D34: 37 | E34: 2 | F34: 0 | G34: 0 | H34: 0 | I34: 0 | J34: =SUMPRODUCT(B34:I34,$B$11:$I$11) -> 41.5
A35: 11:15-11:30 | B35: 0 | C35: 2 | D35: 39 | E35: 5 | F35: 0 | G35: 0 | H35: 0 | I35: 0 | J35: =SUMPRODUCT(B35:I35,$B$11:$I$11) -> 48.5 | K35: =J35+J34 -> 90
A36: 11:30-11:45 | B36: 2 | C36: 1 | D36: 22 | E36: 3 | F36: 0 | G36: 0 | H36: 0 | I36: 0 | J36: =SUMPRODUCT(B36:I36,$B$11:$I$11) -> 28.5
A37: 11:45-12:00 | B37: 1 | C37: 0 | D37: 39 | E37: 2 | F37: 0 | G37: 0 | H37: 0 | I37: 1 | J37: =SUMPRODUCT(B37:I37,$B$11:$I$11) -> 44 | K37: =J37+J36 -> 72.5 | L37: =SUM(J34:J37) -> 162.5 | M37: =SUM(C34:I37) -> 154
A38: 12:00-12:15 | B38: 1 | C38: 2 | D38: 36 | E38: 2 | F38: 0 | G38: 0 | H38: 0 | I38: 0 | J38: =SUMPRODUCT(B38:I38,$B$11:$I$11) -> 41.5
A39: 12:15-12:30 | B39: 2 | C39: 2 | D39: 32 | E39: 2 | F39: 0 | G39: 1 | H39: 0 | I39: 0 | J39: =SUMPRODUCT(B39:I39,$B$11:$I$11) -> 39.5 | K39: =J39+J38 -> 81
A40: 12:30-12:45 | B40: 2 | C40: 2 | D40: 33 | E40: 1 | F40: 0 | G40: 0 | H40: 0 | I40: 0 | J40: =SUMPRODUCT(B40:I40,$B$11:$I$11) -> 37.5
A41: 12:45-13:00 | B41: 3 | C41: 3 | D41: 48 | E41: 3 | F41: 0 | G41: 1 | H41: 0 | I41: 0 | J41: =SUMPRODUCT(B41:I41,$B$11:$I$11) -> 58.5 | K41: =J41+J40 -> 96 | L41: =SUM(J38:J41) -> 177 | M41: =SUM(C38:I41) -> 168
A42: 13:00-13:15 | B42: 1 | C42: 3 | D42: 45 | E42: 3 | F42: 0 | G42: 2 | H42: 0 | I42: 0 | J42: =SUMPRODUCT(B42:I42,$B$11:$I$11) -> 56
...

Sheet R9
A3: ICRA Schwap e.U.
A4: VERKEHRSZÄHLUNG - PKW-Einheiten
A5: Datum : | J5: Lfd. Nummer : | K5: 0
A6: ='Deckbl.'!I11 -> 44817 | J6: Wetter : | K6: ='Deckbl.'!I12 -> Sonnig 10-26°
B7: Verkehrszählung : | C7: ='Deckbl.'!C8 -> Karl-Wurmb-Straße / Fanny-von-Lehnert-Straße (Salzburg)
B8: Zählstelle : | I8: Sachbearbeiter : | J8: ICRA / Schwap
B9: Richtung : | C9: R9 | I9: Uhrzeit : | J9: ='Deckbl.'!C11 -> 7-19
B10: Bemerkung : | I10: Dateiname:
A11: Faktoren | B11: 0.5 | C11: 1 | D11: ='Faktoren PKW-E'!B16 -> 1 | E11: 1.5 | F11: 1.5 | G11: 1.5 | H11: 2 | I11: 1.5
C12: einsp. | D12: PKW | E12: Lin. | F12: Reis. | H12: LKW + | I12: sonst. | J12: PKW-E | K12: PKW-E | L12: PKW-E | M12: KFZ
A13: Zeit | B13: Rad | C13: KFZ | D13: Kombi | E13: Bus | F13: Bus | G13: LKW | H13: Anh. | I13: KFZ | J13: / 15 min | K13: / 30 min | L13: / 1 Std. | M13: / 1 Std.
A14: 6:00-6:15 | J14: =SUMPRODUCT(B14:I14,$B$11:$I$11) -> 0
A15: 6:15-6:30 | J15: =SUMPRODUCT(B15:I15,$B$11:$I$11) -> 0 | K15: =J15+J14 -> 0
A16: 6:30-6:45 | J16: =SUMPRODUCT(B16:I16,$B$11:$I$11) -> 0
A17: 6:45-7:00 | J17: =SUMPRODUCT(B17:I17,$B$11:$I$11) -> 0 | K17: =J17+J16 -> 0 | L17: =SUM(J14:J17) -> 0 | M17: =SUM(C14:I17) -> 0
A18: 7:00-7:15 | B18: 2 | C18: 0 | D18: 8 | E18: 0 | F18: 0 | G18: 0 | H18: 0 | I18: 0 | J18: =SUMPRODUCT(B18:I18,$B$11:$I$11) -> 9
A19: 7:15-7:30 | B19: 1 | C19: 1 | D19: 4 | E19: 0 | F19: 0 | G19: 0 | H19: 0 | I19: 0 | J19: =SUMPRODUCT(B19:I19,$B$11:$I$11) -> 5.5 | K19: =J19+J18 -> 14.5
A20: 7:30-7:45 | B20: 2 | C20: 1 | D20: 6 | E20: 0 | F20: 0 | G20: 1 | H20: 0 | I20: 0 | J20: =SUMPRODUCT(B20:I20,$B$11:$I$11) -> 9.5
A21: 7:45-8:00 | B21: 0 | C21: 0 | D21: 9 | E21: 0 | F21: 0 | G21: 0 | H21: 0 | I21: 0 | J21: =SUMPRODUCT(B21:I21,$B$11:$I$11) -> 9 | K21: =J21+J20 -> 18.5 | L21: =SUM(J18:J21) -> 33 | M21: =SUM(C18:I21) -> 30
A22: 8:00-8:15 | B22: 1 | C22: 0 | D22: 9 | E22: 0 | F22: 0 | G22: 0 | H22: 0 | I22: 0 | J22: =SUMPRODUCT(B22:I22,$B$11:$I$11) -> 9.5
A23: 8:15-8:30 | B23: 0 | C23: 2 | D23: 10 | E23: 0 | F23: 0 | G23: 0 | H23: 0 | I23: 0 | J23: =SUMPRODUCT(B23:I23,$B$11:$I$11) -> 12 | K23: =J23+J22 -> 21.5
A24: 8:30-8:45 | B24: 2 | C24: 0 | D24: 7 | E24: 0 | F24: 0 | G24: 0 | H24: 0 | I24: 0 | J24: =SUMPRODUCT(B24:I24,$B$11:$I$11) -> 8
A25: 8:45-9:00 | B25: 1 | C25: 0 | D25: 5 | E25: 0 | F25: 0 | G25: 0 | H25: 0 | I25: 0 | J25: =SUMPRODUCT(B25:I25,$B$11:$I$11) -> 5.5 | K25: =J25+J24 -> 13.5 | L25: =SUM(J22:J25) -> 35 | M25: =SUM(C22:I25) -> 33
A26: 9:00-9:15 | B26: 0 | C26: 0 | D26: 14 | E26: 0 | F26: 0 | G26: 0 | H26: 0 | I26: 0 | J26: =SUMPRODUCT(B26:I26,$B$11:$I$11) -> 14
A27: 9:15-9:30 | B27: 0 | C27: 1 | D27: 3 | E27: 0 | F27: 0 | G27: 0 | H27: 0 | I27: 0 | J27: =SUMPRODUCT(B27:I27,$B$11:$I$11) -> 4 | K27: =J27+J26 -> 18
A28: 9:30-9:45 | B28: 1 | C28: 1 | D28: 5 | E28: 0 | F28: 0 | G28: 0 | H28: 0 | I28: 0 | J28: =SUMPRODUCT(B28:I28,$B$11:$I$11) -> 6.5
A29: 9:45-10:00 | B29: 2 | C29: 0 | D29: 2 | E29: 0 | F29: 0 | G29: 1 | H29: 0 | I29: 0 | J29: =SUMPRODUCT(B29:I29,$B$11:$I$11) -> 4.5 | K29: =J29+J28 -> 11 | L29: =SUM(J26:J29) -> 29 | M29: =SUM(C26:I29) -> 27
A30: 10:00-10:15 | B30: 0 | C30: 0 | D30: 6 | E30: 0 | F30: 0 | G30: 0 | H30: 0 | I30: 0 | J30: =SUMPRODUCT(B30:I30,$B$11:$I$11) -> 6
A31: 10:15-10:30 | B31: 0 | C31: 0 | D31: 2 | E31: 0 | F31: 0 | G31: 0 | H31: 0 | I31: 0 | J31: =SUMPRODUCT(B31:I31,$B$11:$I$11) -> 2 | K31: =J31+J30 -> 8
A32: 10:30-10:45 | B32: 0 | C32: 0 | D32: 6 | E32: 0 | F32: 0 | G32: 1 | H32: 0 | I32: 0 | J32: =SUMPRODUCT(B32:I32,$B$11:$I$11) -> 7.5
A33: 10:45-11:00 | B33: 1 | C33: 0 | D33: 4 | E33: 0 | F33: 0 | G33: 1 | H33: 0 | I33: 0 | J33: =SUMPRODUCT(B33:I33,$B$11:$I$11) -> 6 | K33: =J33+J32 -> 13.5 | L33: =SUM(J30:J33) -> 21.5 | M33: =SUM(C30:I33) -> 20
A34: 11:00-11:15 | B34: 0 | C34: 0 | D34: 8 | E34: 0 | F34: 0 | G34: 0 | H34: 0 | I34: 0 | J34: =SUMPRODUCT(B34:I34,$B$11:$I$11) -> 8
A35: 11:15-11:30 | B35: 3 | C35: 0 | D35: 11 | E35: 0 | F35: 0 | G35: 0 | H35: 0 | I35: 0 | J35: =SUMPRODUCT(B35:I35,$B$11:$I$11) -> 12.5 | K35: =J35+J34 -> 20.5
A36: 11:30-11:45 | B36: 0 | C36: 0 | D36: 4 | E36: 0 | F36: 0 | G36: 0 | H36: 0 | I36: 0 | J36: =SUMPRODUCT(B36:I36,$B$11:$I$11) -> 4
A37: 11:45-12:00 | B37: 1 | C37: 0 | D37: 8 | E37: 0 | F37: 0 | G37: 0 | H37: 0 | I37: 0 | J37: =SUMPRODUCT(B37:I37,$B$11:$I$11) -> 8.5 | K37: =J37+J36 -> 12.5 | L37: =SUM(J34:J37) -> 33 | M37: =SUM(C34:I37) -> 31
A38: 12:00-12:15 | B38: 0 | C38: 0 | D38: 5 | E38: 0 | F38: 0 | G38: 0 | H38: 0 | I38: 0 | J38: =SUMPRODUCT(B38:I38,$B$11:$I$11) -> 5
A39: 12:15-12:30 | B39: 2 | C39: 0 | D39: 9 | E39: 0 | F39: 0 | G39: 0 | H39: 0 | I39: 0 | J39: =SUMPRODUCT(B39:I39,$B$11:$I$11) -> 10 | K39: =J39+J38 -> 15
A40: 12:30-12:45 | B40: 1 | C40: 0 | D40: 9 | E40: 0 | F40: 0 | G40: 0 | H40: 0 | I40: 0 | J40: =SUMPRODUCT(B40:I40,$B$11:$I$11) -> 9.5
A41: 12:45-13:00 | B41: 1 | C41: 0 | D41: 4 | E41: 0 | F41: 0 | G41: 0 | H41: 0 | I41: 0 | J41: =SUMPRODUCT(B41:I41,$B$11:$I$11) -> 4.5 | K41: =J41+J40 -> 14 | L41: =SUM(J38:J41) -> 29 | M41: =SUM(C38:I41) -> 27
A42: 13:00-13:15 | B42: 0 | C42: 0 | D42: 1 | E42: 0 | F42: 0 | G42: 0 | H42: 0 | I42: 0 | J42: =SUMPRODUCT(B42:I42,$B$11:$I$11) -> 1
...

Sheet R10
A3: ICRA Schwap e.U.
A4: VERKEHRSZÄHLUNG - PKW-Einheiten
A5: Datum : | J5: Lfd. Nummer : | K5: 0
A6: ='Deckbl.'!I11 -> 44817 | J6: Wetter : | K6: ='Deckbl.'!I12 -> Sonnig 10-26°
B7: Verkehrszählung : | C7: ='Deckbl.'!C8 -> Karl-Wurmb-Straße / Fanny-von-Lehnert-Straße (Salzburg)
B8: Zählstelle : | I8: Sachbearbeiter : | J8: ICRA / Schwap
B9: Richtung : | C9: R10 | I9: Uhrzeit : | J9: ='Deckbl.'!C11 -> 7-19
B10: Bemerkung : | I10: Dateiname:
A11: Faktoren | B11: 0.5 | C11: 1 | D11: ='Faktoren PKW-E'!B16 -> 1 | E11: 1.5 | F11: 1.5 | G11: 1.5 | H11: 2 | I11: 1.5
C12: einsp. | D12: PKW | E12: Lin. | F12: Reis. | H12: LKW + | I12: sonst. | J12: PKW-E | K12: PKW-E | L12: PKW-E | M12: KFZ
A13: Zeit | B13: Rad | C13: KFZ | D13: Kombi | E13: Bus | F13: Bus | G13: LKW | H13: Anh. | I13: KFZ | J13: / 15 min | K13: / 30 min | L13: / 1 Std. | M13: / 1 Std.
A14: 6:00-6:15 | J14: =SUMPRODUCT(B14:I14,$B$11:$I$11) -> 0
A15: 6:15-6:30 | J15: =SUMPRODUCT(B15:I15,$B$11:$I$11) -> 0 | K15: =J15+J14 -> 0
A16: 6:30-6:45 | J16: =SUMPRODUCT(B16:I16,$B$11:$I$11) -> 0
A17: 6:45-7:00 | J17: =SUMPRODUCT(B17:I17,$B$11:$I$11) -> 0 | K17: =J17+J16 -> 0 | L17: =SUM(J14:J17) -> 0 | M17: =SUM(C14:I17) -> 0
A18: 7:00-7:15 | B18: 1 | C18: 0 | D18: 0 | E18: 0 | F18: 0 | G18: 0 | H18: 0 | I18: 0 | J18: =SUMPRODUCT(B18:I18,$B$11:$I$11) -> 0.5
A19: 7:15-7:30 | B19: 0 | C19: 0 | D19: 0 | E19: 0 | F19: 0 | G19: 0 | H19: 0 | I19: 0 | J19: =SUMPRODUCT(B19:I19,$B$11:$I$11) -> 0 | K19: =J19+J18 -> 0.5
A20: 7:30-7:45 | B20: 1 | C20: 0 | D20: 1 | E20: 0 | F20: 0 | G20: 0 | H20: 0 | I20: 0 | J20: =SUMPRODUCT(B20:I20,$B$11:$I$11) -> 1.5
A21: 7:45-8:00 | B21: 0 | C21: 0 | D21: 0 | E21: 0 | F21: 0 | G21: 0 | H21: 0 | I21: 0 | J21: =SUMPRODUCT(B21:I21,$B$11:$I$11) -> 0 | K21: =J21+J20 -> 1.5 | L21: =SUM(J18:J21) -> 2 | M21: =SUM(C18:I21) -> 1
A22: 8:00-8:15 | B22: 2 | C22: 0 | D22: 0 | E22: 0 | F22: 0 | G22: 0 | H22: 0 | I22: 0 | J22: =SUMPRODUCT(B22:I22,$B$11:$I$11) -> 1
A23: 8:15-8:30 | B23: 0 | C23: 0 | D23: 1 | E23: 0 | F23: 0 | G23: 0 | H23: 0 | I23: 0 | J23: =SUMPRODUCT(B23:I23,$B$11:$I$11) -> 1 | K23: =J23+J22 -> 2
A24: 8:30-8:45 | B24: 0 | C24: 0 | D24: 0 | E24: 0 | F24: 0 | G24: 0 | H24: 0 | I24: 0 | J24: =SUMPRODUCT(B24:I24,$B$11:$I$11) -> 0
A25: 8:45-9:00 | B25: 1 | C25: 0 | D25: 0 | E25: 0 | F25: 0 | G25: 0 | H25: 0 | I25: 0 | J25: =SUMPRODUCT(B25:I25,$B$11:$I$11) -> 0.5 | K25: =J25+J24 -> 0.5 | L25: =SUM(J22:J25) -> 2.5 | M25: =SUM(C22:I25) -> 1
A26: 9:00-9:15 | B26: 0 | C26: 0 | D26: 0 | E26: 0 | F26: 0 | G26: 0 | H26: 0 | I26: 0 | J26: =SUMPRODUCT(B26:I26,$B$11:$I$11) -> 0
A27: 9:15-9:30 | B27: 0 | C27: 0 | D27: 1 | E27: 0 | F27: 0 | G27: 0 | H27: 0 | I27: 0 | J27: =SUMPRODUCT(B27:I27,$B$11:$I$11) -> 1 | K27: =J27+J26 -> 1
A28: 9:30-9:45 | B28: 1 | C28: 0 | D28: 0 | E28: 0 | F28: 0 | G28: 0 | H28: 0 | I28: 0 | J28: =SUMPRODUCT(B28:I28,$B$11:$I$11) -> 0.5
A29: 9:45-10:00 | B29: 0 | C29: 0 | D29: 0 | E29: 0 | F29: 0 | G29: 0 | H29: 0 | I29: 0 | J29: =SUMPRODUCT(B29:I29,$B$11:$I$11) -> 0 | K29: =J29+J28 -> 0.5 | L29: =SUM(J26:J29) -> 1.5 | M29: =SUM(C26:I29) -> 1
A30: 10:00-10:15 | B30: 0 | C30: 0 | D30: 1 | E30: 0 | F30: 0 | G30: 0 | H30: 0 | I30: 0 | J30: =SUMPRODUCT(B30:I30,$B$11:$I$11) -> 1
A31: 10:15-10:30 | B31: 0 | C31: 0 | D31: 0 | E31: 0 | F31: 0 | G31: 0 | H31: 0 | I31: 0 | J31: =SUMPRODUCT(B31:I31,$B$11:$I$11) -> 0 | K31: =J31+J30 -> 1
A32: 10:30-10:45 | B32: 0 | C32: 0 | D32: 1 | E32: 0 | F32: 0 | G32: 0 | H32: 0 | I32: 0 | J32: =SUMPRODUCT(B32:I32,$B$11:$I$11) -> 1
A33: 10:45-11:00 | B33: 1 | C33: 0 | D33: 1 | E33: 0 | F33: 0 | G33: 0 | H33: 0 | I33: 0 | J33: =SUMPRODUCT(B33:I33,$B$11:$I$11) -> 1.5 | K33: =J33+J32 -> 2.5 | L33: =SUM(J30:J33) -> 3.5 | M33: =SUM(C30:I33) -> 3
A34: 11:00-11:15 | B34: 0 | C34: 0 | D34: 0 | E34: 0 | F34: 0 | G34: 0 | H34: 0 | I34: 0 | J34: =SUMPRODUCT(B34:I34,$B$11:$I$11) -> 0
A35: 11:15-11:30 | B35: 0 | C35: 0 | D35: 0 | E35: 0 | F35: 0 | G35: 0 | H35: 0 | I35: 0 | J35: =SUMPRODUCT(B35:I35,$B$11:$I$11) -> 0 | K35: =J35+J34 -> 0
A36: 11:30-11:45 | B36: 0 | C36: 0 | D36: 0 | E36: 0 | F36: 0 | G36: 0 | H36: 0 | I36: 0 | J36: =SUMPRODUCT(B36:I36,$B$11:$I$11) -> 0
A37: 11:45-12:00 | B37: 0 | C37: 0 | D37: 0 | E37: 0 | F37: 0 | G37: 0 | H37: 0 | I37: 0 | J37: =SUMPRODUCT(B37:I37,$B$11:$I$11) -> 0 | K37: =J37+J36 -> 0 | L37: =SUM(J34:J37) -> 0 | M37: =SUM(C34:I37) -> 0
A38: 12:00-12:15 | B38: 0 | C38: 0 | D38: 0 | E38: 0 | F38: 0 | G38: 0 | H38: 0 | I38: 0 | J38: =SUMPRODUCT(B38:I38,$B$11:$I$11) -> 0
A39: 12:15-12:30 | B39: 0 | C39: 0 | D39: 0 | E39: 0 | F39: 0 | G39: 0 | H39: 0 | I39: 0 | J39: =SUMPRODUCT(B39:I39,$B$11:$I$11) -> 0 | K39: =J39+J38 -> 0
A40: 12:30-12:45 | B40: 0 | C40: 0 | D40: 0 | E40: 0 | F40: 0 | G40: 0 | H40: 0 | I40: 0 | J40: =SUMPRODUCT(B40:I40,$B$11:$I$11) -> 0
A41: 12:45-13:00 | B41: 0 | C41: 0 | D41: 0 | E41: 0 | F41: 0 | G41: 0 | H41: 0 | I41: 0 | J41: =SUMPRODUCT(B41:I41,$B$11:$I$11) -> 0 | K41: =J41+J40 -> 0 | L41: =SUM(J38:J41) -> 0 | M41: =SUM(C38:I41) -> 0
A42: 13:00-13:15 | B42: 0 | C42: 0 | D42: 0 | E42: 0 | F42: 0 | G42: 0 | H42: 0 | I42: 0 | J42: =SUMPRODUCT(B42:I42,$B$11:$I$11) -> 0
...

Sheet R11
A3: ICRA Schwap e.U.
A4: VERKEHRSZÄHLUNG - PKW-Einheiten
A5: Datum : | J5: Lfd. Nummer : | K5: 0
A6: ='Deckbl.'!I11 -> 44817 | J6: Wetter : | K6: ='Deckbl.'!I12 -> Sonnig 10-26°
B7: Verkehrszählung : | C7: ='Deckbl.'!C8 -> Karl-Wurmb-Straße / Fanny-von-Lehnert-Straße (Salzburg)
B8: Zählstelle : | I8: Sachbearbeiter : | J8: ICRA / Schwap
B9: Richtung : | C9: R11 | I9: Uhrzeit : | J9: ='Deckbl.'!C11 -> 7-19
B10: Bemerkung : | I10: Dateiname:
A11: Faktoren | B11: 0.5 | C11: 1 | D11: ='Faktoren PKW-E'!B16 -> 1 | E11: 1.5 | F11: 1.5 | G11: 1.5 | H11: 2 | I11: 1.5
C12: einsp. | D12: PKW | E12: Lin. | F12: Reis. | H12: LKW + | I12: sonst. | J12: PKW-E | K12: PKW-E | L12: PKW-E | M12: KFZ
A13: Zeit | B13: Rad | C13: KFZ | D13: Kombi | E13: Bus | F13: Bus | G13: LKW | H13: Anh. | I13: KFZ | J13: / 15 min | K13: / 30 min | L13: / 1 Std. | M13: / 1 Std.
A14: 6:00-6:15 | J14: =SUMPRODUCT(B14:I14,$B$11:$I$11) -> 0
A15: 6:15-6:30 | J15: =SUMPRODUCT(B15:I15,$B$11:$I$11) -> 0 | K15: =J15+J14 -> 0
A16: 6:30-6:45 | J16: =SUMPRODUCT(B16:I16,$B$11:$I$11) -> 0
A17: 6:45-7:00 | J17: =SUMPRODUCT(B17:I17,$B$11:$I$11) -> 0 | K17: =J17+J16 -> 0 | L17: =SUM(J14:J17) -> 0 | M17: =SUM(C14:I17) -> 0
A18: 7:00-7:15 | B18: 6 | C18: 0 | D18: 0 | E18: 0 | F18: 0 | G18: 0 | H18: 0 | I18: 0 | J18: =SUMPRODUCT(B18:I18,$B$11:$I$11) -> 3
A19: 7:15-7:30 | B19: 6 | C19: 0 | D19: 0 | E19: 0 | F19: 0 | G19: 0 | H19: 0 | I19: 0 | J19: =SUMPRODUCT(B19:I19,$B$11:$I$11) -> 3 | K19: =J19+J18 -> 6
A20: 7:30-7:45 | B20: 3 | C20: 1 | D20: 2 | E20: 0 | F20: 0 | G20: 0 | H20: 0 | I20: 0 | J20: =SUMPRODUCT(B20:I20,$B$11:$I$11) -> 4.5
A21: 7:45-8:00 | B21: 8 | C21: 0 | D21: 0 | E21: 0 | F21: 0 | G21: 0 | H21: 0 | I21: 0 | J21: =SUMPRODUCT(B21:I21,$B$11:$I$11) -> 4 | K21: =J21+J20 -> 8.5 | L21: =SUM(J18:J21) -> 14.5 | M21: =SUM(C18:I21) -> 3
A22: 8:00-8:15 | B22: 7 | C22: 0 | D22: 0 | E22: 0 | F22: 0 | G22: 0 | H22: 0 | I22: 0 | J22: =SUMPRODUCT(B22:I22,$B$11:$I$11) -> 3.5
A23: 8:15-8:30 | B23: 5 | C23: 0 | D23: 0 | E23: 0 | F23: 0 | G23: 0 | H23: 0 | I23: 0 | J23: =SUMPRODUCT(B23:I23,$B$11:$I$11) -> 2.5 | K23: =J23+J22 -> 6
A24: 8:30-8:45 | B24: 1 | C24: 0 | D24: 0 | E24: 0 | F24: 0 | G24: 0 | H24: 0 | I24: 0 | J24: =SUMPRODUCT(B24:I24,$B$11:$I$11) -> 0.5
A25: 8:45-9:00 | B25: 4 | C25: 0 | D25: 0 | E25: 0 | F25: 0 | G25: 0 | H25: 0 | I25: 0 | J25: =SUMPRODUCT(B25:I25,$B$11:$I$11) -> 2 | K25: =J25+J24 -> 2.5 | L25: =SUM(J22:J25) -> 8.5 | M25: =SUM(C22:I25) -> 0
A26: 9:00-9:15 | B26: 8 | C26: 0 | D26: 0 | E26: 0 | F26: 0 | G26: 0 | H26: 0 | I26: 0 | J26: =SUMPRODUCT(B26:I26,$B$11:$I$11) -> 4
A27: 9:15-9:30 | B27: 4 | C27: 0 | D27: 1 | E27: 0 | F27: 0 | G27: 0 | H27: 0 | I27: 0 | J27: =SUMPRODUCT(B27:I27,$B$11:$I$11) -> 3 | K27: =J27+J26 -> 7
A28: 9:30-9:45 | B28: 8 | C28: 0 | D28: 0 | E28: 0 | F28: 0 | G28: 0 | H28: 0 | I28: 0 | J28: =SUMPRODUCT(B28:I28,$B$11:$I$11) -> 4
A29: 9:45-10:00 | B29: 3 | C29: 0 | D29: 0 | E29: 0 | F29: 0 | G29: 0 | H29: 0 | I29: 0 | J29: =SUMPRODUCT(B29:I29,$B$11:$I$11) -> 1.5 | K29: =J29+J28 -> 5.5 | L29: =SUM(J26:J29) -> 12.5 | M29: =SUM(C26:I29) -> 1
A30: 10:00-10:15 | B30: 1 | C30: 0 | D30: 0 | E30: 0 | F30: 0 | G30: 0 | H30: 0 | I30: 0 | J30: =SUMPRODUCT(B30:I30,$B$11:$I$11) -> 0.5
A31: 10:15-10:30 | B31: 4 | C31: 0 | D31: 1 | E31: 0 | F31: 0 | G31: 0 | H31: 0 | I31: 0 | J31: =SUMPRODUCT(B31:I31,$B$11:$I$11) -> 3 | K31: =J31+J30 -> 3.5
A32: 10:30-10:45 | B32: 4 | C32: 0 | D32: 0 | E32: 0 | F32: 0 | G32: 0 | H32: 0 | I32: 0 | J32: =SUMPRODUCT(B32:I32,$B$11:$I$11) -> 2
A33: 10:45-11:00 | B33: 3 | C33: 0 | D33: 3 | E33: 0 | F33: 0 | G33: 0 | H33: 0 | I33: 0 | J33: =SUMPRODUCT(B33:I33,$B$11:$I$11) -> 4.5 | K33: =J33+J32 -> 6.5 | L33: =SUM(J30:J33) -> 10 | M33: =SUM(C30:I33) -> 4
A34: 11:00-11:15 | B34: 1 | C34: 0 | D34: 2 | E34: 0 | F34: 0 | G34: 0 | H34: 0 | I34: 0 | J34: =SUMPRODUCT(B34:I34,$B$11:$I$11) -> 2.5
A35: 11:15-11:30 | B35: 1 | C35: 0 | D35: 1 | E35: 0 | F35: 0 | G35: 0 | H35: 0 | I35: 0 | J35: =SUMPRODUCT(B35:I35,$B$11:$I$11) -> 1.5 | K35: =J35+J34 -> 4
A36: 11:30-11:45 | B36: 5 | C36: 0 | D36: 1 | E36: 0 | F36: 0 | G36: 0 | H36: 0 | I36: 0 | J36: =SUMPRODUCT(B36:I36,$B$11:$I$11) -> 3.5
A37: 11:45-12:00 | B37: 9 | C37: 0 | D37: 0 | E37: 0 | F37: 0 | G37: 0 | H37: 0 | I37: 0 | J37: =SUMPRODUCT(B37:I37,$B$11:$I$11) -> 4.5 | K37: =J37+J36 -> 8 | L37: =SUM(J34:J37) -> 12 | M37: =SUM(C34:I37) -> 4
A38: 12:00-12:15 | B38: 3 | C38: 0 | D38: 1 | E38: 0 | F38: 0 | G38: 0 | H38: 0 | I38: 0 | J38: =SUMPRODUCT(B38:I38,$B$11:$I$11) -> 2.5
A39: 12:15-12:30 | B39: 0 | C39: 0 | D39: 1 | E39: 0 | F39: 0 | G39: 0 | H39: 0 | I39: 0 | J39: =SUMPRODUCT(B39:I39,$B$11:$I$11) -> 1 | K39: =J39+J38 -> 3.5
A40: 12:30-12:45 | B40: 1 | C40: 0 | D40: 1 | E40: 0 | F40: 0 | G40: 0 | H40: 0 | I40: 0 | J40: =SUMPRODUCT(B40:I40,$B$11:$I$11) -> 1.5
A41: 12:45-13:00 | B41: 4 | C41: 0 | D41: 0 | E41: 0 | F41: 0 | G41: 0 | H41: 0 | I41: 0 | J41: =SUMPRODUCT(B41:I41,$B$11:$I$11) -> 2 | K41: =J41+J40 -> 3.5 | L41: =SUM(J38:J41) -> 7 | M41: =SUM(C38:I41) -> 3
A42: 13:00-13:15 | B42: 3 | C42: 0 | D42: 0 | E42: 0 | F42: 0 | G42: 0 | H42: 0 | I42: 0 | J42: =SUMPRODUCT(B42:I42,$B$11:$I$11) -> 1.5
...

Sheet R12
A3: ICRA Schwap e.U.
A4: VERKEHRSZÄHLUNG - PKW-Einheiten
A5: Datum : | J5: Lfd. Nummer : | K5: 0
A6: ='Deckbl.'!I11 -> 44817 | J6: Wetter : | K6: ='Deckbl.'!I12 -> Sonnig 10-26°
B7: Verkehrszählung : | C7: ='Deckbl.'!C8 -> Karl-Wurmb-Straße / Fanny-von-Lehnert-Straße (Salzburg)
B8: Zählstelle : | I8: Sachbearbeiter : | J8: ICRA / Schwap
B9: Richtung : | C9: R12 | I9: Uhrzeit : | J9: ='Deckbl.'!C11 -> 7-19
B10: Bemerkung : | I10: Dateiname:
A11: Faktoren | B11: 0.5 | C11: 1 | D11: ='Faktoren PKW-E'!B16 -> 1 | E11: 1.5 | F11: 1.5 | G11: 1.5 | H11: 2 | I11: 1.5
C12: einsp. | D12: PKW | E12: Lin. | F12: Reis. | H12: LKW + | I12: sonst. | J12: PKW-E | K12: PKW-E | L12: PKW-E | M12: KFZ
A13: Zeit | B13: Rad | C13: KFZ | D13: Kombi | E13: Bus | F13: Bus | G13: LKW | H13: Anh. | I13: KFZ | J13: / 15 min | K13: / 30 min | L13: / 1 Std. | M13: / 1 Std.
A14: 6:00-6:15 | J14: =SUMPRODUCT(B14:I14,$B$11:$I$11) -> 0
A15: 6:15-6:30 | J15: =SUMPRODUCT(B15:I15,$B$11:$I$11) -> 0 | K15: =J15+J14 -> 0
A16: 6:30-6:45 | J16: =SUMPRODUCT(B16:I16,$B$11:$I$11) -> 0
A17: 6:45-7:00 | J17: =SUMPRODUCT(B17:I17,$B$11:$I$11) -> 0 | K17: =J17+J16 -> 0 | L17: =SUM(J14:J17) -> 0 | M17: =SUM(C14:I17) -> 0
A18: 7:00-7:15 | B18: 0 | C18: 0 | D18: 1 | E18: 0 | F18: 0 | G18: 0 | H18: 0 | I18: 0 | J18: =SUMPRODUCT(B18:I18,$B$11:$I$11) -> 1
A19: 7:15-7:30 | B19: 0 | C19: 0 | D19: 3 | E19: 0 | F19: 0 | G19: 0 | H19: 0 | I19: 0 | J19: =SUMPRODUCT(B19:I19,$B$11:$I$11) -> 3 | K19: =J19+J18 -> 4
A20: 7:30-7:45 | B20: 0 | C20: 0 | D20: 7 | E20: 0 | F20: 0 | G20: 0 | H20: 0 | I20: 1 | J20: =SUMPRODUCT(B20:I20,$B$11:$I$11) -> 8.5
A21: 7:45-8:00 | B21: 0 | C21: 0 | D21: 8 | E21: 0 | F21: 0 | G21: 0 | H21: 0 | I21: 0 | J21: =SUMPRODUCT(B21:I21,$B$11:$I$11) -> 8 | K21: =J21+J20 -> 16.5 | L21: =SUM(J18:J21) -> 20.5 | M21: =SUM(C18:I21) -> 20
A22: 8:00-8:15 | B22: 0 | C22: 0 | D22: 1 | E22: 0 | F22: 0 | G22: 0 | H22: 0 | I22: 0 | J22: =SUMPRODUCT(B22:I22,$B$11:$I$11) -> 1
A23: 8:15-8:30 | B23: 0 | C23: 0 | D23: 2 | E23: 0 | F23: 0 | G23: 0 | H23: 0 | I23: 0 | J23: =SUMPRODUCT(B23:I23,$B$11:$I$11) -> 2 | K23: =J23+J22 -> 3
A24: 8:30-8:45 | B24: 0 | C24: 0 | D24: 3 | E24: 0 | F24: 0 | G24: 1 | H24: 0 | I24: 0 | J24: =SUMPRODUCT(B24:I24,$B$11:$I$11) -> 4.5
A25: 8:45-9:00 | B25: 3 | C25: 0 | D25: 3 | E25: 0 | F25: 0 | G25: 0 | H25: 0 | I25: 0 | J25: =SUMPRODUCT(B25:I25,$B$11:$I$11) -> 4.5 | K25: =J25+J24 -> 9 | L25: =SUM(J22:J25) -> 12 | M25: =SUM(C22:I25) -> 10
A26: 9:00-9:15 | B26: 0 | C26: 0 | D26: 2 | E26: 0 | F26: 0 | G26: 0 | H26: 0 | I26: 0 | J26: =SUMPRODUCT(B26:I26,$B$11:$I$11) -> 2
A27: 9:15-9:30 | B27: 0 | C27: 0 | D27: 2 | E27: 0 | F27: 0 | G27: 0 | H27: 0 | I27: 0 | J27: =SUMPRODUCT(B27:I27,$B$11:$I$11) -> 2 | K27: =J27+J26 -> 4
A28: 9:30-9:45 | B28: 0 | C28: 0 | D28: 3 | E28: 0 | F28: 0 | G28: 0 | H28: 0 | I28: 0 | J28: =SUMPRODUCT(B28:I28,$B$11:$I$11) -> 3
