Workbook

Sheet Deckbl.
A5: ICRA Schwap e.U.
B8: Verkehrszählungsort : | C8: Sandleiten / Schulstraße / Parkstraße (Pregarten)
B10: Lfd. Nummer :
B11: Zählzeit : | C11: 6-20 | H11: Datum : | I11: 45036
B12: Sachbearbeiter : | C12: ICRA / Schwap | H12: Wetter : | I12: morgens leichter Regen, dann Sonne, 5-17°
B14: Anmerkungen :

Sheet R1
A3: ICRA Schwap e.U.
A4: VERKEHRSZÄHLUNG - PKW-Einheiten
A5: Datum : | J5: Lfd. Nummer : | K5: 0
A6: ='Deckbl.'!I11 -> 45036 | J6: Wetter : | K6: ='Deckbl.'!I12 -> morgens leichter Regen, dann Sonne, 5-17°
B7: Verkehrszählung : | C7: ='Deckbl.'!C8 -> Sandleiten / Schulstraße / Parkstraße (Pregarten)
B8: Zählstelle : | I8: Sachbearbeiter : | J8: ICRA / Schwap
B9: Richtung : | C9: R1 | I9: Uhrzeit : | J9: ='Deckbl.'!C11 -> 6-20
B10: Bemerkung : | I10: Dateiname:
A11: Faktoren | B11: 0.5 | C11: 1 | D11: ='Faktoren PKW-E'!B16 -> 1 | E11: 1.5 | F11: 1.5 | G11: 1.5 | H11: 2 | I11: 1.5
C12: einsp. | D12: PKW | E12: Lin. | F12: Reis. | H12: LKW + | I12: sonst. | J12: PKW-E | K12: PKW-E | L12: PKW-E | M12: KFZ
A13: Zeit | B13: Rad | C13: KFZ | D13: Kombi | E13: Bus | F13: Bus | G13: LKW | H13: Anh. | I13: KFZ | J13: / 15 min | K13: / 30 min | L13: / 1 Std. | M13: / 1 Std.
A14: 6:00-6:15 | B14: 0 | C14: 0 | D14: 1 | E14: 0 | F14: 0 | G14: 0 | H14: 0 | I14: 0 | J14: =SUMPRODUCT(B14:I14,$B$11:$I$11) -> 1
A15: 6:15-6:30 | B15: 0 | C15: 0 | D15: 4 | E15: 0 | F15: 0 | G15: 0 | H15: 0 | I15: 0 | J15: =SUMPRODUCT(B15:I15,$B$11:$I$11) -> 4 | K15: =J15+J14 -> 5
A16: 6:30-6:45 | B16: 1 | C16: 0 | D16: 1 | E16: 0 | F16: 0 | G16: 0 | H16: 0 | I16: 0 | J16: =SUMPRODUCT(B16:I16,$B$11:$I$11) -> 1.5
A17: 6:45-7:00 | B17: 0 | C17: 0 | D17: 2 | E17: 0 | F17: 0 | G17: 0 | H17: 0 | I17: 0 | J17: =SUMPRODUCT(B17:I17,$B$11:$I$11) -> 2 | K17: =J17+J16 -> 3.5 | L17: =SUM(J14:J17) -> 8.5 | M17: =SUM(C14:I17) -> 8
A18: 7:00-7:15 | B18: 0 | C18: 0 | D18: 0 | E18: 0 | F18: 0 | G18: 0 | H18: 0 | I18: 0 | J18: =SUMPRODUCT(B18:I18,$B$11:$I$11) -> 0
A19: 7:15-7:30 | B19: 0 | C19: 0 | D19: 7 | E19: 0 | F19: 0 | G19: 0 | H19: 0 | I19: 0 | J19: =SUMPRODUCT(B19:I19,$B$11:$I$11) -> 7 | K19: =J19+J18 -> 7
A20: 7:30-7:45 | B20: 0 | C20: 0 | D20: 2 | E20: 0 | F20: 0 | G20: 0 | H20: 0 | I20: 0 | J20: =SUMPRODUCT(B20:I20,$B$11:$I$11) -> 2
A21: 7:45-8:00 | B21: 0 | C21: 0 | D21: 4 | E21: 0 | F21: 0 | G21: 0 | H21: 0 | I21: 0 | J21: =SUMPRODUCT(B21:I21,$B$11:$I$11) -> 4 | K21: =J21+J20 -> 6 | L21: =SUM(J18:J21) -> 13 | M21: =SUM(C18:I21) -> 13
A22: 8:00-8:15 | B22: 0 | C22: 0 | D22: 0 | E22: 0 | F22: 0 | G22: 0 | H22: 0 | I22: 0 | J22: =SUMPRODUCT(B22:I22,$B$11:$I$11) -> 0
A23: 8:15-8:30 | B23: 0 | C23: 0 | D23: 2 | E23: 0 | F23: 0 | G23: 0 | H23: 0 | I23: 0 | J23: =SUMPRODUCT(B23:I23,$B$11:$I$11) -> 2 | K23: =J23+J22 -> 2
A24: 8:30-8:45 | B24: 0 | C24: 0 | D24: 2 | E24: 0 | F24: 0 | G24: 0 | H24: 0 | I24: 0 | J24: =SUMPRODUCT(B24:I24,$B$11:$I$11) -> 2
A25: 8:45-9:00 | B25: 0 | C25: 0 | D25: 0 | E25: 0 | F25: 0 | G25: 0 | H25: 0 | I25: 0 | J25: =SUMPRODUCT(B25:I25,$B$11:$I$11) -> 0 | K25: =J25+J24 -> 2 | L25: =SUM(J22:J25) -> 4 | M25: =SUM(C22:I25) -> 4
A26: 9:00-9:15 | B26: 0 | C26: 0 | D26: 3 | E26: 0 | F26: 0 | G26: 0 | H26: 0 | I26: 0 | J26: =SUMPRODUCT(B26:I26,$B$11:$I$11) -> 3
A27: 9:15-9:30 | B27: 0 | C27: 0 | D27: 1 | E27: 0 | F27: 0 | G27: 1 | H27: 0 | I27: 0 | J27: =SUMPRODUCT(B27:I27,$B$11:$I$11) -> 2.5 | K27: =J27+J26 -> 5.5
A28: 9:30-9:45 | B28: 0 | C28: 0 | D28: 0 | E28: 0 | F28: 0 | G28: 0 | H28: 0 | I28: 0 | J28: =SUMPRODUCT(B28:I28,$B$11:$I$11) -> 0
A29: 9:45-10:00 | B29: 0 | C29: 0 | D29: 0 | E29: 0 | F29: 0 | G29: 0 | H29: 0 | I29: 0 | J29: =SUMPRODUCT(B29:I29,$B$11:$I$11) -> 0 | K29: =J29+J28 -> 0 | L29: =SUM(J26:J29) -> 5.5 | M29: =SUM(C26:I29) -> 5
A30: 10:00-10:15 | B30: 0 | C30: 0 | D30: 2 | E30: 0 | F30: 0 | G30: 0 | H30: 0 | I30: 0 | J30: =SUMPRODUCT(B30:I30,$B$11:$I$11) -> 2
A31: 10:15-10:30 | B31: 0 | C31: 0 | D31: 0 | E31: 0 | F31: 0 | G31: 0 | H31: 0 | I31: 0 | J31: =SUMPRODUCT(B31:I31,$B$11:$I$11) -> 0 | K31: =J31+J30 -> 2
A32: 10:30-10:45 | B32: 0 | C32: 0 | D32: 0 | E32: 0 | F32: 0 | G32: 0 | H32: 0 | I32: 0 | J32: =SUMPRODUCT(B32:I32,$B$11:$I$11) -> 0
A33: 10:45-11:00 | B33: 0 | C33: 0 | D33: 0 | E33: 0 | F33: 0 | G33: 0 | H33: 0 | I33: 0 | J33: =SUMPRODUCT(B33:I33,$B$11:$I$11) -> 0 | K33: =J33+J32 -> 0 | L33: =SUM(J30:J33) -> 2 | M33: =SUM(C30:I33) -> 2
A34: 11:00-11:15 | B34: 0 | C34: 0 | D34: 2 | E34: 0 | F34: 0 | G34: 0 | H34: 0 | I34: 0 | J34: =SUMPRODUCT(B34:I34,$B$11:$I$11) -> 2
A35: 11:15-11:30 | B35: 0 | C35: 0 | D35: 2 | E35: 0 | F35: 0 | G35: 0 | H35: 0 | I35: 0 | J35: =SUMPRODUCT(B35:I35,$B$11:$I$11) -> 2 | K35: =J35+J34 -> 4
A36: 11:30-11:45 | B36: 0 | C36: 1 | D36: 3 | E36: 0 | F36: 0 | G36: 0 | H36: 0 | I36: 0 | J36: =SUMPRODUCT(B36:I36,$B$11:$I$11) -> 4
A37: 11:45-12:00 | B37: 0 | C37: 0 | D37: 2 | E37: 0 | F37: 0 | G37: 0 | H37: 0 | I37: 0 | J37: =SUMPRODUCT(B37:I37,$B$11:$I$11) -> 2 | K37: =J37+J36 -> 6 | L37: =SUM(J34:J37) -> 10 | M37: =SUM(C34:I37) -> 10
A38: 12:00-12:15 | B38: 0 | C38: 0 | D38: 3 | E38: 0 | F38: 0 | G38: 1 | H38: 0 | I38: 0 | J38: =SUMPRODUCT(B38:I38,$B$11:$I$11) -> 4.5
A39: 12:15-12:30 | B39: 0 | C39: 0 | D39: 6 | E39: 0 | F39: 0 | G39: 0 | H39: 0 | I39: 0 | J39: =SUMPRODUCT(B39:I39,$B$11:$I$11) -> 6 | K39: =J39+J38 -> 10.5
A40: 12:30-12:45 | B40: 0 | C40: 0 | D40: 2 | E40: 0 | F40: 0 | G40: 0 | H40: 0 | I40: 0 | J40: =SUMPRODUCT(B40:I40,$B$11:$I$11) -> 2
A41: 12:45-13:00 | B41: 0 | C41: 0 | D41: 2 | E41: 0 | F41: 0 | G41: 0 | H41: 0 | I41: 0 | J41: =SUMPRODUCT(B41:I41,$B$11:$I$11) -> 2 | K41: =J41+J40 -> 4 | L41: =SUM(J38:J41) -> 14.5 | M41: =SUM(C38:I41) -> 14
A42: 13:00-13:15 | B42: 0 | C42: 0 | D42: 0 | E42: 0 | F42: 0 | G42: 0 | H42: 0 | I42: 0 | J42: =SUMPRODUCT(B42:I42,$B$11:$I$11) -> 0
...

Sheet R2
A3: ICRA Schwap e.U.
A4: VERKEHRSZÄHLUNG - PKW-Einheiten
A5: Datum : | J5: Lfd. Nummer : | K5: 0
A6: ='Deckbl.'!I11 -> 45036 | J6: Wetter : | K6: ='Deckbl.'!I12 -> morgens leichter Regen, dann Sonne, 5-17°
B7: Verkehrszählung : | C7: ='Deckbl.'!C8 -> Sandleiten / Schulstraße / Parkstraße (Pregarten)
B8: Zählstelle : | I8: Sachbearbeiter : | J8: ICRA / Schwap
B9: Richtung : | C9: R2 | I9: Uhrzeit : | J9: ='Deckbl.'!C11 -> 6-20
B10: Bemerkung : | I10: Dateiname:
A11: Faktoren | B11: 0.5 | C11: 1 | D11: ='Faktoren PKW-E'!B16 -> 1 | E11: 1.5 | F11: 1.5 | G11: 1.5 | H11: 2 | I11: 1.5
C12: einsp. | D12: PKW | E12: Lin. | F12: Reis. | H12: LKW + | I12: sonst. | J12: PKW-E | K12: PKW-E | L12: PKW-E | M12: KFZ
A13: Zeit | B13: Rad | C13: KFZ | D13: Kombi | E13: Bus | F13: Bus | G13: LKW | H13: Anh. | I13: KFZ | J13: / 15 min | K13: / 30 min | L13: / 1 Std. | M13: / 1 Std.
A14: 6:00-6:15 | B14: 0 | C14: 0 | D14: 2 | E14: 0 | F14: 0 | G14: 0 | H14: 0 | I14: 0 | J14: =SUMPRODUCT(B14:I14,$B$11:$I$11) -> 2
A15: 6:15-6:30 | B15: 0 | C15: 0 | D15: 3 | E15: 0 | F15: 0 | G15: 0 | H15: 0 | I15: 0 | J15: =SUMPRODUCT(B15:I15,$B$11:$I$11) -> 3 | K15: =J15+J14 -> 5
A16: 6:30-6:45 | B16: 1 | C16: 0 | D16: 0 | E16: 0 | F16: 0 | G16: 0 | H16: 0 | I16: 0 | J16: =SUMPRODUCT(B16:I16,$B$11:$I$11) -> 0.5
A17: 6:45-7:00 | B17: 0 | C17: 0 | D17: 3 | E17: 0 | F17: 0 | G17: 0 | H17: 0 | I17: 0 | J17: =SUMPRODUCT(B17:I17,$B$11:$I$11) -> 3 | K17: =J17+J16 -> 3.5 | L17: =SUM(J14:J17) -> 8.5 | M17: =SUM(C14:I17) -> 8
A18: 7:00-7:15 | B18: 0 | C18: 0 | D18: 7 | E18: 0 | F18: 0 | G18: 0 | H18: 0 | I18: 0 | J18: =SUMPRODUCT(B18:I18,$B$11:$I$11) -> 7
A19: 7:15-7:30 | B19: 1 | C19: 0 | D19: 5 | E19: 0 | F19: 0 | G19: 0 | H19: 0 | I19: 0 | J19: =SUMPRODUCT(B19:I19,$B$11:$I$11) -> 5.5 | K19: =J19+J18 -> 12.5
A20: 7:30-7:45 | B20: 0 | C20: 0 | D20: 8 | E20: 0 | F20: 0 | G20: 0 | H20: 0 | I20: 0 | J20: =SUMPRODUCT(B20:I20,$B$11:$I$11) -> 8
A21: 7:45-8:00 | B21: 0 | C21: 0 | D21: 15 | E21: 0 | F21: 0 | G21: 0 | H21: 0 | I21: 0 | J21: =SUMPRODUCT(B21:I21,$B$11:$I$11) -> 15 | K21: =J21+J20 -> 23 | L21: =SUM(J18:J21) -> 35.5 | M21: =SUM(C18:I21) -> 35
A22: 8:00-8:15 | B22: 0 | C22: 0 | D22: 1 | E22: 0 | F22: 0 | G22: 0 | H22: 0 | I22: 0 | J22: =SUMPRODUCT(B22:I22,$B$11:$I$11) -> 1
A23: 8:15-8:30 | B23: 0 | C23: 0 | D23: 4 | E23: 0 | F23: 0 | G23: 0 | H23: 0 | I23: 0 | J23: =SUMPRODUCT(B23:I23,$B$11:$I$11) -> 4 | K23: =J23+J22 -> 5
A24: 8:30-8:45 | B24: 0 | C24: 0 | D24: 2 | E24: 0 | F24: 0 | G24: 0 | H24: 0 | I24: 1 | J24: =SUMPRODUCT(B24:I24,$B$11:$I$11) -> 3.5
A25: 8:45-9:00 | B25: 0 | C25: 0 | D25: 1 | E25: 0 | F25: 0 | G25: 0 | H25: 0 | I25: 0 | J25: =SUMPRODUCT(B25:I25,$B$11:$I$11) -> 1 | K25: =J25+J24 -> 4.5 | L25: =SUM(J22:J25) -> 9.5 | M25: =SUM(C22:I25) -> 9
A26: 9:00-9:15 | B26: 0 | C26: 0 | D26: 0 | E26: 0 | F26: 0 | G26: 0 | H26: 0 | I26: 0 | J26: =SUMPRODUCT(B26:I26,$B$11:$I$11) -> 0
A27: 9:15-9:30 | B27: 0 | C27: 0 | D27: 4 | E27: 0 | F27: 0 | G27: 0 | H27: 0 | I27: 0 | J27: =SUMPRODUCT(B27:I27,$B$11:$I$11) -> 4 | K27: =J27+J26 -> 4
A28: 9:30-9:45 | B28: 0 | C28: 0 | D28: 0 | E28: 0 | F28: 0 | G28: 0 | H28: 0 | I28: 0 | J28: =SUMPRODUCT(B28:I28,$B$11:$I$11) -> 0
A29: 9:45-10:00 | B29: 1 | C29: 0 | D29: 1 | E29: 0 | F29: 0 | G29: 1 | H29: 0 | I29: 0 | J29: =SUMPRODUCT(B29:I29,$B$11:$I$11) -> 3 | K29: =J29+J28 -> 3 | L29: =SUM(J26:J29) -> 7 | M29: =SUM(C26:I29) -> 6
A30: 10:00-10:15 | B30: 0 | C30: 0 | D30: 0 | E30: 0 | F30: 0 | G30: 0 | H30: 0 | I30: 1 | J30: =SUMPRODUCT(B30:I30,$B$11:$I$11) -> 1.5
A31: 10:15-10:30 | B31: 0 | C31: 0 | D31: 0 | E31: 0 | F31: 0 | G31: 0 | H31: 0 | I31: 0 | J31: =SUMPRODUCT(B31:I31,$B$11:$I$11) -> 0 | K31: =J31+J30 -> 1.5
A32: 10:30-10:45 | B32: 0 | C32: 0 | D32: 1 | E32: 0 | F32: 0 | G32: 0 | H32: 0 | I32: 0 | J32: =SUMPRODUCT(B32:I32,$B$11:$I$11) -> 1
A33: 10:45-11:00 | B33: 0 | C33: 0 | D33: 2 | E33: 0 | F33: 0 | G33: 0 | H33: 0 | I33: 0 | J33: =SUMPRODUCT(B33:I33,$B$11:$I$11) -> 2 | K33: =J33+J32 -> 3 | L33: =SUM(J30:J33) -> 4.5 | M33: =SUM(C30:I33) -> 4
A34: 11:00-11:15 | B34: 0 | C34: 0 | D34: 4 | E34: 0 | F34: 0 | G34: 0 | H34: 0 | I34: 0 | J34: =SUMPRODUCT(B34:I34,$B$11:$I$11) -> 4
A35: 11:15-11:30 | B35: 0 | C35: 0 | D35: 1 | E35: 0 | F35: 0 | G35: 0 | H35: 0 | I35: 0 | J35: =SUMPRODUCT(B35:I35,$B$11:$I$11) -> 1 | K35: =J35+J34 -> 5
A36: 11:30-11:45 | B36: 0 | C36: 0 | D36: 5 | E36: 0 | F36: 0 | G36: 0 | H36: 0 | I36: 0 | J36: =SUMPRODUCT(B36:I36,$B$11:$I$11) -> 5
A37: 11:45-12:00 | B37: 0 | C37: 0 | D37: 7 | E37: 0 | F37: 0 | G37: 0 | H37: 0 | I37: 0 | J37: =SUMPRODUCT(B37:I37,$B$11:$I$11) -> 7 | K37: =J37+J36 -> 12 | L37: =SUM(J34:J37) -> 17 | M37: =SUM(C34:I37) -> 17
A38: 12:00-12:15 | B38: 0 | C38: 0 | D38: 0 | E38: 0 | F38: 0 | G38: 0 | H38: 0 | I38: 0 | J38: =SUMPRODUCT(B38:I38,$B$11:$I$11) -> 0
A39: 12:15-12:30 | B39: 0 | C39: 0 | D39: 1 | E39: 0 | F39: 0 | G39: 0 | H39: 0 | I39: 0 | J39: =SUMPRODUCT(B39:I39,$B$11:$I$11) -> 1 | K39: =J39+J38 -> 1
A40: 12:30-12:45 | B40: 1 | C40: 0 | D40: 1 | E40: 0 | F40: 0 | G40: 0 | H40: 0 | I40: 0 | J40: =SUMPRODUCT(B40:I40,$B$11:$I$11) -> 1.5
A41: 12:45-13:00 | B41: 2 | C41: 0 | D41: 2 | E41: 0 | F41: 0 | G41: 0 | H41: 0 | I41: 0 | J41: =SUMPRODUCT(B41:I41,$B$11:$I$11) -> 3 | K41: =J41+J40 -> 4.5 | L41: =SUM(J38:J41) -> 5.5 | M41: =SUM(C38:I41) -> 4
A42: 13:00-13:15 | B42: 0 | C42: 0 | D42: 2 | E42: 0 | F42: 0 | G42: 0 | H42: 0 | I42: 0 | J42: =SUMPRODUCT(B42:I42,$B$11:$I$11) -> 2
...

Sheet R8
A3: ICRA Schwap e.U.
A4: VERKEHRSZÄHLUNG - PKW-Einheiten
A5: Datum : | J5: Lfd. Nummer : | K5: 0
A6: ='Deckbl.'!I11 -> 45036 | J6: Wetter : | K6: ='Deckbl.'!I12 -> morgens leichter Regen, dann Sonne, 5-17°
B7: Verkehrszählung : | C7: ='Deckbl.'!C8 -> Sandleiten / Schulstraße / Parkstraße (Pregarten)
B8: Zählstelle : | I8: Sachbearbeiter : | J8: ICRA / Schwap
B9: Richtung : | C9: R8 | I9: Uhrzeit : | J9: ='Deckbl.'!C11 -> 6-20
B10: Bemerkung : | I10: Dateiname:
A11: Faktoren | B11: 0.5 | C11: 1 | D11: ='Faktoren PKW-E'!B16 -> 1 | E11: 1.5 | F11: 1.5 | G11: 1.5 | H11: 2 | I11: 1.5
C12: einsp. | D12: PKW | E12: Lin. | F12: Reis. | H12: LKW + | I12: sonst. | J12: PKW-E | K12: PKW-E | L12: PKW-E | M12: KFZ
A13: Zeit | B13: Rad | C13: KFZ | D13: Kombi | E13: Bus | F13: Bus | G13: LKW | H13: Anh. | I13: KFZ | J13: / 15 min | K13: / 30 min | L13: / 1 Std. | M13: / 1 Std.
A14: 6:00-6:15 | B14: 0 | C14: 0 | D14: 0 | E14: 0 | F14: 0 | G14: 0 | H14: 0 | I14: 0 | J14: =SUMPRODUCT(B14:I14,$B$11:$I$11) -> 0
A15: 6:15-6:30 | B15: 0 | C15: 0 | D15: 2 | E15: 0 | F15: 0 | G15: 0 | H15: 0 | I15: 0 | J15: =SUMPRODUCT(B15:I15,$B$11:$I$11) -> 2 | K15: =J15+J14 -> 2
A16: 6:30-6:45 | B16: 0 | C16: 0 | D16: 1 | E16: 0 | F16: 0 | G16: 0 | H16: 0 | I16: 0 | J16: =SUMPRODUCT(B16:I16,$B$11:$I$11) -> 1
A17: 6:45-7:00 | B17: 0 | C17: 0 | D17: 3 | E17: 0 | F17: 0 | G17: 0 | H17: 0 | I17: 0 | J17: =SUMPRODUCT(B17:I17,$B$11:$I$11) -> 3 | K17: =J17+J16 -> 4 | L17: =SUM(J14:J17) -> 6 | M17: =SUM(C14:I17) -> 6
A18: 7:00-7:15 | B18: 0 | C18: 0 | D18: 3 | E18: 0 | F18: 0 | G18: 0 | H18: 0 | I18: 0 | J18: =SUMPRODUCT(B18:I18,$B$11:$I$11) -> 3
A19: 7:15-7:30 | B19: 0 | C19: 0 | D19: 2 | E19: 0 | F19: 0 | G19: 0 | H19: 0 | I19: 0 | J19: =SUMPRODUCT(B19:I19,$B$11:$I$11) -> 2 | K19: =J19+J18 -> 5
A20: 7:30-7:45 | B20: 0 | C20: 0 | D20: 3 | E20: 0 | F20: 0 | G20: 0 | H20: 0 | I20: 0 | J20: =SUMPRODUCT(B20:I20,$B$11:$I$11) -> 3
A21: 7:45-8:00 | B21: 0 | C21: 0 | D21: 11 | E21: 0 | F21: 0 | G21: 0 | H21: 0 | I21: 0 | J21: =SUMPRODUCT(B21:I21,$B$11:$I$11) -> 11 | K21: =J21+J20 -> 14 | L21: =SUM(J18:J21) -> 19 | M21: =SUM(C18:I21) -> 19
A22: 8:00-8:15 | B22: 0 | C22: 0 | D22: 2 | E22: 0 | F22: 0 | G22: 0 | H22: 0 | I22: 0 | J22: =SUMPRODUCT(B22:I22,$B$11:$I$11) -> 2
A23: 8:15-8:30 | B23: 0 | C23: 0 | D23: 1 | E23: 0 | F23: 0 | G23: 0 | H23: 0 | I23: 1 | J23: =SUMPRODUCT(B23:I23,$B$11:$I$11) -> 2.5 | K23: =J23+J22 -> 4.5
A24: 8:30-8:45 | B24: 0 | C24: 0 | D24: 2 | E24: 0 | F24: 0 | G24: 0 | H24: 0 | I24: 0 | J24: =SUMPRODUCT(B24:I24,$B$11:$I$11) -> 2
A25: 8:45-9:00 | B25: 0 | C25: 0 | D25: 1 | E25: 0 | F25: 0 | G25: 0 | H25: 0 | I25: 1 | J25: =SUMPRODUCT(B25:I25,$B$11:$I$11) -> 2.5 | K25: =J25+J24 -> 4.5 | L25: =SUM(J22:J25) -> 9 | M25: =SUM(C22:I25) -> 8
A26: 9:00-9:15 | B26: 0 | C26: 0 | D26: 0 | E26: 0 | F26: 0 | G26: 0 | H26: 0 | I26: 0 | J26: =SUMPRODUCT(B26:I26,$B$11:$I$11) -> 0
A27: 9:15-9:30 | B27: 0 | C27: 0 | D27: 0 | E27: 0 | F27: 0 | G27: 0 | H27: 0 | I27: 0 | J27: =SUMPRODUCT(B27:I27,$B$11:$I$11) -> 0 | K27: =J27+J26 -> 0
A28: 9:30-9:45 | B28: 0 | C28: 0 | D28: 1 | E28: 0 | F28: 0 | G28: 0 | H28: 0 | I28: 0 | J28: =SUMPRODUCT(B28:I28,$B$11:$I$11) -> 1
A29: 9:45-10:00 | B29: 0 | C29: 0 | D29: 1 | E29: 0 | F29: 0 | G29: 0 | H29: 0 | I29: 0 | J29: =SUMPRODUCT(B29:I29,$B$11:$I$11) -> 1 | K29: =J29+J28 -> 2 | L29: =SUM(J26:J29) -> 2 | M29: =SUM(C26:I29) -> 2
A30: 10:00-10:15 | B30: 0 | C30: 0 | D30: 1 | E30: 0 | F30: 0 | G30: 0 | H30: 0 | I30: 0 | J30: =SUMPRODUCT(B30:I30,$B$11:$I$11) -> 1
A31: 10:15-10:30 | B31: 1 | C31: 0 | D31: 0 | E31: 0 | F31: 0 | G31: 0 | H31: 0 | I31: 0 | J31: =SUMPRODUCT(B31:I31,$B$11:$I$11) -> 0.5 | K31: =J31+J30 -> 1.5
A32: 10:30-10:45 | B32: 0 | C32: 0 | D32: 6 | E32: 0 | F32: 0 | G32: 0 | H32: 0 | I32: 0 | J32: =SUMPRODUCT(B32:I32,$B$11:$I$11) -> 6
A33: 10:45-11:00 | B33: 0 | C33: 0 | D33: 1 | E33: 0 | F33: 0 | G33: 0 | H33: 0 | I33: 0 | J33: =SUMPRODUCT(B33:I33,$B$11:$I$11) -> 1 | K33: =J33+J32 -> 7 | L33: =SUM(J30:J33) -> 8.5 | M33: =SUM(C30:I33) -> 8
A34: 11:00-11:15 | B34: 0 | C34: 0 | D34: 3 | E34: 0 | F34: 0 | G34: 0 | H34: 0 | I34: 0 | J34: =SUMPRODUCT(B34:I34,$B$11:$I$11) -> 3
A35: 11:15-11:30 | B35: 0 | C35: 1 | D35: 4 | E35: 0 | F35: 0 | G35: 0 | H35: 0 | I35: 0 | J35: =SUMPRODUCT(B35:I35,$B$11:$I$11) -> 5 | K35: =J35+J34 -> 8
A36: 11:30-11:45 | B36: 0 | C36: 0 | D36: 7 | E36: 0 | F36: 0 | G36: 0 | H36: 0 | I36: 0 | J36: =SUMPRODUCT(B36:I36,$B$11:$I$11) -> 7
A37: 11:45-12:00 | B37: 0 | C37: 0 | D37: 7 | E37: 0 | F37: 0 | G37: 0 | H37: 0 | I37: 0 | J37: =SUMPRODUCT(B37:I37,$B$11:$I$11) -> 7 | K37: =J37+J36 -> 14 | L37: =SUM(J34:J37) -> 22 | M37: =SUM(C34:I37) -> 22
A38: 12:00-12:15 | B38: 0 | C38: 0 | D38: 2 | E38: 0 | F38: 0 | G38: 0 | H38: 0 | I38: 0 | J38: =SUMPRODUCT(B38:I38,$B$11:$I$11) -> 2
A39: 12:15-12:30 | B39: 1 | C39: 0 | D39: 1 | E39: 0 | F39: 0 | G39: 0 | H39: 0 | I39: 0 | J39: =SUMPRODUCT(B39:I39,$B$11:$I$11) -> 1.5 | K39: =J39+J38 -> 3.5
A40: 12:30-12:45 | B40: 0 | C40: 0 | D40: 5 | E40: 0 | F40: 0 | G40: 0 | H40: 0 | I40: 0 | J40: =SUMPRODUCT(B40:I40,$B$11:$I$11) -> 5
A41: 12:45-13:00 | B41: 0 | C41: 0 | D41: 1 | E41: 0 | F41: 0 | G41: 0 | H41: 0 | I41: 0 | J41: =SUMPRODUCT(B41:I41,$B$11:$I$11) -> 1 | K41: =J41+J40 -> 6 | L41: =SUM(J38:J41) -> 9.5 | M41: =SUM(C38:I41) -> 9
A42: 13:00-13:15 | B42: 0 | C42: 0 | D42: 2 | E42: 0 | F42: 0 | G42: 0 | H42: 0 | I42: 0 | J42: =SUMPRODUCT(B42:I42,$B$11:$I$11) -> 2
...

Sheet R9
A3: ICRA Schwap e.U.
A4: VERKEHRSZÄHLUNG - PKW-Einheiten
A5: Datum : | J5: Lfd. Nummer : | K5: 0
A6: ='Deckbl.'!I11 -> 45036 | J6: Wetter : | K6: ='Deckbl.'!I12 -> morgens leichter Regen, dann Sonne, 5-17°
B7: Verkehrszählung : | C7: ='Deckbl.'!C8 -> Sandleiten / Schulstraße / Parkstraße (Pregarten)
B8: Zählstelle : | I8: Sachbearbeiter : | J8: ICRA / Schwap
B9: Richtung : | C9: R9 | I9: Uhrzeit : | J9: ='Deckbl.'!C11 -> 6-20
B10: Bemerkung : | I10: Dateiname:
A11: Faktoren | B11: 0.5 | C11: 1 | D11: ='Faktoren PKW-E'!B16 -> 1 | E11: 1.5 | F11: 1.5 | G11: 1.5 | H11: 2 | I11: 1.5
C12: einsp. | D12: PKW | E12: Lin. | F12: Reis. | H12: LKW + | I12: sonst. | J12: PKW-E | K12: PKW-E | L12: PKW-E | M12: KFZ
A13: Zeit | B13: Rad | C13: KFZ | D13: Kombi | E13: Bus | F13: Bus | G13: LKW | H13: Anh. | I13: KFZ | J13: / 15 min | K13: / 30 min | L13: / 1 Std. | M13: / 1 Std.
A14: 6:00-6:15 | B14: 0 | C14: 0 | D14: 3 | E14: 0 | F14: 0 | G14: 0 | H14: 0 | I14: 0 | J14: =SUMPRODUCT(B14:I14,$B$11:$I$11) -> 3
A15: 6:15-6:30 | B15: 0 | C15: 0 | D15: 2 | E15: 0 | F15: 0 | G15: 0 | H15: 0 | I15: 0 | J15: =SUMPRODUCT(B15:I15,$B$11:$I$11) -> 2 | K15: =J15+J14 -> 5
A16: 6:30-6:45 | B16: 0 | C16: 0 | D16: 7 | E16: 0 | F16: 0 | G16: 1 | H16: 0 | I16: 0 | J16: =SUMPRODUCT(B16:I16,$B$11:$I$11) -> 8.5
A17: 6:45-7:00 | B17: 1 | C17: 0 | D17: 7 | E17: 0 | F17: 0 | G17: 0 | H17: 0 | I17: 0 | J17: =SUMPRODUCT(B17:I17,$B$11:$I$11) -> 7.5 | K17: =J17+J16 -> 16 | L17: =SUM(J14:J17) -> 21 | M17: =SUM(C14:I17) -> 20
A18: 7:00-7:15 | B18: 0 | C18: 0 | D18: 12 | E18: 0 | F18: 0 | G18: 0 | H18: 0 | I18: 0 | J18: =SUMPRODUCT(B18:I18,$B$11:$I$11) -> 12
A19: 7:15-7:30 | B19: 0 | C19: 0 | D19: 22 | E19: 0 | F19: 0 | G19: 0 | H19: 0 | I19: 0 | J19: =SUMPRODUCT(B19:I19,$B$11:$I$11) -> 22 | K19: =J19+J18 -> 34
A20: 7:30-7:45 | B20: 0 | C20: 0 | D20: 46 | E20: 0 | F20: 1 | G20: 0 | H20: 0 | I20: 0 | J20: =SUMPRODUCT(B20:I20,$B$11:$I$11) -> 47.5
A21: 7:45-8:00 | B21: 0 | C21: 0 | D21: 18 | E21: 0 | F21: 0 | G21: 0 | H21: 0 | I21: 0 | J21: =SUMPRODUCT(B21:I21,$B$11:$I$11) -> 18 | K21: =J21+J20 -> 65.5 | L21: =SUM(J18:J21) -> 99.5 | M21: =SUM(C18:I21) -> 99
A22: 8:00-8:15 | B22: 0 | C22: 0 | D22: 8 | E22: 0 | F22: 0 | G22: 0 | H22: 0 | I22: 0 | J22: =SUMPRODUCT(B22:I22,$B$11:$I$11) -> 8
A23: 8:15-8:30 | B23: 0 | C23: 0 | D23: 9 | E23: 0 | F23: 0 | G23: 0 | H23: 0 | I23: 0 | J23: =SUMPRODUCT(B23:I23,$B$11:$I$11) -> 9 | K23: =J23+J22 -> 17
A24: 8:30-8:45 | B24: 1 | C24: 0 | D24: 3 | E24: 0 | F24: 0 | G24: 0 | H24: 0 | I24: 0 | J24: =SUMPRODUCT(B24:I24,$B$11:$I$11) -> 3.5
A25: 8:45-9:00 | B25: 0 | C25: 0 | D25: 11 | E25: 0 | F25: 0 | G25: 0 | H25: 0 | I25: 0 | J25: =SUMPRODUCT(B25:I25,$B$11:$I$11) -> 11 | K25: =J25+J24 -> 14.5 | L25: =SUM(J22:J25) -> 31.5 | M25: =SUM(C22:I25) -> 31
A26: 9:00-9:15 | B26: 0 | C26: 0 | D26: 6 | E26: 0 | F26: 0 | G26: 0 | H26: 0 | I26: 0 | J26: =SUMPRODUCT(B26:I26,$B$11:$I$11) -> 6
A27: 9:15-9:30 | B27: 0 | C27: 0 | D27: 10 | E27: 0 | F27: 0 | G27: 0 | H27: 0 | I27: 0 | J27: =SUMPRODUCT(B27:I27,$B$11:$I$11) -> 10 | K27: =J27+J26 -> 16
A28: 9:30-9:45 | B28: 0 | C28: 0 | D28: 6 | E28: 0 | F28: 0 | G28: 0 | H28: 0 | I28: 0 | J28: =SUMPRODUCT(B28:I28,$B$11:$I$11) -> 6
A29: 9:45-10:00 | B29: 0 | C29: 0 | D29: 5 | E29: 0 | F29: 0 | G29: 0 | H29: 0 | I29: 0 | J29: =SUMPRODUCT(B29:I29,$B$11:$I$11) -> 5 | K29: =J29+J28 -> 11 | L29: =SUM(J26:J29) -> 27 | M29: =SUM(C26:I29) -> 27
A30: 10:00-10:15 | B30: 0 | C30: 0 | D30: 2 | E30: 0 | F30: 0 | G30: 0 | H30: 0 | I30: 0 | J30: =SUMPRODUCT(B30:I30,$B$11:$I$11) -> 2
A31: 10:15-10:30 | B31: 0 | C31: 0 | D31: 11 | E31: 0 | F31: 0 | G31: 0 | H31: 0 | I31: 0 | J31: =SUMPRODUCT(B31:I31,$B$11:$I$11) -> 11 | K31: =J31+J30 -> 13
A32: 10:30-10:45 | B32: 0 | C32: 0 | D32: 7 | E32: 0 | F32: 0 | G32: 0 | H32: 0 | I32: 0 | J32: =SUMPRODUCT(B32:I32,$B$11:$I$11) -> 7
A33: 10:45-11:00 | B33: 1 | C33: 0 | D33: 2 | E33: 0 | F33: 0 | G33: 0 | H33: 0 | I33: 0 | J33: =SUMPRODUCT(B33:I33,$B$11:$I$11) -> 2.5 | K33: =J33+J32 -> 9.5 | L33: =SUM(J30:J33) -> 22.5 | M33: =SUM(C30:I33) -> 22
A34: 11:00-11:15 | B34: 0 | C34: 0 | D34: 12 | E34: 0 | F34: 0 | G34: 0 | H34: 0 | I34: 0 | J34: =SUMPRODUCT(B34:I34,$B$11:$I$11) -> 12
A35: 11:15-11:30 | B35: 0 | C35: 0 | D35: 22 | E35: 0 | F35: 0 | G35: 0 | H35: 0 | I35: 0 | J35: =SUMPRODUCT(B35:I35,$B$11:$I$11) -> 22 | K35: =J35+J34 -> 34
A36: 11:30-11:45 | B36: 0 | C36: 0 | D36: 10 | E36: 0 | F36: 0 | G36: 0 | H36: 0 | I36: 0 | J36: =SUMPRODUCT(B36:I36,$B$11:$I$11) -> 10
A37: 11:45-12:00 | B37: 1 | C37: 0 | D37: 15 | E37: 0 | F37: 0 | G37: 0 | H37: 0 | I37: 0 | J37: =SUMPRODUCT(B37:I37,$B$11:$I$11) -> 15.5 | K37: =J37+J36 -> 25.5 | L37: =SUM(J34:J37) -> 59.5 | M37: =SUM(C34:I37) -> 59
A38: 12:00-12:15 | B38: 1 | C38: 1 | D38: 6 | E38: 0 | F38: 0 | G38: 0 | H38: 0 | I38: 0 | J38: =SUMPRODUCT(B38:I38,$B$11:$I$11) -> 7.5
A39: 12:15-12:30 | B39: 0 | C39: 0 | D39: 12 | E39: 0 | F39: 0 | G39: 0 | H39: 0 | I39: 0 | J39: =SUMPRODUCT(B39:I39,$B$11:$I$11) -> 12 | K39: =J39+J38 -> 19.5
A40: 12:30-12:45 | B40: 0 | C40: 0 | D40: 7 | E40: 0 | F40: 0 | G40: 0 | H40: 0 | I40: 0 | J40: =SUMPRODUCT(B40:I40,$B$11:$I$11) -> 7
A41: 12:45-13:00 | B41: 1 | C41: 1 | D41: 9 | E41: 0 | F41: 0 | G41: 0 | H41: 0 | I41: 0 | J41: =SUMPRODUCT(B41:I41,$B$11:$I$11) -> 10.5 | K41: =J41+J40 -> 17.5 | L41: =SUM(J38:J41) -> 37 | M41: =SUM(C38:I41) -> 36
A42: 13:00-13:15 | B42: 0 | C42: 0 | D42: 9 | E42: 0 | F42: 0 | G42: 0 | H42: 0 | I42: 0 | J42: =SUMPRODUCT(B42:I42,$B$11:$I$11) -> 9
...

Sheet R10
A3: ICRA Schwap e.U.
A4: VERKEHRSZÄHLUNG - PKW-Einheiten
A5: Datum : | J5: Lfd. Nummer : | K5: 0
A6: ='Deckbl.'!I11 -> 45036 | J6: Wetter : | K6: ='Deckbl.'!I12 -> morgens leichter Regen, dann Sonne, 5-17°
B7: Verkehrszählung : | C7: ='Deckbl.'!C8 -> Sandleiten / Schulstraße / Parkstraße (Pregarten)
B8: Zählstelle : | I8: Sachbearbeiter : | J8: ICRA / Schwap
B9: Richtung : | C9: R10 | I9: Uhrzeit : | J9: ='Deckbl.'!C11 -> 6-20
B10: Bemerkung : | I10: Dateiname:
A11: Faktoren | B11: 0.5 | C11: 1 | D11: ='Faktoren PKW-E'!B16 -> 1 | E11: 1.5 | F11: 1.5 | G11: 1.5 | H11: 2 | I11: 1.5
C12: einsp. | D12: PKW | E12: Lin. | F12: Reis. | H12: LKW + | I12: sonst. | J12: PKW-E | K12: PKW-E | L12: PKW-E | M12: KFZ
A13: Zeit | B13: Rad | C13: KFZ | D13: Kombi | E13: Bus | F13: Bus | G13: LKW | H13: Anh. | I13: KFZ | J13: / 15 min | K13: / 30 min | L13: / 1 Std. | M13: / 1 Std.
A14: 6:00-6:15 | B14: 0 | C14: 0 | D14: 3 | E14: 0 | F14: 0 | G14: 0 | H14: 0 | I14: 0 | J14: =SUMPRODUCT(B14:I14,$B$11:$I$11) -> 3
A15: 6:15-6:30 | B15: 0 | C15: 0 | D15: 4 | E15: 0 | F15: 0 | G15: 0 | H15: 0 | I15: 0 | J15: =SUMPRODUCT(B15:I15,$B$11:$I$11) -> 4 | K15: =J15+J14 -> 7
A16: 6:30-6:45 | B16: 0 | C16: 0 | D16: 9 | E16: 0 | F16: 0 | G16: 1 | H16: 0 | I16: 0 | J16: =SUMPRODUCT(B16:I16,$B$11:$I$11) -> 10.5
A17: 6:45-7:00 | B17: 1 | C17: 0 | D17: 10 | E17: 1 | F17: 0 | G17: 0 | H17: 0 | I17: 0 | J17: =SUMPRODUCT(B17:I17,$B$11:$I$11) -> 12 | K17: =J17+J16 -> 22.5 | L17: =SUM(J14:J17) -> 29.5 | M17: =SUM(C14:I17) -> 28
A18: 7:00-7:15 | B18: 0 | C18: 0 | D18: 15 | E18: 0 | F18: 0 | G18: 0 | H18: 0 | I18: 0 | J18: =SUMPRODUCT(B18:I18,$B$11:$I$11) -> 15
A19: 7:15-7:30 | B19: 0 | C19: 0 | D19: 18 | E19: 0 | F19: 0 | G19: 0 | H19: 0 | I19: 0 | J19: =SUMPRODUCT(B19:I19,$B$11:$I$11) -> 18 | K19: =J19+J18 -> 33
A20: 7:30-7:45 | B20: 0 | C20: 0 | D20: 15 | E20: 0 | F20: 0 | G20: 0 | H20: 0 | I20: 0 | J20: =SUMPRODUCT(B20:I20,$B$11:$I$11) -> 15
A21: 7:45-8:00 | B21: 0 | C21: 0 | D21: 9 | E21: 0 | F21: 0 | G21: 0 | H21: 0 | I21: 0 | J21: =SUMPRODUCT(B21:I21,$B$11:$I$11) -> 9 | K21: =J21+J20 -> 24 | L21: =SUM(J18:J21) -> 57 | M21: =SUM(C18:I21) -> 57
A22: 8:00-8:15 | B22: 0 | C22: 0 | D22: 17 | E22: 0 | F22: 0 | G22: 0 | H22: 0 | I22: 0 | J22: =SUMPRODUCT(B22:I22,$B$11:$I$11) -> 17
A23: 8:15-8:30 | B23: 0 | C23: 0 | D23: 12 | E23: 0 | F23: 0 | G23: 0 | H23: 0 | I23: 0 | J23: =SUMPRODUCT(B23:I23,$B$11:$I$11) -> 12 | K23: =J23+J22 -> 29
A24: 8:30-8:45 | B24: 1 | C24: 0 | D24: 7 | E24: 0 | F24: 0 | G24: 0 | H24: 0 | I24: 0 | J24: =SUMPRODUCT(B24:I24,$B$11:$I$11) -> 7.5
A25: 8:45-9:00 | B25: 1 | C25: 0 | D25: 5 | E25: 0 | F25: 0 | G25: 0 | H25: 1 | I25: 0 | J25: =SUMPRODUCT(B25:I25,$B$11:$I$11) -> 7.5 | K25: =J25+J24 -> 15 | L25: =SUM(J22:J25) -> 44 | M25: =SUM(C22:I25) -> 42
A26: 9:00-9:15 | B26: 1 | C26: 0 | D26: 7 | E26: 0 | F26: 0 | G26: 0 | H26: 0 | I26: 0 | J26: =SUMPRODUCT(B26:I26,$B$11:$I$11) -> 7.5
A27: 9:15-9:30 | B27: 0 | C27: 0 | D27: 9 | E27: 0 | F27: 0 | G27: 0 | H27: 0 | I27: 0 | J27: =SUMPRODUCT(B27:I27,$B$11:$I$11) -> 9 | K27: =J27+J26 -> 16.5
A28: 9:30-9:45 | B28: 0 | C28: 0 | D28: 5 | E28: 0 | F28: 0 | G28: 0 | H28: 0 | I28: 0 | J28: =SUMPRODUCT(B28:I28,$B$11:$I$11) -> 5
A29: 9:45-10:00 | B29: 0 | C29: 0 | D29: 8 | E29: 0 | F29: 0 | G29: 0 | H29: 0 | I29: 0 | J29: =SUMPRODUCT(B29:I29,$B$11:$I$11) -> 8 | K29: =J29+J28 -> 13 | L29: =SUM(J26:J29) -> 29.5 | M29: =SUM(C26:I29) -> 29
A30: 10:00-10:15 | B30: 1 | C30: 0 | D30: 8 | E30: 0 | F30: 0 | G30: 0 | H30: 0 | I30: 0 | J30: =SUMPRODUCT(B30:I30,$B$11:$I$11) -> 8.5
A31: 10:15-10:30 | B31: 0 | C31: 0 | D31: 10 | E31: 0 | F31: 0 | G31: 0 | H31: 0 | I31: 0 | J31: =SUMPRODUCT(B31:I31,$B$11:$I$11) -> 10 | K31: =J31+J30 -> 18.5
A32: 10:30-10:45 | B32: 0 | C32: 0 | D32: 7 | E32: 0 | F32: 0 | G32: 0 | H32: 0 | I32: 0 | J32: =SUMPRODUCT(B32:I32,$B$11:$I$11) -> 7
A33: 10:45-11:00 | B33: 0 | C33: 0 | D33: 13 | E33: 0 | F33: 0 | G33: 0 | H33: 0 | I33: 0 | J33: =SUMPRODUCT(B33:I33,$B$11:$I$11) -> 13 | K33: =J33+J32 -> 20 | L33: =SUM(J30:J33) -> 38.5 | M33: =SUM(C30:I33) -> 38
A34: 11:00-11:15 | B34: 0 | C34: 0 | D34: 10 | E34: 0 | F34: 0 | G34: 0 | H34: 0 | I34: 0 | J34: =SUMPRODUCT(B34:I34,$B$11:$I$11) -> 10
A35: 11:15-11:30 | B35: 0 | C35: 0 | D35: 8 | E35: 0 | F35: 0 | G35: 0 | H35: 0 | I35: 0 | J35: =SUMPRODUCT(B35:I35,$B$11:$I$11) -> 8 | K35: =J35+J34 -> 18
A36: 11:30-11:45 | B36: 0 | C36: 0 | D36: 13 | E36: 0 | F36: 0 | G36: 0 | H36: 0 | I36: 0 | J36: =SUMPRODUCT(B36:I36,$B$11:$I$11) -> 13
A37: 11:45-12:00 | B37: 0 | C37: 0 | D37: 17 | E37: 0 | F37: 0 | G37: 0 | H37: 0 | I37: 0 | J37: =SUMPRODUCT(B37:I37,$B$11:$I$11) -> 17 | K37: =J37+J36 -> 30 | L37: =SUM(J34:J37) -> 48 | M37: =SUM(C34:I37) -> 48
A38: 12:00-12:15 | B38: 1 | C38: 0 | D38: 12 | E38: 0 | F38: 0 | G38: 0 | H38: 0 | I38: 0 | J38: =SUMPRODUCT(B38:I38,$B$11:$I$11) -> 12.5
A39: 12:15-12:30 | B39: 1 | C39: 0 | D39: 13 | E39: 0 | F39: 0 | G39: 0 | H39: 0 | I39: 0 | J39: =SUMPRODUCT(B39:I39,$B$11:$I$11) -> 13.5 | K39: =J39+J38 -> 26
A40: 12:30-12:45 | B40: 0 | C40: 0 | D40: 5 | E40: 0 | F40: 0 | G40: 1 | H40: 0 | I40: 0 | J40: =SUMPRODUCT(B40:I40,$B$11:$I$11) -> 6.5
A41: 12:45-13:00 | B41: 0 | C41: 0 | D41: 9 | E41: 0 | F41: 1 | G41: 0 | H41: 0 | I41: 0 | J41: =SUMPRODUCT(B41:I41,$B$11:$I$11) -> 10.5 | K41: =J41+J40 -> 17 | L41: =SUM(J38:J41) -> 43 | M41: =SUM(C38:I41) -> 41
A42: 13:00-13:15 | B42: 0 | C42: 0 | D42: 9 | E42: 0 | F42: 0 | G42: 0 | H42: 0 | I42: 0 | J42: =SUMPRODUCT(B42:I42,$B$11:$I$11) -> 9
...

Sheet R12
A3: ICRA Schwap e.U.
A4: VERKEHRSZÄHLUNG - PKW-Einheiten
A5: Datum : | J5: Lfd. Nummer : | K5: 0
A6: ='Deckbl.'!I11 -> 45036 | J6: Wetter : | K6: ='Deckbl.'!I12 -> morgens leichter Regen, dann Sonne, 5-17°
B7: Verkehrszählung : | C7: ='Deckbl.'!C8 -> Sandleiten / Schulstraße / Parkstraße (Pregarten)
B8: Zählstelle : | I8: Sachbearbeiter : | J8: ICRA / Schwap
B9: Richtung : | C9: R12 | I9: Uhrzeit : | J9: ='Deckbl.'!C11 -> 6-20
B10: Bemerkung : | I10: Dateiname:
A11: Faktoren | B11: 0.5 | C11: 1 | D11: ='Faktoren PKW-E'!B16 -> 1 | E11: 1.5 | F11: 1.5 | G11: 1.5 | H11: 2 | I11: 1.5
C12: einsp. | D12: PKW | E12: Lin. | F12: Reis. | H12: LKW + | I12: sonst. | J12: PKW-E | K12: PKW-E | L12: PKW-E | M12: KFZ
A13: Zeit | B13: Rad | C13: KFZ | D13: Kombi | E13: Bus | F13: Bus | G13: LKW | H13: Anh. | I13: KFZ | J13: / 15 min | K13: / 30 min | L13: / 1 Std. | M13: / 1 Std.
A14: 6:00-6:15 | B14: 0 | C14: 0 | D14: 0 | E14: 0 | F14: 0 | G14: 0 | H14: 0 | I14: 0 | J14: =SUMPRODUCT(B14:I14,$B$11:$I$11) -> 0
A15: 6:15-6:30 | B15: 0 | C15: 0 | D15: 1 | E15: 0 | F15: 0 | G15: 0 | H15: 0 | I15: 0 | J15: =SUMPRODUCT(B15:I15,$B$11:$I$11) -> 1 | K15: =J15+J14 -> 1
A16: 6:30-6:45 | B16: 0 | C16: 0 | D16: 0 | E16: 0 | F16: 0 | G16: 0 | H16: 0 | I16: 0 | J16: =SUMPRODUCT(B16:I16,$B$11:$I$11) -> 0
A17: 6:45-7:00 | B17: 0 | C17: 0 | D17: 1 | E17: 0 | F17: 0 | G17: 0 | H17: 0 | I17: 0 | J17: =SUMPRODUCT(B17:I17,$B$11:$I$11) -> 1 | K17: =J17+J16 -> 1 | L17: =SUM(J14:J17) -> 2 | M17: =SUM(C14:I17) -> 2
A18: 7:00-7:15 | B18: 0 | C18: 0 | D18: 1 | E18: 0 | F18: 0 | G18: 0 | H18: 0 | I18: 0 | J18: =SUMPRODUCT(B18:I18,$B$11:$I$11) -> 1
A19: 7:15-7:30 | B19: 0 | C19: 0 | D19: 2 | E19: 0 | F19: 0 | G19: 0 | H19: 0 | I19: 0 | J19: =SUMPRODUCT(B19:I19,$B$11:$I$11) -> 2 | K19: =J19+J18 -> 3
A20: 7:30-7:45 | B20: 1 | C20: 0 | D20: 1 | E20: 0 | F20: 0 | G20: 0 | H20: 0 | I20: 0 | J20: =SUMPRODUCT(B20:I20,$B$11:$I$11) -> 1.5
A21: 7:45-8:00 | B21: 0 | C21: 0 | D21: 4 | E21: 0 | F21: 0 | G21: 0 | H21: 0 | I21: 0 | J21: =SUMPRODUCT(B21:I21,$B$11:$I$11) -> 4 | K21: =J21+J20 -> 5.5 | L21: =SUM(J18:J21) -> 8.5 | M21: =SUM(C18:I21) -> 8
A22: 8:00-8:15 | B22: 0 | C22: 0 | D22: 0 | E22: 0 | F22: 0 | G22: 0 | H22: 0 | I22: 0 | J22: =SUMPRODUCT(B22:I22,$B$11:$I$11) -> 0
A23: 8:15-8:30 | B23: 0 | C23: 0 | D23: 2 | E23: 0 | F23: 0 | G23: 1 | H23: 0 | I23: 0 | J23: =SUMPRODUCT(B23:I23,$B$11:$I$11) -> 3.5 | K23: =J23+J22 -> 3.5
A24: 8:30-8:45 | B24: 0 | C24: 0 | D24: 2 | E24: 0 | F24: 0 | G24: 1 | H24: 0 | I24: 0 | J24: =SUMPRODUCT(B24:I24,$B$11:$I$11) -> 3.5
A25: 8:45-9:00 | B25: 0 | C25: 0 | D25: 0 | E25: 0 | F25: 0 | G25: 0 | H25: 0 | I25: 0 | J25: =SUMPRODUCT(B25:I25,$B$11:$I$11) -> 0 | K25: =J25+J24 -> 3.5 | L25: =SUM(J22:J25) -> 7 | M25: =SUM(C22:I25) -> 6
A26: 9:00-9:15 | B26: 0 | C26: 0 | D26: 0 | E26: 0 | F26: 0 | G26: 0 | H26: 0 | I26: 0 | J26: =SUMPRODUCT(B26:I26,$B$11:$I$11) -> 0
A27: 9:15-9:30 | B27: 0 | C27: 0 | D27: 2 | E27: 0 | F27: 0 | G27: 0 | H27: 0 | I27: 0 | J27: =SUMPRODUCT(B27:I27,$B$11:$I$11) -> 2 | K27: =J27+J26 -> 2
A28: 9:30-9:45 | B28: 0 | C28: 0 | D28: 0 | E28: 0 | F28: 0 | G28: 0 | H28: 0 | I28: 0 | J28: =SUMPRODUCT(B28:I28,$B$11:$I$11) -> 0
A29: 9:45-10:00 | B29: 0 | C29: 0 | D29: 0 | E29: 0 | F29: 0 | G29: 0 | H29: 0 | I29: 0 | J29: =SUMPRODUCT(B29:I29,$B$11:$I$11) -> 0 | K29: =J29+J28 -> 0 | L29: =SUM(J26:J29) -> 2 | M29: =SUM(C26:I29) -> 2
A30: 10:00-10:15 | B30: 0 | C30: 0 | D30: 2 | E30: 0 | F30: 0 | G30: 0 | H30: 0 | I30: 0 | J30: =SUMPRODUCT(B30:I30,$B$11:$I$11) -> 2
A31: 10:15-10:30 | B31: 0 | C31: 0 | D31: 1 | E31: 0 | F31: 0 | G31: 0 | H31: 0 | I31: 0 | J31: =SUMPRODUCT(B31:I31,$B$11:$I$11) -> 1 | K31: =J31+J30 -> 3
A32: 10:30-10:45 | B32: 0 | C32: 0 | D32: 1 | E32: 0 | F32: 0 | G32: 0 | H32: 0 | I32: 0 | J32: =SUMPRODUCT(B32:I32,$B$11:$I$11) -> 1
A33: 10:45-11:00 | B33: 0 | C33: 0 | D33: 2 | E33: 0 | F33: 0 | G33: 0 | H33: 0 | I33: 0 | J33: =SUMPRODUCT(B33:I33,$B$11:$I$11) -> 2 | K33: =J33+J32 -> 3 | L33: =SUM(J30:J33) -> 6 | M33: =SUM(C30:I33) -> 6
A34: 11:00-11:15 | B34: 0 | C34: 0 | D34: 0 | E34: 0 | F34: 0 | G34: 0 | H34: 0 | I34: 0 | J34: =SUMPRODUCT(B34:I34,$B$11:$I$11) -> 0
A35: 11:15-11:30 | B35: 0 | C35: 0 | D35: 2 | E35: 0 | F35: 0 | G35: 0 | H35: 0 | I35: 0 | J35: =SUMPRODUCT(B35:I35,$B$11:$I$11) -> 2 | K35: =J35+J34 -> 2
A36: 11:30-11:45 | B36: 0 | C36: 0 | D36: 2 | E36: 0 | F36: 0 | G36: 0 | H36: 1 | I36: 0 | J36: =SUMPRODUCT(B36:I36,$B$11:$I$11) -> 4
A37: 11:45-12:00 | B37: 0 | C37: 0 | D37: 0 | E37: 0 | F37: 0 | G37: 2 | H37: 0 | I37: 1 | J37: =SUMPRODUCT(B37:I37,$B$11:$I$11) -> 4.5 | K37: =J37+J36 -> 8.5 | L37: =SUM(J34:J37) -> 10.5 | M37: =SUM(C34:I37) -> 8
A38: 12:00-12:15 | B38: 1 | C38: 0 | D38: 2 | E38: 0 | F38: 0 | G38: 0 | H38: 0 | I38: 0 | J38: =SUMPRODUCT(B38:I38,$B$11:$I$11) -> 2.5
A39: 12:15-12:30 | B39: 1 | C39: 0 | D39: 2 | E39: 0 | F39: 0 | G39: 0 | H39: 0 | I39: 0 | J39: =SUMPRODUCT(B39:I39,$B$11:$I$11) -> 2.5 | K39: =J39+J38 -> 5
A40: 12:30-12:45 | B40: 0 | C40: 0 | D40: 7 | E40: 0 | F40: 0 | G40: 0 | H40: 0 | I40: 0 | J40: =SUMPRODUCT(B40:I40,$B$11:$I$11) -> 7
A41: 12:45-13:00 | B41: 0 | C41: 0 | D41: 3 | E41: 0 | F41: 0 | G41: 1 | H41: 0 | I41: 0 | J41: =SUMPRODUCT(B41:I41,$B$11:$I$11) -> 4.5 | K41: =J41+J40 -> 11.5 | L41: =SUM(J38:J41) -> 16.5 | M41: =SUM(C38:I41) -> 15
A42: 13:00-13:15 | B42: 0 | C42: 0 | D42: 1 | E42: 0 | F42: 0 | G42: 0 | H42: 0 | I42: 0 | J42: =SUMPRODUCT(B42:I42,$B$11:$I$11) -> 1
...

Sheet FG
A3: ICRA Schwap e.U.
A4: VERKEHRSZÄHLUNG – Fußgänger/Radfahrer
A5: Datum : | B5: ='Deckbl.'!I11 -> 45036 | J5: Lfd. Nummer : | K5: ='Deckbl.'!C10 -> 0
J6: Wetter : | K6: ='Deckbl.'!I12 -> morgens leichter Regen, dann Sonne, 5-17°
B7: Verkehrszählung : | D7: ='Deckbl.'!C8 -> Sandleiten / Schulstraße / Parkstraße (Pregarten)
B8: Zählstelle : | I8: Sachbearbeiter : | J8: ICRA / Schwap
B9: Richtung : | I9: Uhrzeit : | J9: ='Deckbl.'!C11 -> 6-20
B10: Bemerkung :
B11: A | C11: C | D11: D | E11: Z | J11: FG/R | K11: FG/R | L11: FG/R
A12: Zeit | B12: FG | C12: FG | D12: FG | E12: FG | J12: / 15 min | K12: / 30 min | L12: / 1 Std.
A13: 6:00-6:15 | B13: 0 | C13: 0 | D13: 0 | E13: 0 | J13: =SUM(B13:I13) -> 0
A14: 6:15-6:30 | B14: 1 | C14: 3 | D14: 0 | E14: 0 | J14: =SUM(B14:I14) -> 4 | K14: =J14+J13 -> 4
A15: 6:30-6:45 | B15: 0 | C15: 0 | D15: 0 | E15: 0 | J15: =SUM(B15:I15) -> 0
A16: 6:45-7:00 | B16: 1 | C16: 1 | D16: 0 | E16: 1 | J16: =SUM(B16:I16) -> 3 | K16: =J16+J15 -> 3 | L16: =SUM(J13:J16) -> 7
A17: 7:00-7:15 | B17: 0 | C17: 0 | D17: 0 | E17: 3 | J17: =SUM(B17:I17) -> 3
A18: 7:15-7:30 | B18: 0 | C18: 2 | D18: 0 | E18: 11 | J18: =SUM(B18:I18) -> 13 | K18: =J18+J17 -> 16
A19: 7:30-7:45 | B19: 0 | C19: 6 | D19: 0 | E19: 27 | J19: =SUM(B19:I19) -> 33
A20: 7:45-8:00 | B20: 7 | C20: 0 | D20: 0 | E20: 14 | J20: =SUM(B20:I20) -> 21 | K20: =J20+J19 -> 54 | L20: =SUM(J17:J20) -> 70
A21: 8:00-8:15 | B21: 0 | C21: 0 | D21: 0 | E21: 0 | J21: =SUM(B21:I21) -> 0
A22: 8:15-8:30 | B22: 0 | C22: 1 | D22: 0 | E22: 1 | J22: =SUM(B22:I22) -> 2 | K22: =J22+J21 -> 2
A23: 8:30-8:45 | B23: 0 | C23: 0 | D23: 0 | E23: 1 | J23: =SUM(B23:I23) -> 1
A24: 8:45-9:00 | B24: 0 | C24: 0 | D24: 0 | E24: 0 | J24: =SUM(B24:I24) -> 0 | K24: =J24+J23 -> 1 | L24: =SUM(J21:J24) -> 3
A25: 9:00-9:15 | B25: 0 | C25: 0 | D25: 0 | E25: 0 | J25: =SUM(B25:I25) -> 0
A26: 9:15-9:30 | B26: 1 | C26: 1 | D26: 0 | E26: 0 | J26: =SUM(B26:I26) -> 2 | K26: =J26+J25 -> 2
A27: 9:30-9:45 | B27: 0 | C27: 2 | D27: 0 | E27: 0 | J27: =SUM(B27:I27) -> 2
A28: 9:45-10:00 | B28: 0 | C28: 3 | D28: 0 | E28: 0 | J28: =SUM(B28:I28) -> 3 | K28: =J28+J27 -> 5 | L28: =SUM(J25:J28) -> 7
A29: 10:00-10:15 | B29: 0 | C29: 2 | D29: 0 | E29: 0 | J29: =SUM(B29:I29) -> 2
A30: 10:15-10:30 | B30: 0 | C30: 2 | D30: 0 | E30: 0 | J30: =SUM(B30:I30) -> 2 | K30: =J30+J29 -> 4
A31: 10:30-10:45 | B31: 2 | C31: 2 | D31: 0 | E31: 2 | J31: =SUM(B31:I31) -> 6
A32: 10:45-11:00 | B32: 0 | C32: 0 | D32: 0 | E32: 0 | J32: =SUM(B32:I32) -> 0 | K32: =J32+J31 -> 6 | L32: =SUM(J29:J32) -> 10
A33: 11:00-11:15 | B33: 0 | C33: 1 | D33: 0 | E33: 0 | J33: =SUM(B33:I33) -> 1
A34: 11:15-11:30 | B34: 0 | C34: 0 | D34: 0 | E34: 0 | J34: =SUM(B34:I34) -> 0 | K34: =J34+J33 -> 1
A35: 11:30-11:45 | B35: 0 | C35: 0 | D35: 0 | E35: 8 | J35: =SUM(B35:I35) -> 8
A36: 11:45-12:00 | B36: 2 | C36: 2 | D36: 2 | E36: 61 | J36: =SUM(B36:I36) -> 67 | K36: =J36+J35 -> 75 | L36: =SUM(J33:J36) -> 76
A37: 12:00-12:15 | B37: 0 | C37: 0 | D37: 0 | E37: 5 | J37: =SUM(B37:I37) -> 5
A38: 12:15-12:30 | B38: 0 | C38: 1 | D38: 0 | E38: 0 | J38: =SUM(B38:I38) -> 1 | K38: =J38+J37 -> 6
A39: 12:30-12:45 | B39: 0 | C39: 0 | D39: 3 | E39: 1 | J39: =SUM(B39:I39) -> 4
A40: 12:45-13:00 | B40: 5 | C40: 0 | D40: 1 | E40: 21 | J40: =SUM(B40:I40) -> 27 | K40: =J40+J39 -> 31 | L40: =SUM(J37:J40) -> 37
A41: 13:00-13:15 | B41: 1 | C41: 0 | D41: 0 | E41: 0 | J41: =SUM(B41:I41) -> 1
A42: 13:15-13:30 | B42: 0 | C42: 0 | D42: 0 | E42: 0 | J42: =SUM(B42:I42) -> 0 | K42: =J42+J41 -> 1
...

Sheet Faktoren PKW-E
A1: Faktoren für Umrechnung PKW-Einheiten nach RVS 03.05.11
A3: Rad | B3: 0.5
A4: einsp. KFZ | B4: 1
A5: PKW / Kombi | B5: 1
A6: Linienbus | B6: 1.5
A7: Reisebus | B7: 1.5
A8: LKW | B8: 1.5
A9: LKW mit Anhänger | B9: 2
A10: sonstige KFZ / Traktoren | B10: 1.5
A12: Faktoren für Umrechnung PKW-Einheiten nach RVS 03.05.31 (VLSA)
A14: Rad | B14: 0.3
A15: Motorrad | B15: 0.5
A16: PKW | B16: 1
A17: Lkw, Bus Traktor | B17: 2
A18: Gelenkbus, Sattelschlepper | B18: 3
A19: Lkw mit Anh. oder Traktor mit Anh. | B19: 4
