Workbook

Sheet Deckbl.
A5: www.verkehrszählung.at
B8: Verkehrszählungsort : | C8: B122 / Badhaller Straße / Holznerweg (Bad Hall)
B10: Lfd. Nummer :
B11: Zählzeit : | C11: 7-19 Uhr | H11: Datum : | I11: 45944
B12: Sachbearbeiter : | C12: Schwap | H12: Wetter : | I12: 9-14 ° sonnig
B14: Anmerkungen :

Sheet R1
A3: ICRA Schwap e.U.
A4: VERKEHRSZÄHLUNG - PKW-Einheiten
A5: Datum : | J5: Lfd. Nummer : | K5: 0
A6: =Deckbl.!I11 -> 45944 | J6: Wetter : | K6: =Deckbl.!I12 -> 9-14 ° sonnig
B7: Verkehrszählung : | C7: =Deckbl.!C8 -> B122 / Badhaller Straße / Holznerweg (Bad Hall)
B8: Zählstelle : | I8: Sachbearbeiter : | J8: ICRA / Schwap
B9: Richtung : | C9: R1 | I9: Uhrzeit : | J9: =Deckbl.!C11 -> 7-19 Uhr
B10: Bemerkung :
A11: Faktoren | B11: 0.3 | C11: 0.5 | D11: 1 | E11: 2 | F11: 2 | G11: 2 | H11: 3 | I11: 2
C12: einsp. | D12: PKW | E12: Linien- | F12: Reise- | G12: LKW | H12: LKW + | I12: Traktor | J12: PKW-E | K12: PKW-E | L12: PKW-E | M12: KFZ
A13: Zeit | B13: Rad | C13: KFZ | D13: Kombi | E13: bus | F13: bus | H13: Anh. | I13: Sonst. | J13: / 15 min | K13: / 30 min | L13: / 1 Std. | M13: / 1 Std.
A14: 5:00-5:15 | J14: =SUMPRODUCT(B14:I14,$B$11:$I$11) -> 0
A15: 5:15-5:30 | J15: =SUMPRODUCT(B15:I15,$B$11:$I$11) -> 0 | K15: =J15+J14 -> 0
A16: 5:30-5:45 | J16: =SUMPRODUCT(B16:I16,$B$11:$I$11) -> 0
A17: 5:45-6:00 | J17: =SUMPRODUCT(B17:I17,$B$11:$I$11) -> 0 | K17: =J17+J16 -> 0 | L17: =SUM(J14:J17) -> 0 | M17: =SUM(C14:I17) -> 0
A18: 6:00-6:15 | J18: =SUMPRODUCT(B18:I18,$B$11:$I$11) -> 0
A19: 6:15-6:30 | J19: =SUMPRODUCT(B19:I19,$B$11:$I$11) -> 0 | K19: =J19+J18 -> 0
A20: 6:30-6:45 | J20: =SUMPRODUCT(B20:I20,$B$11:$I$11) -> 0
A21: 6:45-7:00 | J21: =SUMPRODUCT(B21:I21,$B$11:$I$11) -> 0 | K21: =J21+J20 -> 0 | L21: =SUM(J18:J21) -> 0 | M21: =SUM(C18:I21) -> 0
A22: 7:00-7:15 | B22: 0 | C22: 0 | D22: 6 | E22: 0 | F22: 0 | G22: 0 | H22: 0 | I22: 0 | J22: =SUMPRODUCT(B22:I22,$B$11:$I$11) -> 6
A23: 7:15-7:30 | B23: 0 | C23: 0 | D23: 4 | E23: 0 | F23: 0 | G23: 0 | H23: 0 | I23: 0 | J23: =SUMPRODUCT(B23:I23,$B$11:$I$11) -> 4 | K23: =J23+J22 -> 10
A24: 7:30-7:45 | B24: 0 | C24: 0 | D24: 9 | E24: 1 | F24: 0 | G24: 1 | H24: 0 | I24: 0 | J24: =SUMPRODUCT(B24:I24,$B$11:$I$11) -> 13
A25: 7:45-8:00 | B25: 0 | C25: 0 | D25: 9 | E25: 0 | F25: 0 | G25: 0 | H25: 0 | I25: 0 | J25: =SUMPRODUCT(B25:I25,$B$11:$I$11) -> 9 | K25: =J25+J24 -> 22 | L25: =SUM(J22:J25) -> 32 | M25: =SUM(C22:I25) -> 30
A26: 8:00-8:15 | B26: 0 | C26: 0 | D26: 4 | E26: 0 | F26: 0 | G26: 0 | H26: 0 | I26: 0 | J26: =SUMPRODUCT(B26:I26,$B$11:$I$11) -> 4
A27: 8:15-8:30 | B27: 0 | C27: 0 | D27: 4 | E27: 0 | F27: 0 | G27: 0 | H27: 0 | I27: 0 | J27: =SUMPRODUCT(B27:I27,$B$11:$I$11) -> 4 | K27: =J27+J26 -> 8
A28: 8:30-8:45 | B28: 0 | C28: 0 | D28: 10 | E28: 0 | F28: 0 | G28: 0 | H28: 0 | I28: 0 | J28: =SUMPRODUCT(B28:I28,$B$11:$I$11) -> 10
A29: 8:45-9:00 | B29: 0 | C29: 0 | D29: 13 | E29: 0 | F29: 0 | G29: 0 | H29: 0 | I29: 0 | J29: =SUMPRODUCT(B29:I29,$B$11:$I$11) -> 13 | K29: =J29+J28 -> 23 | L29: =SUM(J26:J29) -> 31 | M29: =SUM(C26:I29) -> 31
A30: 9:00-9:15 | B30: 0 | C30: 0 | D30: 9 | E30: 0 | F30: 0 | G30: 0 | H30: 0 | I30: 0 | J30: =SUMPRODUCT(B30:I30,$B$11:$I$11) -> 9
A31: 9:15-9:30 | B31: 0 | C31: 0 | D31: 11 | E31: 0 | F31: 0 | G31: 0 | H31: 0 | I31: 0 | J31: =SUMPRODUCT(B31:I31,$B$11:$I$11) -> 11 | K31: =J31+J30 -> 20
A32: 9:30-9:45 | B32: 0 | C32: 0 | D32: 10 | E32: 0 | F32: 0 | G32: 1 | H32: 0 | I32: 0 | J32: =SUMPRODUCT(B32:I32,$B$11:$I$11) -> 12
A33: 9:45-10:00 | B33: 0 | C33: 0 | D33: 11 | E33: 0 | F33: 0 | G33: 0 | H33: 0 | I33: 0 | J33: =SUMPRODUCT(B33:I33,$B$11:$I$11) -> 11 | K33: =J33+J32 -> 23 | L33: =SUM(J30:J33) -> 43 | M33: =SUM(C30:I33) -> 42
A34: 10:00-10:15 | B34: 0 | C34: 0 | D34: 14 | E34: 0 | F34: 0 | G34: 0 | H34: 0 | I34: 0 | J34: =SUMPRODUCT(B34:I34,$B$11:$I$11) -> 14
A35: 10:15-10:30 | B35: 0 | C35: 0 | D35: 10 | E35: 0 | F35: 0 | G35: 0 | H35: 0 | I35: 0 | J35: =SUMPRODUCT(B35:I35,$B$11:$I$11) -> 10 | K35: =J35+J34 -> 24
A36: 10:30-10:45 | B36: 0 | C36: 0 | D36: 0 | E36: 0 | F36: 0 | G36: 0 | H36: 0 | I36: 0 | J36: =SUMPRODUCT(B36:I36,$B$11:$I$11) -> 0
A37: 10:45-11:00 | B37: 0 | C37: 0 | D37: 4 | E37: 0 | F37: 0 | G37: 0 | H37: 0 | I37: 1 | J37: =SUMPRODUCT(B37:I37,$B$11:$I$11) -> 6 | K37: =J37+J36 -> 6 | L37: =SUM(J34:J37) -> 30 | M37: =SUM(C34:I37) -> 29
A38: 11:00-11:15 | B38: 0 | C38: 0 | D38: 10 | E38: 0 | F38: 0 | G38: 0 | H38: 0 | I38: 0 | J38: =SUMPRODUCT(B38:I38,$B$11:$I$11) -> 10
A39: 11:15-11:30 | B39: 0 | C39: 0 | D39: 5 | E39: 0 | F39: 0 | G39: 0 | H39: 0 | I39: 0 | J39: =SUMPRODUCT(B39:I39,$B$11:$I$11) -> 5 | K39: =J39+J38 -> 15
A40: 11:30-11:45 | B40: 0 | C40: 0 | D40: 5 | E40: 0 | F40: 0 | G40: 0 | H40: 0 | I40: 0 | J40: =SUMPRODUCT(B40:I40,$B$11:$I$11) -> 5
A41: 11:45-12:00 | B41: 0 | C41: 1 | D41: 8 | E41: 0 | F41: 0 | G41: 0 | H41: 0 | I41: 1 | J41: =SUMPRODUCT(B41:I41,$B$11:$I$11) -> 10.5 | K41: =J41+J40 -> 15.5 | L41: =SUM(J38:J41) -> 30.5 | M41: =SUM(C38:I41) -> 30
A42: 12:00-12:15 | B42: 0 | C42: 0 | D42: 7 | E42: 0 | F42: 0 | G42: 0 | H42: 0 | I42: 0 | J42: =SUMPRODUCT(B42:I42,$B$11:$I$11) -> 7
...

Sheet R2
A3: ICRA Schwap e.U.
A4: VERKEHRSZÄHLUNG - PKW-Einheiten
A5: Datum : | J5: Lfd. Nummer : | K5: 0
A6: =Deckbl.!I11 -> 45944 | J6: Wetter : | K6: =Deckbl.!I12 -> 9-14 ° sonnig
B7: Verkehrszählung : | C7: =Deckbl.!C8 -> B122 / Badhaller Straße / Holznerweg (Bad Hall)
B8: Zählstelle : | I8: Sachbearbeiter : | J8: ICRA / Schwap
B9: Richtung : | C9: R2 | I9: Uhrzeit : | J9: =Deckbl.!C11 -> 7-19 Uhr
B10: Bemerkung :
A11: Faktoren | B11: 0.3 | C11: 0.5 | D11: 1 | E11: 2 | F11: 2 | G11: 2 | H11: 3 | I11: 2
C12: einsp. | D12: PKW | E12: Linien- | F12: Reise- | G12: LKW | H12: LKW + | I12: Traktor | J12: PKW-E | K12: PKW-E | L12: PKW-E | M12: KFZ
A13: Zeit | B13: Rad | C13: KFZ | D13: Kombi | E13: bus | F13: bus | H13: Anh. | I13: Sonst. | J13: / 15 min | K13: / 30 min | L13: / 1 Std. | M13: / 1 Std.
A14: 5:00-5:15 | J14: =SUMPRODUCT(B14:I14,$B$11:$I$11) -> 0
A15: 5:15-5:30 | J15: =SUMPRODUCT(B15:I15,$B$11:$I$11) -> 0 | K15: =J15+J14 -> 0
A16: 5:30-5:45 | J16: =SUMPRODUCT(B16:I16,$B$11:$I$11) -> 0
A17: 5:45-6:00 | J17: =SUMPRODUCT(B17:I17,$B$11:$I$11) -> 0 | K17: =J17+J16 -> 0 | L17: =SUM(J14:J17) -> 0 | M17: =SUM(C14:I17) -> 0
A18: 6:00-6:15 | J18: =SUMPRODUCT(B18:I18,$B$11:$I$11) -> 0
A19: 6:15-6:30 | J19: =SUMPRODUCT(B19:I19,$B$11:$I$11) -> 0 | K19: =J19+J18 -> 0
A20: 6:30-6:45 | J20: =SUMPRODUCT(B20:I20,$B$11:$I$11) -> 0
A21: 6:45-7:00 | J21: =SUMPRODUCT(B21:I21,$B$11:$I$11) -> 0 | K21: =J21+J20 -> 0 | L21: =SUM(J18:J21) -> 0 | M21: =SUM(C18:I21) -> 0
A22: 7:00-7:15 | B22: 0 | C22: 0 | D22: 68 | E22: 1 | F22: 0 | G22: 2 | H22: 8 | I22: 0 | J22: =SUMPRODUCT(B22:I22,$B$11:$I$11) -> 98
A23: 7:15-7:30 | B23: 0 | C23: 0 | D23: 100 | E23: 2 | F23: 0 | G23: 6 | H23: 4 | I23: 0 | J23: =SUMPRODUCT(B23:I23,$B$11:$I$11) -> 128 | K23: =J23+J22 -> 226
A24: 7:30-7:45 | B24: 0 | C24: 0 | D24: 84 | E24: 2 | F24: 0 | G24: 2 | H24: 5 | I24: 0 | J24: =SUMPRODUCT(B24:I24,$B$11:$I$11) -> 107
A25: 7:45-8:00 | B25: 0 | C25: 0 | D25: 86 | E25: 1 | F25: 0 | G25: 5 | H25: 8 | I25: 1 | J25: =SUMPRODUCT(B25:I25,$B$11:$I$11) -> 124 | K25: =J25+J24 -> 231 | L25: =SUM(J22:J25) -> 457 | M25: =SUM(C22:I25) -> 385
A26: 8:00-8:15 | B26: 0 | C26: 0 | D26: 73 | E26: 1 | F26: 0 | G26: 0 | H26: 10 | I26: 0 | J26: =SUMPRODUCT(B26:I26,$B$11:$I$11) -> 105
A27: 8:15-8:30 | B27: 0 | C27: 0 | D27: 72 | E27: 1 | F27: 0 | G27: 4 | H27: 2 | I27: 0 | J27: =SUMPRODUCT(B27:I27,$B$11:$I$11) -> 88 | K27: =J27+J26 -> 193
A28: 8:30-8:45 | B28: 0 | C28: 0 | D28: 77 | E28: 0 | F28: 0 | G28: 11 | H28: 4 | I28: 0 | J28: =SUMPRODUCT(B28:I28,$B$11:$I$11) -> 111
A29: 8:45-9:00 | B29: 0 | C29: 0 | D29: 74 | E29: 0 | F29: 0 | G29: 6 | H29: 10 | I29: 0 | J29: =SUMPRODUCT(B29:I29,$B$11:$I$11) -> 116 | K29: =J29+J28 -> 227 | L29: =SUM(J26:J29) -> 420 | M29: =SUM(C26:I29) -> 345
A30: 9:00-9:15 | B30: 0 | C30: 1 | D30: 79 | E30: 0 | F30: 0 | G30: 4 | H30: 5 | I30: 0 | J30: =SUMPRODUCT(B30:I30,$B$11:$I$11) -> 102.5
A31: 9:15-9:30 | B31: 0 | C31: 0 | D31: 58 | E31: 1 | F31: 0 | G31: 2 | H31: 6 | I31: 1 | J31: =SUMPRODUCT(B31:I31,$B$11:$I$11) -> 84 | K31: =J31+J30 -> 186.5
A32: 9:30-9:45 | B32: 0 | C32: 0 | D32: 74 | E32: 1 | F32: 0 | G32: 3 | H32: 5 | I32: 1 | J32: =SUMPRODUCT(B32:I32,$B$11:$I$11) -> 99
A33: 9:45-10:00 | B33: 0 | C33: 0 | D33: 82 | E33: 1 | F33: 0 | G33: 1 | H33: 7 | I33: 0 | J33: =SUMPRODUCT(B33:I33,$B$11:$I$11) -> 107 | K33: =J33+J32 -> 206 | L33: =SUM(J30:J33) -> 392.5 | M33: =SUM(C30:I33) -> 332
A34: 10:00-10:15 | B34: 1 | C34: 0 | D34: 71 | E34: 0 | F34: 0 | G34: 0 | H34: 5 | I34: 1 | J34: =SUMPRODUCT(B34:I34,$B$11:$I$11) -> 88.3
A35: 10:15-10:30 | B35: 0 | C35: 0 | D35: 60 | E35: 1 | F35: 0 | G35: 5 | H35: 3 | I35: 0 | J35: =SUMPRODUCT(B35:I35,$B$11:$I$11) -> 81 | K35: =J35+J34 -> 169.3
A36: 10:30-10:45 | B36: 0 | C36: 0 | D36: 73 | E36: 0 | F36: 0 | G36: 2 | H36: 5 | I36: 0 | J36: =SUMPRODUCT(B36:I36,$B$11:$I$11) -> 92
A37: 10:45-11:00 | B37: 0 | C37: 0 | D37: 70 | E37: 1 | F37: 0 | G37: 3 | H37: 7 | I37: 0 | J37: =SUMPRODUCT(B37:I37,$B$11:$I$11) -> 99 | K37: =J37+J36 -> 191 | L37: =SUM(J34:J37) -> 360.3 | M37: =SUM(C34:I37) -> 307
A38: 11:00-11:15 | B38: 0 | C38: 1 | D38: 55 | E38: 0 | F38: 0 | G38: 4 | H38: 7 | I38: 1 | J38: =SUMPRODUCT(B38:I38,$B$11:$I$11) -> 86.5
A39: 11:15-11:30 | B39: 0 | C39: 0 | D39: 66 | E39: 1 | F39: 0 | G39: 3 | H39: 4 | I39: 0 | J39: =SUMPRODUCT(B39:I39,$B$11:$I$11) -> 86 | K39: =J39+J38 -> 172.5
A40: 11:30-11:45 | B40: 0 | C40: 1 | D40: 66 | E40: 3 | F40: 0 | G40: 1 | H40: 8 | I40: 0 | J40: =SUMPRODUCT(B40:I40,$B$11:$I$11) -> 98.5
A41: 11:45-12:00 | B41: 0 | C41: 0 | D41: 68 | E41: 1 | F41: 0 | G41: 3 | H41: 5 | I41: 0 | J41: =SUMPRODUCT(B41:I41,$B$11:$I$11) -> 91 | K41: =J41+J40 -> 189.5 | L41: =SUM(J38:J41) -> 362 | M41: =SUM(C38:I41) -> 298
A42: 12:00-12:15 | B42: 0 | C42: 0 | D42: 70 | E42: 0 | F42: 0 | G42: 0 | H42: 6 | I42: 1 | J42: =SUMPRODUCT(B42:I42,$B$11:$I$11) -> 90
...

Sheet R3
A3: ICRA Schwap e.U.
A4: VERKEHRSZÄHLUNG - PKW-Einheiten
A5: Datum : | J5: Lfd. Nummer : | K5: 0
A6: =Deckbl.!I11 -> 45944 | J6: Wetter : | K6: =Deckbl.!I12 -> 9-14 ° sonnig
B7: Verkehrszählung : | C7: =Deckbl.!C8 -> B122 / Badhaller Straße / Holznerweg (Bad Hall)
B8: Zählstelle : | I8: Sachbearbeiter : | J8: ICRA / Schwap
B9: Richtung : | C9: R3 | I9: Uhrzeit : | J9: =Deckbl.!C11 -> 7-19 Uhr
B10: Bemerkung :
A11: Faktoren | B11: 0.3 | C11: 0.5 | D11: 1 | E11: 2 | F11: 2 | G11: 2 | H11: 3 | I11: 2
C12: einsp. | D12: PKW | E12: Linien- | F12: Reise- | G12: LKW | H12: LKW + | I12: Traktor | J12: PKW-E | K12: PKW-E | L12: PKW-E | M12: KFZ
A13: Zeit | B13: Rad | C13: KFZ | D13: Kombi | E13: bus | F13: bus | H13: Anh. | I13: Sonst. | J13: / 15 min | K13: / 30 min | L13: / 1 Std. | M13: / 1 Std.
A14: 5:00-5:15 | J14: =SUMPRODUCT(B14:I14,$B$11:$I$11) -> 0
A15: 5:15-5:30 | J15: =SUMPRODUCT(B15:I15,$B$11:$I$11) -> 0 | K15: =J15+J14 -> 0
A16: 5:30-5:45 | J16: =SUMPRODUCT(B16:I16,$B$11:$I$11) -> 0
A17: 5:45-6:00 | J17: =SUMPRODUCT(B17:I17,$B$11:$I$11) -> 0 | K17: =J17+J16 -> 0 | L17: =SUM(J14:J17) -> 0 | M17: =SUM(C14:I17) -> 0
A18: 6:00-6:15 | J18: =SUMPRODUCT(B18:I18,$B$11:$I$11) -> 0
A19: 6:15-6:30 | J19: =SUMPRODUCT(B19:I19,$B$11:$I$11) -> 0 | K19: =J19+J18 -> 0
A20: 6:30-6:45 | J20: =SUMPRODUCT(B20:I20,$B$11:$I$11) -> 0
A21: 6:45-7:00 | J21: =SUMPRODUCT(B21:I21,$B$11:$I$11) -> 0 | K21: =J21+J20 -> 0 | L21: =SUM(J18:J21) -> 0 | M21: =SUM(C18:I21) -> 0
A22: 7:00-7:15 | B22: 0 | C22: 0 | D22: 11 | E22: 0 | F22: 0 | G22: 1 | H22: 0 | I22: 0 | J22: =SUMPRODUCT(B22:I22,$B$11:$I$11) -> 13
A23: 7:15-7:30 | B23: 0 | C23: 0 | D23: 15 | E23: 0 | F23: 0 | G23: 0 | H23: 0 | I23: 0 | J23: =SUMPRODUCT(B23:I23,$B$11:$I$11) -> 15 | K23: =J23+J22 -> 28
A24: 7:30-7:45 | B24: 0 | C24: 0 | D24: 7 | E24: 0 | F24: 0 | G24: 0 | H24: 0 | I24: 0 | J24: =SUMPRODUCT(B24:I24,$B$11:$I$11) -> 7
A25: 7:45-8:00 | B25: 0 | C25: 0 | D25: 8 | E25: 0 | F25: 0 | G25: 0 | H25: 0 | I25: 0 | J25: =SUMPRODUCT(B25:I25,$B$11:$I$11) -> 8 | K25: =J25+J24 -> 15 | L25: =SUM(J22:J25) -> 43 | M25: =SUM(C22:I25) -> 42
A26: 8:00-8:15 | B26: 0 | C26: 0 | D26: 6 | E26: 0 | F26: 0 | G26: 2 | H26: 1 | I26: 0 | J26: =SUMPRODUCT(B26:I26,$B$11:$I$11) -> 13
A27: 8:15-8:30 | B27: 0 | C27: 0 | D27: 15 | E27: 0 | F27: 0 | G27: 0 | H27: 0 | I27: 0 | J27: =SUMPRODUCT(B27:I27,$B$11:$I$11) -> 15 | K27: =J27+J26 -> 28
A28: 8:30-8:45 | B28: 0 | C28: 0 | D28: 13 | E28: 1 | F28: 0 | G28: 0 | H28: 0 | I28: 0 | J28: =SUMPRODUCT(B28:I28,$B$11:$I$11) -> 15
A29: 8:45-9:00 | B29: 0 | C29: 0 | D29: 18 | E29: 0 | F29: 0 | G29: 0 | H29: 0 | I29: 0 | J29: =SUMPRODUCT(B29:I29,$B$11:$I$11) -> 18 | K29: =J29+J28 -> 33 | L29: =SUM(J26:J29) -> 61 | M29: =SUM(C26:I29) -> 56
A30: 9:00-9:15 | B30: 0 | C30: 0 | D30: 10 | E30: 0 | F30: 0 | G30: 1 | H30: 0 | I30: 0 | J30: =SUMPRODUCT(B30:I30,$B$11:$I$11) -> 12
A31: 9:15-9:30 | B31: 0 | C31: 0 | D31: 10 | E31: 1 | F31: 0 | G31: 1 | H31: 0 | I31: 0 | J31: =SUMPRODUCT(B31:I31,$B$11:$I$11) -> 14 | K31: =J31+J30 -> 26
A32: 9:30-9:45 | B32: 0 | C32: 0 | D32: 17 | E32: 0 | F32: 0 | G32: 0 | H32: 0 | I32: 0 | J32: =SUMPRODUCT(B32:I32,$B$11:$I$11) -> 17
A33: 9:45-10:00 | B33: 0 | C33: 0 | D33: 12 | E33: 0 | F33: 0 | G33: 0 | H33: 0 | I33: 0 | J33: =SUMPRODUCT(B33:I33,$B$11:$I$11) -> 12 | K33: =J33+J32 -> 29 | L33: =SUM(J30:J33) -> 55 | M33: =SUM(C30:I33) -> 52
A34: 10:00-10:15 | B34: 0 | C34: 0 | D34: 19 | E34: 0 | F34: 0 | G34: 1 | H34: 0 | I34: 0 | J34: =SUMPRODUCT(B34:I34,$B$11:$I$11) -> 21
A35: 10:15-10:30 | B35: 0 | C35: 0 | D35: 16 | E35: 0 | F35: 0 | G35: 0 | H35: 0 | I35: 0 | J35: =SUMPRODUCT(B35:I35,$B$11:$I$11) -> 16 | K35: =J35+J34 -> 37
A36: 10:30-10:45 | B36: 0 | C36: 0 | D36: 15 | E36: 1 | F36: 0 | G36: 0 | H36: 0 | I36: 0 | J36: =SUMPRODUCT(B36:I36,$B$11:$I$11) -> 17
A37: 10:45-11:00 | B37: 0 | C37: 0 | D37: 10 | E37: 0 | F37: 0 | G37: 0 | H37: 0 | I37: 0 | J37: =SUMPRODUCT(B37:I37,$B$11:$I$11) -> 10 | K37: =J37+J36 -> 27 | L37: =SUM(J34:J37) -> 64 | M37: =SUM(C34:I37) -> 62
A38: 11:00-11:15 | B38: 0 | C38: 0 | D38: 16 | E38: 0 | F38: 0 | G38: 0 | H38: 0 | I38: 0 | J38: =SUMPRODUCT(B38:I38,$B$11:$I$11) -> 16
A39: 11:15-11:30 | B39: 0 | C39: 0 | D39: 13 | E39: 0 | F39: 0 | G39: 0 | H39: 0 | I39: 0 | J39: =SUMPRODUCT(B39:I39,$B$11:$I$11) -> 13 | K39: =J39+J38 -> 29
A40: 11:30-11:45 | B40: 0 | C40: 0 | D40: 15 | E40: 0 | F40: 0 | G40: 1 | H40: 0 | I40: 0 | J40: =SUMPRODUCT(B40:I40,$B$11:$I$11) -> 17
A41: 11:45-12:00 | B41: 0 | C41: 0 | D41: 14 | E41: 0 | F41: 0 | G41: 0 | H41: 0 | I41: 0 | J41: =SUMPRODUCT(B41:I41,$B$11:$I$11) -> 14 | K41: =J41+J40 -> 31 | L41: =SUM(J38:J41) -> 60 | M41: =SUM(C38:I41) -> 59
A42: 12:00-12:15 | B42: 0 | C42: 0 | D42: 13 | E42: 0 | F42: 0 | G42: 0 | H42: 0 | I42: 0 | J42: =SUMPRODUCT(B42:I42,$B$11:$I$11) -> 13
...

Sheet R4
A3: ICRA Schwap e.U.
A4: VERKEHRSZÄHLUNG - PKW-Einheiten
A5: Datum : | J5: Lfd. Nummer : | K5: 0
A6: =Deckbl.!I11 -> 45944 | J6: Wetter : | K6: =Deckbl.!I12 -> 9-14 ° sonnig
B7: Verkehrszählung : | C7: =Deckbl.!C8 -> B122 / Badhaller Straße / Holznerweg (Bad Hall)
B8: Zählstelle : | I8: Sachbearbeiter : | J8: ICRA / Schwap
B9: Richtung : | C9: R4 | I9: Uhrzeit : | J9: =Deckbl.!C11 -> 7-19 Uhr
B10: Bemerkung :
A11: Faktoren | B11: 0.3 | C11: 0.5 | D11: 1 | E11: 2 | F11: 2 | G11: 2 | H11: 3 | I11: 2
C12: einsp. | D12: PKW | E12: Linien- | F12: Reise- | G12: LKW | H12: LKW + | I12: Traktor | J12: PKW-E | K12: PKW-E | L12: PKW-E | M12: KFZ
A13: Zeit | B13: Rad | C13: KFZ | D13: Kombi | E13: bus | F13: bus | H13: Anh. | I13: Sonst. | J13: / 15 min | K13: / 30 min | L13: / 1 Std. | M13: / 1 Std.
A14: 5:00-5:15 | J14: =SUMPRODUCT(B14:I14,$B$11:$I$11) -> 0
A15: 5:15-5:30 | J15: =SUMPRODUCT(B15:I15,$B$11:$I$11) -> 0 | K15: =J15+J14 -> 0
A16: 5:30-5:45 | J16: =SUMPRODUCT(B16:I16,$B$11:$I$11) -> 0
A17: 5:45-6:00 | J17: =SUMPRODUCT(B17:I17,$B$11:$I$11) -> 0 | K17: =J17+J16 -> 0 | L17: =SUM(J14:J17) -> 0 | M17: =SUM(C14:I17) -> 0
A18: 6:00-6:15 | J18: =SUMPRODUCT(B18:I18,$B$11:$I$11) -> 0
A19: 6:15-6:30 | J19: =SUMPRODUCT(B19:I19,$B$11:$I$11) -> 0 | K19: =J19+J18 -> 0
A20: 6:30-6:45 | J20: =SUMPRODUCT(B20:I20,$B$11:$I$11) -> 0
A21: 6:45-7:00 | J21: =SUMPRODUCT(B21:I21,$B$11:$I$11) -> 0 | K21: =J21+J20 -> 0 | L21: =SUM(J18:J21) -> 0 | M21: =SUM(C18:I21) -> 0
A22: 7:00-7:15 | B22: 0 | C22: 0 | D22: 11 | E22: 1 | F22: 0 | G22: 0 | H22: 0 | I22: 0 | J22: =SUMPRODUCT(B22:I22,$B$11:$I$11) -> 13
A23: 7:15-7:30 | B23: 0 | C23: 0 | D23: 16 | E23: 0 | F23: 0 | G23: 0 | H23: 1 | I23: 0 | J23: =SUMPRODUCT(B23:I23,$B$11:$I$11) -> 19 | K23: =J23+J22 -> 32
A24: 7:30-7:45 | B24: 0 | C24: 1 | D24: 14 | E24: 0 | F24: 0 | G24: 1 | H24: 0 | I24: 0 | J24: =SUMPRODUCT(B24:I24,$B$11:$I$11) -> 16.5
A25: 7:45-8:00 | B25: 0 | C25: 0 | D25: 13 | E25: 0 | F25: 0 | G25: 0 | H25: 0 | I25: 0 | J25: =SUMPRODUCT(B25:I25,$B$11:$I$11) -> 13 | K25: =J25+J24 -> 29.5 | L25: =SUM(J22:J25) -> 61.5 | M25: =SUM(C22:I25) -> 58
A26: 8:00-8:15 | B26: 0 | C26: 0 | D26: 5 | E26: 0 | F26: 0 | G26: 0 | H26: 0 | I26: 0 | J26: =SUMPRODUCT(B26:I26,$B$11:$I$11) -> 5
A27: 8:15-8:30 | B27: 0 | C27: 0 | D27: 12 | E27: 0 | F27: 0 | G27: 0 | H27: 0 | I27: 0 | J27: =SUMPRODUCT(B27:I27,$B$11:$I$11) -> 12 | K27: =J27+J26 -> 17
A28: 8:30-8:45 | B28: 0 | C28: 0 | D28: 8 | E28: 0 | F28: 0 | G28: 0 | H28: 1 | I28: 0 | J28: =SUMPRODUCT(B28:I28,$B$11:$I$11) -> 11
A29: 8:45-9:00 | B29: 0 | C29: 0 | D29: 15 | E29: 0 | F29: 0 | G29: 1 | H29: 0 | I29: 0 | J29: =SUMPRODUCT(B29:I29,$B$11:$I$11) -> 17 | K29: =J29+J28 -> 28 | L29: =SUM(J26:J29) -> 45 | M29: =SUM(C26:I29) -> 42
A30: 9:00-9:15 | B30: 0 | C30: 0 | D30: 12 | E30: 0 | F30: 0 | G30: 0 | H30: 0 | I30: 0 | J30: =SUMPRODUCT(B30:I30,$B$11:$I$11) -> 12
A31: 9:15-9:30 | B31: 0 | C31: 0 | D31: 21 | E31: 0 | F31: 0 | G31: 0 | H31: 1 | I31: 0 | J31: =SUMPRODUCT(B31:I31,$B$11:$I$11) -> 24 | K31: =J31+J30 -> 36
A32: 9:30-9:45 | B32: 0 | C32: 0 | D32: 19 | E32: 0 | F32: 0 | G32: 0 | H32: 0 | I32: 0 | J32: =SUMPRODUCT(B32:I32,$B$11:$I$11) -> 19
A33: 9:45-10:00 | B33: 0 | C33: 0 | D33: 22 | E33: 0 | F33: 0 | G33: 0 | H33: 0 | I33: 0 | J33: =SUMPRODUCT(B33:I33,$B$11:$I$11) -> 22 | K33: =J33+J32 -> 41 | L33: =SUM(J30:J33) -> 77 | M33: =SUM(C30:I33) -> 75
A34: 10:00-10:15 | B34: 0 | C34: 0 | D34: 13 | E34: 0 | F34: 0 | G34: 1 | H34: 0 | I34: 0 | J34: =SUMPRODUCT(B34:I34,$B$11:$I$11) -> 15
A35: 10:15-10:30 | B35: 0 | C35: 0 | D35: 14 | E35: 0 | F35: 0 | G35: 0 | H35: 0 | I35: 0 | J35: =SUMPRODUCT(B35:I35,$B$11:$I$11) -> 14 | K35: =J35+J34 -> 29
A36: 10:30-10:45 | B36: 0 | C36: 0 | D36: 20 | E36: 0 | F36: 0 | G36: 1 | H36: 0 | I36: 0 | J36: =SUMPRODUCT(B36:I36,$B$11:$I$11) -> 22
A37: 10:45-11:00 | B37: 0 | C37: 0 | D37: 21 | E37: 0 | F37: 0 | G37: 1 | H37: 0 | I37: 0 | J37: =SUMPRODUCT(B37:I37,$B$11:$I$11) -> 23 | K37: =J37+J36 -> 45 | L37: =SUM(J34:J37) -> 74 | M37: =SUM(C34:I37) -> 71
A38: 11:00-11:15 | B38: 0 | C38: 0 | D38: 10 | E38: 0 | F38: 0 | G38: 0 | H38: 0 | I38: 0 | J38: =SUMPRODUCT(B38:I38,$B$11:$I$11) -> 10
A39: 11:15-11:30 | B39: 0 | C39: 0 | D39: 12 | E39: 0 | F39: 0 | G39: 1 | H39: 0 | I39: 0 | J39: =SUMPRODUCT(B39:I39,$B$11:$I$11) -> 14 | K39: =J39+J38 -> 24
A40: 11:30-11:45 | B40: 0 | C40: 0 | D40: 11 | E40: 0 | F40: 0 | G40: 0 | H40: 0 | I40: 0 | J40: =SUMPRODUCT(B40:I40,$B$11:$I$11) -> 11
A41: 11:45-12:00 | B41: 0 | C41: 0 | D41: 12 | E41: 0 | F41: 0 | G41: 0 | H41: 0 | I41: 0 | J41: =SUMPRODUCT(B41:I41,$B$11:$I$11) -> 12 | K41: =J41+J40 -> 23 | L41: =SUM(J38:J41) -> 47 | M41: =SUM(C38:I41) -> 46
A42: 12:00-12:15 | B42: 0 | C42: 0 | D42: 18 | E42: 1 | F42: 0 | G42: 1 | H42: 0 | I42: 0 | J42: =SUMPRODUCT(B42:I42,$B$11:$I$11) -> 22
...

Sheet R5
A3: ICRA Schwap e.U.
A4: VERKEHRSZÄHLUNG - PKW-Einheiten
A5: Datum : | J5: Lfd. Nummer : | K5: 0
A6: =Deckbl.!I11 -> 45944 | J6: Wetter : | K6: =Deckbl.!I12 -> 9-14 ° sonnig
B7: Verkehrszählung : | C7: =Deckbl.!C8 -> B122 / Badhaller Straße / Holznerweg (Bad Hall)
B8: Zählstelle : | I8: Sachbearbeiter : | J8: ICRA / Schwap
B9: Richtung : | C9: R5 | I9: Uhrzeit : | J9: =Deckbl.!C11 -> 7-19 Uhr
B10: Bemerkung :
A11: Faktoren | B11: 0.3 | C11: 0.5 | D11: 1 | E11: 2 | F11: 2 | G11: 2 | H11: 3 | I11: 2
C12: einsp. | D12: PKW | E12: Linien- | F12: Reise- | G12: LKW | H12: LKW + | I12: Traktor | J12: PKW-E | K12: PKW-E | L12: PKW-E | M12: KFZ
A13: Zeit | B13: Rad | C13: KFZ | D13: Kombi | E13: bus | F13: bus | H13: Anh. | I13: Sonst. | J13: / 15 min | K13: / 30 min | L13: / 1 Std. | M13: / 1 Std.
A14: 5:00-5:15 | J14: =SUMPRODUCT(B14:I14,$B$11:$I$11) -> 0
A15: 5:15-5:30 | J15: =SUMPRODUCT(B15:I15,$B$11:$I$11) -> 0 | K15: =J15+J14 -> 0
A16: 5:30-5:45 | J16: =SUMPRODUCT(B16:I16,$B$11:$I$11) -> 0
A17: 5:45-6:00 | J17: =SUMPRODUCT(B17:I17,$B$11:$I$11) -> 0 | K17: =J17+J16 -> 0 | L17: =SUM(J14:J17) -> 0 | M17: =SUM(C14:I17) -> 0
A18: 6:00-6:15 | J18: =SUMPRODUCT(B18:I18,$B$11:$I$11) -> 0
A19: 6:15-6:30 | J19: =SUMPRODUCT(B19:I19,$B$11:$I$11) -> 0 | K19: =J19+J18 -> 0
A20: 6:30-6:45 | J20: =SUMPRODUCT(B20:I20,$B$11:$I$11) -> 0
A21: 6:45-7:00 | J21: =SUMPRODUCT(B21:I21,$B$11:$I$11) -> 0 | K21: =J21+J20 -> 0 | L21: =SUM(J18:J21) -> 0 | M21: =SUM(C18:I21) -> 0
A22: 7:00-7:15 | B22: 0 | C22: 0 | D22: 11 | E22: 0 | F22: 0 | G22: 0 | H22: 0 | I22: 0 | J22: =SUMPRODUCT(B22:I22,$B$11:$I$11) -> 11
A23: 7:15-7:30 | B23: 2 | C23: 0 | D23: 8 | E23: 0 | F23: 0 | G23: 1 | H23: 0 | I23: 0 | J23: =SUMPRODUCT(B23:I23,$B$11:$I$11) -> 10.6 | K23: =J23+J22 -> 21.6
A24: 7:30-7:45 | B24: 0 | C24: 0 | D24: 14 | E24: 0 | F24: 0 | G24: 0 | H24: 0 | I24: 0 | J24: =SUMPRODUCT(B24:I24,$B$11:$I$11) -> 14
A25: 7:45-8:00 | B25: 0 | C25: 0 | D25: 11 | E25: 0 | F25: 0 | G25: 0 | H25: 0 | I25: 0 | J25: =SUMPRODUCT(B25:I25,$B$11:$I$11) -> 11 | K25: =J25+J24 -> 25 | L25: =SUM(J22:J25) -> 46.6 | M25: =SUM(C22:I25) -> 45
A26: 8:00-8:15 | B26: 0 | C26: 0 | D26: 6 | E26: 0 | F26: 0 | G26: 0 | H26: 0 | I26: 0 | J26: =SUMPRODUCT(B26:I26,$B$11:$I$11) -> 6
A27: 8:15-8:30 | B27: 1 | C27: 0 | D27: 8 | E27: 0 | F27: 0 | G27: 0 | H27: 0 | I27: 0 | J27: =SUMPRODUCT(B27:I27,$B$11:$I$11) -> 8.3 | K27: =J27+J26 -> 14.3
A28: 8:30-8:45 | B28: 0 | C28: 0 | D28: 11 | E28: 0 | F28: 0 | G28: 0 | H28: 0 | I28: 0 | J28: =SUMPRODUCT(B28:I28,$B$11:$I$11) -> 11
A29: 8:45-9:00 | B29: 0 | C29: 0 | D29: 17 | E29: 0 | F29: 0 | G29: 0 | H29: 0 | I29: 0 | J29: =SUMPRODUCT(B29:I29,$B$11:$I$11) -> 17 | K29: =J29+J28 -> 28 | L29: =SUM(J26:J29) -> 42.3 | M29: =SUM(C26:I29) -> 42
A30: 9:00-9:15 | B30: 0 | C30: 0 | D30: 6 | E30: 0 | F30: 0 | G30: 0 | H30: 0 | I30: 0 | J30: =SUMPRODUCT(B30:I30,$B$11:$I$11) -> 6
A31: 9:15-9:30 | B31: 0 | C31: 0 | D31: 8 | E31: 0 | F31: 0 | G31: 0 | H31: 0 | I31: 0 | J31: =SUMPRODUCT(B31:I31,$B$11:$I$11) -> 8 | K31: =J31+J30 -> 14
A32: 9:30-9:45 | B32: 1 | C32: 0 | D32: 4 | E32: 0 | F32: 0 | G32: 0 | H32: 0 | I32: 0 | J32: =SUMPRODUCT(B32:I32,$B$11:$I$11) -> 4.3
A33: 9:45-10:00 | B33: 0 | C33: 0 | D33: 16 | E33: 0 | F33: 0 | G33: 0 | H33: 0 | I33: 0 | J33: =SUMPRODUCT(B33:I33,$B$11:$I$11) -> 16 | K33: =J33+J32 -> 20.3 | L33: =SUM(J30:J33) -> 34.3 | M33: =SUM(C30:I33) -> 34
A34: 10:00-10:15 | B34: 0 | C34: 0 | D34: 8 | E34: 0 | F34: 0 | G34: 0 | H34: 0 | I34: 0 | J34: =SUMPRODUCT(B34:I34,$B$11:$I$11) -> 8
A35: 10:15-10:30 | B35: 0 | C35: 0 | D35: 13 | E35: 0 | F35: 0 | G35: 0 | H35: 0 | I35: 0 | J35: =SUMPRODUCT(B35:I35,$B$11:$I$11) -> 13 | K35: =J35+J34 -> 21
A36: 10:30-10:45 | B36: 0 | C36: 0 | D36: 16 | E36: 0 | F36: 0 | G36: 0 | H36: 0 | I36: 0 | J36: =SUMPRODUCT(B36:I36,$B$11:$I$11) -> 16
A37: 10:45-11:00 | B37: 1 | C37: 0 | D37: 17 | E37: 0 | F37: 0 | G37: 0 | H37: 0 | I37: 0 | J37: =SUMPRODUCT(B37:I37,$B$11:$I$11) -> 17.3 | K37: =J37+J36 -> 33.3 | L37: =SUM(J34:J37) -> 54.3 | M37: =SUM(C34:I37) -> 54
A38: 11:00-11:15 | B38: 2 | C38: 0 | D38: 19 | E38: 0 | F38: 0 | G38: 0 | H38: 0 | I38: 0 | J38: =SUMPRODUCT(B38:I38,$B$11:$I$11) -> 19.6
A39: 11:15-11:30 | B39: 3 | C39: 0 | D39: 22 | E39: 0 | F39: 0 | G39: 0 | H39: 0 | I39: 0 | J39: =SUMPRODUCT(B39:I39,$B$11:$I$11) -> 22.9 | K39: =J39+J38 -> 42.5
A40: 11:30-11:45 | B40: 1 | C40: 0 | D40: 13 | E40: 1 | F40: 0 | G40: 0 | H40: 0 | I40: 0 | J40: =SUMPRODUCT(B40:I40,$B$11:$I$11) -> 15.3
A41: 11:45-12:00 | B41: 0 | C41: 0 | D41: 17 | E41: 0 | F41: 0 | G41: 0 | H41: 0 | I41: 0 | J41: =SUMPRODUCT(B41:I41,$B$11:$I$11) -> 17 | K41: =J41+J40 -> 32.3 | L41: =SUM(J38:J41) -> 74.8 | M41: =SUM(C38:I41) -> 72
A42: 12:00-12:15 | B42: 0 | C42: 0 | D42: 16 | E42: 0 | F42: 0 | G42: 0 | H42: 0 | I42: 0 | J42: =SUMPRODUCT(B42:I42,$B$11:$I$11) -> 16
...

Sheet R6
A3: ICRA Schwap e.U.
A4: VERKEHRSZÄHLUNG - PKW-Einheiten
A5: Datum : | J5: Lfd. Nummer : | K5: 0
A6: =Deckbl.!I11 -> 45944 | J6: Wetter : | K6: =Deckbl.!I12 -> 9-14 ° sonnig
B7: Verkehrszählung : | C7: =Deckbl.!C8 -> B122 / Badhaller Straße / Holznerweg (Bad Hall)
B8: Zählstelle : | I8: Sachbearbeiter : | J8: ICRA / Schwap
B9: Richtung : | C9: R6 | I9: Uhrzeit : | J9: =Deckbl.!C11 -> 7-19 Uhr
B10: Bemerkung :
A11: Faktoren | B11: 0.3 | C11: 0.5 | D11: 1 | E11: 2 | F11: 2 | G11: 2 | H11: 3 | I11: 2
C12: einsp. | D12: PKW | E12: Linien- | F12: Reise- | G12: LKW | H12: LKW + | I12: Traktor | J12: PKW-E | K12: PKW-E | L12: PKW-E | M12: KFZ
A13: Zeit | B13: Rad | C13: KFZ | D13: Kombi | E13: bus | F13: bus | H13: Anh. | I13: Sonst. | J13: / 15 min | K13: / 30 min | L13: / 1 Std. | M13: / 1 Std.
A14: 5:00-5:15 | J14: =SUMPRODUCT(B14:I14,$B$11:$I$11) -> 0
A15: 5:15-5:30 | J15: =SUMPRODUCT(B15:I15,$B$11:$I$11) -> 0 | K15: =J15+J14 -> 0
A16: 5:30-5:45 | J16: =SUMPRODUCT(B16:I16,$B$11:$I$11) -> 0
A17: 5:45-6:00 | J17: =SUMPRODUCT(B17:I17,$B$11:$I$11) -> 0 | K17: =J17+J16 -> 0 | L17: =SUM(J14:J17) -> 0 | M17: =SUM(C14:I17) -> 0
A18: 6:00-6:15 | J18: =SUMPRODUCT(B18:I18,$B$11:$I$11) -> 0
A19: 6:15-6:30 | J19: =SUMPRODUCT(B19:I19,$B$11:$I$11) -> 0 | K19: =J19+J18 -> 0
A20: 6:30-6:45 | J20: =SUMPRODUCT(B20:I20,$B$11:$I$11) -> 0
A21: 6:45-7:00 | J21: =SUMPRODUCT(B21:I21,$B$11:$I$11) -> 0 | K21: =J21+J20 -> 0 | L21: =SUM(J18:J21) -> 0 | M21: =SUM(C18:I21) -> 0
A22: 7:00-7:15 | B22: 0 | C22: 0 | D22: 15 | E22: 0 | F22: 0 | G22: 0 | H22: 0 | I22: 0 | J22: =SUMPRODUCT(B22:I22,$B$11:$I$11) -> 15
A23: 7:15-7:30 | B23: 0 | C23: 0 | D23: 16 | E23: 0 | F23: 0 | G23: 1 | H23: 1 | I23: 0 | J23: =SUMPRODUCT(B23:I23,$B$11:$I$11) -> 21 | K23: =J23+J22 -> 36
A24: 7:30-7:45 | B24: 0 | C24: 0 | D24: 17 | E24: 0 | F24: 0 | G24: 0 | H24: 0 | I24: 0 | J24: =SUMPRODUCT(B24:I24,$B$11:$I$11) -> 17
A25: 7:45-8:00 | B25: 0 | C25: 1 | D25: 12 | E25: 0 | F25: 0 | G25: 0 | H25: 0 | I25: 0 | J25: =SUMPRODUCT(B25:I25,$B$11:$I$11) -> 12.5 | K25: =J25+J24 -> 29.5 | L25: =SUM(J22:J25) -> 65.5 | M25: =SUM(C22:I25) -> 63
A26: 8:00-8:15 | B26: 0 | C26: 0 | D26: 12 | E26: 0 | F26: 0 | G26: 0 | H26: 0 | I26: 0 | J26: =SUMPRODUCT(B26:I26,$B$11:$I$11) -> 12
A27: 8:15-8:30 | B27: 0 | C27: 0 | D27: 16 | E27: 1 | F27: 0 | G27: 0 | H27: 0 | I27: 0 | J27: =SUMPRODUCT(B27:I27,$B$11:$I$11) -> 18 | K27: =J27+J26 -> 30
A28: 8:30-8:45 | B28: 0 | C28: 1 | D28: 10 | E28: 0 | F28: 0 | G28: 1 | H28: 0 | I28: 0 | J28: =SUMPRODUCT(B28:I28,$B$11:$I$11) -> 12.5
A29: 8:45-9:00 | B29: 1 | C29: 0 | D29: 10 | E29: 0 | F29: 0 | G29: 1 | H29: 0 | I29: 0 | J29: =SUMPRODUCT(B29:I29,$B$11:$I$11) -> 12.3 | K29: =J29+J28 -> 24.8 | L29: =SUM(J26:J29) -> 54.8 | M29: =SUM(C26:I29) -> 52
A30: 9:00-9:15 | B30: 0 | C30: 0 | D30: 16 | E30: 0 | F30: 0 | G30: 0 | H30: 0 | I30: 0 | J30: =SUMPRODUCT(B30:I30,$B$11:$I$11) -> 16
A31: 9:15-9:30 | B31: 1 | C31: 0 | D31: 18 | E31: 0 | F31: 0 | G31: 0 | H31: 0 | I31: 0 | J31: =SUMPRODUCT(B31:I31,$B$11:$I$11) -> 18.3 | K31: =J31+J30 -> 34.3
A32: 9:30-9:45 | B32: 0 | C32: 0 | D32: 19 | E32: 0 | F32: 0 | G32: 1 | H32: 0 | I32: 0 | J32: =SUMPRODUCT(B32:I32,$B$11:$I$11) -> 21
A33: 9:45-10:00 | B33: 0 | C33: 0 | D33: 25 | E33: 0 | F33: 0 | G33: 1 | H33: 0 | I33: 0 | J33: =SUMPRODUCT(B33:I33,$B$11:$I$11) -> 27 | K33: =J33+J32 -> 48 | L33: =SUM(J30:J33) -> 82.3 | M33: =SUM(C30:I33) -> 80
A34: 10:00-10:15 | B34: 0 | C34: 0 | D34: 19 | E34: 0 | F34: 0 | G34: 0 | H34: 0 | I34: 0 | J34: =SUMPRODUCT(B34:I34,$B$11:$I$11) -> 19
A35: 10:15-10:30 | B35: 0 | C35: 0 | D35: 20 | E35: 0 | F35: 0 | G35: 0 | H35: 0 | I35: 0 | J35: =SUMPRODUCT(B35:I35,$B$11:$I$11) -> 20 | K35: =J35+J34 -> 39
A36: 10:30-10:45 | B36: 0 | C36: 0 | D36: 26 | E36: 0 | F36: 0 | G36: 0 | H36: 0 | I36: 0 | J36: =SUMPRODUCT(B36:I36,$B$11:$I$11) -> 26
A37: 10:45-11:00 | B37: 0 | C37: 0 | D37: 29 | E37: 0 | F37: 0 | G37: 0 | H37: 1 | I37: 0 | J37: =SUMPRODUCT(B37:I37,$B$11:$I$11) -> 32 | K37: =J37+J36 -> 58 | L37: =SUM(J34:J37) -> 97 | M37: =SUM(C34:I37) -> 95
A38: 11:00-11:15 | B38: 0 | C38: 0 | D38: 30 | E38: 0 | F38: 0 | G38: 0 | H38: 0 | I38: 0 | J38: =SUMPRODUCT(B38:I38,$B$11:$I$11) -> 30
A39: 11:15-11:30 | B39: 1 | C39: 0 | D39: 24 | E39: 0 | F39: 0 | G39: 0 | H39: 0 | I39: 0 | J39: =SUMPRODUCT(B39:I39,$B$11:$I$11) -> 24.3 | K39: =J39+J38 -> 54.3
A40: 11:30-11:45 | B40: 0 | C40: 0 | D40: 17 | E40: 0 | F40: 0 | G40: 0 | H40: 0 | I40: 0 | J40: =SUMPRODUCT(B40:I40,$B$11:$I$11) -> 17
A41: 11:45-12:00 | B41: 0 | C41: 0 | D41: 16 | E41: 0 | F41: 0 | G41: 0 | H41: 0 | I41: 0 | J41: =SUMPRODUCT(B41:I41,$B$11:$I$11) -> 16 | K41: =J41+J40 -> 33 | L41: =SUM(J38:J41) -> 87.3 | M41: =SUM(C38:I41) -> 87
A42: 12:00-12:15 | B42: 0 | C42: 0 | D42: 23 | E42: 0 | F42: 0 | G42: 0 | H42: 0 | I42: 0 | J42: =SUMPRODUCT(B42:I42,$B$11:$I$11) -> 23
...

Sheet R7
A3: ICRA Schwap e.U.
A4: VERKEHRSZÄHLUNG - PKW-Einheiten
A5: Datum : | J5: Lfd. Nummer : | K5: 0
A6: =Deckbl.!I11 -> 45944 | J6: Wetter : | K6: =Deckbl.!I12 -> 9-14 ° sonnig
B7: Verkehrszählung : | C7: =Deckbl.!C8 -> B122 / Badhaller Straße / Holznerweg (Bad Hall)
B8: Zählstelle : | I8: Sachbearbeiter : | J8: ICRA / Schwap
B9: Richtung : | C9: R7 | I9: Uhrzeit : | J9: =Deckbl.!C11 -> 7-19 Uhr
B10: Bemerkung :
A11: Faktoren | B11: 0.3 | C11: 0.5 | D11: 1 | E11: 2 | F11: 2 | G11: 2 | H11: 3 | I11: 2
C12: einsp. | D12: PKW | E12: Linien- | F12: Reise- | G12: LKW | H12: LKW + | I12: Traktor | J12: PKW-E | K12: PKW-E | L12: PKW-E | M12: KFZ
A13: Zeit | B13: Rad | C13: KFZ | D13: Kombi | E13: bus | F13: bus | H13: Anh. | I13: Sonst. | J13: / 15 min | K13: / 30 min | L13: / 1 Std. | M13: / 1 Std.
A14: 5:00-5:15 | J14: =SUMPRODUCT(B14:I14,$B$11:$I$11) -> 0
A15: 5:15-5:30 | J15: =SUMPRODUCT(B15:I15,$B$11:$I$11) -> 0 | K15: =J15+J14 -> 0
A16: 5:30-5:45 | J16: =SUMPRODUCT(B16:I16,$B$11:$I$11) -> 0
A17: 5:45-6:00 | J17: =SUMPRODUCT(B17:I17,$B$11:$I$11) -> 0 | K17: =J17+J16 -> 0 | L17: =SUM(J14:J17) -> 0 | M17: =SUM(C14:I17) -> 0
A18: 6:00-6:15 | J18: =SUMPRODUCT(B18:I18,$B$11:$I$11) -> 0
A19: 6:15-6:30 | J19: =SUMPRODUCT(B19:I19,$B$11:$I$11) -> 0 | K19: =J19+J18 -> 0
A20: 6:30-6:45 | J20: =SUMPRODUCT(B20:I20,$B$11:$I$11) -> 0
A21: 6:45-7:00 | J21: =SUMPRODUCT(B21:I21,$B$11:$I$11) -> 0 | K21: =J21+J20 -> 0 | L21: =SUM(J18:J21) -> 0 | M21: =SUM(C18:I21) -> 0
A22: 7:00-7:15 | B22: 0 | C22: 0 | D22: 2 | E22: 0 | F22: 0 | G22: 1 | H22: 0 | I22: 0 | J22: =SUMPRODUCT(B22:I22,$B$11:$I$11) -> 4
A23: 7:15-7:30 | B23: 0 | C23: 0 | D23: 5 | E23: 0 | F23: 0 | G23: 0 | H23: 0 | I23: 0 | J23: =SUMPRODUCT(B23:I23,$B$11:$I$11) -> 5 | K23: =J23+J22 -> 9
A24: 7:30-7:45 | B24: 0 | C24: 0 | D24: 5 | E24: 0 | F24: 0 | G24: 0 | H24: 0 | I24: 0 | J24: =SUMPRODUCT(B24:I24,$B$11:$I$11) -> 5
A25: 7:45-8:00 | B25: 0 | C25: 0 | D25: 7 | E25: 0 | F25: 0 | G25: 0 | H25: 0 | I25: 0 | J25: =SUMPRODUCT(B25:I25,$B$11:$I$11) -> 7 | K25: =J25+J24 -> 12 | L25: =SUM(J22:J25) -> 21 | M25: =SUM(C22:I25) -> 20
A26: 8:00-8:15 | B26: 0 | C26: 0 | D26: 8 | E26: 0 | F26: 0 | G26: 0 | H26: 0 | I26: 0 | J26: =SUMPRODUCT(B26:I26,$B$11:$I$11) -> 8
A27: 8:15-8:30 | B27: 0 | C27: 0 | D27: 7 | E27: 0 | F27: 0 | G27: 0 | H27: 0 | I27: 0 | J27: =SUMPRODUCT(B27:I27,$B$11:$I$11) -> 7 | K27: =J27+J26 -> 15
A28: 8:30-8:45 | B28: 0 | C28: 0 | D28: 9 | E28: 0 | F28: 0 | G28: 0 | H28: 0 | I28: 0 | J28: =SUMPRODUCT(B28:I28,$B$11:$I$11) -> 9
A29: 8:45-9:00 | B29: 0 | C29: 0 | D29: 14 | E29: 0 | F29: 0 | G29: 0 | H29: 0 | I29: 0 | J29: =SUMPRODUCT(B29:I29,$B$11:$I$11) -> 14 | K29: =J29+J28 -> 23 | L29: =SUM(J26:J29) -> 38 | M29: =SUM(C26:I29) -> 38
A30: 9:00-9:15 | B30: 0 | C30: 0 | D30: 10 | E30: 0 | F30: 0 | G30: 0 | H30: 0 | I30: 0 | J30: =SUMPRODUCT(B30:I30,$B$11:$I$11) -> 10
A31: 9:15-9:30 | B31: 0 | C31: 0 | D31: 18 | E31: 0 | F31: 0 | G31: 0 | H31: 0 | I31: 0 | J31: =SUMPRODUCT(B31:I31,$B$11:$I$11) -> 18 | K31: =J31+J30 -> 28
A32: 9:30-9:45 | B32: 1 | C32: 0 | D32: 11 | E32: 0 | F32: 0 | G32: 0 | H32: 0 | I32: 0 | J32: =SUMPRODUCT(B32:I32,$B$11:$I$11) -> 11.3
A33: 9:45-10:00 | B33: 0 | C33: 0 | D33: 12 | E33: 0 | F33: 0 | G33: 0 | H33: 0 | I33: 0 | J33: =SUMPRODUCT(B33:I33,$B$11:$I$11) -> 12 | K33: =J33+J32 -> 23.3 | L33: =SUM(J30:J33) -> 51.3 | M33: =SUM(C30:I33) -> 51
A34: 10:00-10:15 | B34: 0 | C34: 0 | D34: 19 | E34: 0 | F34: 0 | G34: 0 | H34: 0 | I34: 0 | J34: =SUMPRODUCT(B34:I34,$B$11:$I$11) -> 19
A35: 10:15-10:30 | B35: 0 | C35: 0 | D35: 14 | E35: 0 | F35: 0 | G35: 0 | H35: 0 | I35: 0 | J35: =SUMPRODUCT(B35:I35,$B$11:$I$11) -> 14 | K35: =J35+J34 -> 33
A36: 10:30-10:45 | B36: 0 | C36: 0 | D36: 8 | E36: 0 | F36: 0 | G36: 0 | H36: 0 | I36: 0 | J36: =SUMPRODUCT(B36:I36,$B$11:$I$11) -> 8
A37: 10:45-11:00 | B37: 0 | C37: 0 | D37: 15 | E37: 0 | F37: 0 | G37: 0 | H37: 0 | I37: 0 | J37: =SUMPRODUCT(B37:I37,$B$11:$I$11) -> 15 | K37: =J37+J36 -> 23 | L37: =SUM(J34:J37) -> 56 | M37: =SUM(C34:I37) -> 56
A38: 11:00-11:15 | B38: 0 | C38: 0 | D38: 10 | E38: 0 | F38: 0 | G38: 0 | H38: 0 | I38: 0 | J38: =SUMPRODUCT(B38:I38,$B$11:$I$11) -> 10
A39: 11:15-11:30 | B39: 0 | C39: 0 | D39: 17 | E39: 0 | F39: 0 | G39: 0 | H39: 0 | I39: 0 | J39: =SUMPRODUCT(B39:I39,$B$11:$I$11) -> 17 | K39: =J39+J38 -> 27
A40: 11:30-11:45 | B40: 0 | C40: 0 | D40: 8 | E40: 0 | F40: 0 | G40: 0 | H40: 0 | I40: 0 | J40: =SUMPRODUCT(B40:I40,$B$11:$I$11) -> 8
A41: 11:45-12:00 | B41: 0 | C41: 0 | D41: 14 | E41: 0 | F41: 0 | G41: 0 | H41: 0 | I41: 0 | J41: =SUMPRODUCT(B41:I41,$B$11:$I$11) -> 14 | K41: =J41+J40 -> 22 | L41: =SUM(J38:J41) -> 49 | M41: =SUM(C38:I41) -> 49
A42: 12:00-12:15 | B42: 0 | C42: 0 | D42: 9 | E42: 0 | F42: 0 | G42: 0 | H42: 0 | I42: 0 | J42: =SUMPRODUCT(B42:I42,$B$11:$I$11) -> 9
...

Sheet R8
A3: ICRA Schwap e.U.
A4: VERKEHRSZÄHLUNG - PKW-Einheiten
A5: Datum : | J5: Lfd. Nummer : | K5: 0
A6: =Deckbl.!I11 -> 45944 | J6: Wetter : | K6: =Deckbl.!I12 -> 9-14 ° sonnig
B7: Verkehrszählung : | C7: =Deckbl.!C8 -> B122 / Badhaller Straße / Holznerweg (Bad Hall)
B8: Zählstelle : | I8: Sachbearbeiter : | J8: ICRA / Schwap
B9: Richtung : | C9: R8 | I9: Uhrzeit : | J9: =Deckbl.!C11 -> 7-19 Uhr
B10: Bemerkung :
A11: Faktoren | B11: 0.3 | C11: 0.5 | D11: 1 | E11: 2 | F11: 2 | G11: 2 | H11: 3 | I11: 2
C12: einsp. | D12: PKW | E12: Linien- | F12: Reise- | G12: LKW | H12: LKW + | I12: Traktor | J12: PKW-E | K12: PKW-E | L12: PKW-E | M12: KFZ
A13: Zeit | B13: Rad | C13: KFZ | D13: Kombi | E13: bus | F13: bus | H13: Anh. | I13: Sonst. | J13: / 15 min | K13: / 30 min | L13: / 1 Std. | M13: / 1 Std.
A14: 5:00-5:15 | J14: =SUMPRODUCT(B14:I14,$B$11:$I$11) -> 0
A15: 5:15-5:30 | J15: =SUMPRODUCT(B15:I15,$B$11:$I$11) -> 0 | K15: =J15+J14 -> 0
A16: 5:30-5:45 | J16: =SUMPRODUCT(B16:I16,$B$11:$I$11) -> 0
A17: 5:45-6:00 | J17: =SUMPRODUCT(B17:I17,$B$11:$I$11) -> 0 | K17: =J17+J16 -> 0 | L17: =SUM(J14:J17) -> 0 | M17: =SUM(C14:I17) -> 0
A18: 6:00-6:15 | J18: =SUMPRODUCT(B18:I18,$B$11:$I$11) -> 0
A19: 6:15-6:30 | J19: =SUMPRODUCT(B19:I19,$B$11:$I$11) -> 0 | K19: =J19+J18 -> 0
A20: 6:30-6:45 | J20: =SUMPRODUCT(B20:I20,$B$11:$I$11) -> 0
A21: 6:45-7:00 | J21: =SUMPRODUCT(B21:I21,$B$11:$I$11) -> 0 | K21: =J21+J20 -> 0 | L21: =SUM(J18:J21) -> 0 | M21: =SUM(C18:I21) -> 0
A22: 7:00-7:15 | B22: 0 | C22: 1 | D22: 123 | E22: 0 | F22: 0 | G22: 3 | H22: 5 | I22: 0 | J22: =SUMPRODUCT(B22:I22,$B$11:$I$11) -> 144.5
A23: 7:15-7:30 | B23: 0 | C23: 0 | D23: 108 | E23: 1 | F23: 0 | G23: 3 | H23: 2 | I23: 0 | J23: =SUMPRODUCT(B23:I23,$B$11:$I$11) -> 122 | K23: =J23+J22 -> 266.5
A24: 7:30-7:45 | B24: 0 | C24: 0 | D24: 114 | E24: 1 | F24: 0 | G24: 2 | H24: 4 | I24: 0 | J24: =SUMPRODUCT(B24:I24,$B$11:$I$11) -> 132
A25: 7:45-8:00 | B25: 0 | C25: 1 | D25: 90 | E25: 0 | F25: 1 | G25: 4 | H25: 2 | I25: 0 | J25: =SUMPRODUCT(B25:I25,$B$11:$I$11) -> 106.5 | K25: =J25+J24 -> 238.5 | L25: =SUM(J22:J25) -> 505 | M25: =SUM(C22:I25) -> 465
A26: 8:00-8:15 | B26: 0 | C26: 0 | D26: 86 | E26: 1 | F26: 0 | G26: 4 | H26: 4 | I26: 1 | J26: =SUMPRODUCT(B26:I26,$B$11:$I$11) -> 110
A27: 8:15-8:30 | B27: 0 | C27: 0 | D27: 73 | E27: 1 | F27: 0 | G27: 3 | H27: 1 | I27: 0 | J27: =SUMPRODUCT(B27:I27,$B$11:$I$11) -> 84 | K27: =J27+J26 -> 194
A28: 8:30-8:45 | B28: 0 | C28: 0 | D28: 73 | E28: 2 | F28: 0 | G28: 6 | H28: 7 | I28: 0 | J28: =SUMPRODUCT(B28:I28,$B$11:$I$11) -> 110
A29: 8:45-9:00 | B29: 0 | C29: 0 | D29: 68 | E29: 2 | F29: 0 | G29: 1 | H29: 7 | I29: 0 | J29: =SUMPRODUCT(B29:I29,$B$11:$I$11) -> 95 | K29: =J29+J28 -> 205 | L29: =SUM(J26:J29) -> 399 | M29: =SUM(C26:I29) -> 340
A30: 9:00-9:15 | B30: 0 | C30: 0 | D30: 58 | E30: 1 | F30: 0 | G30: 2 | H30: 6 | I30: 0 | J30: =SUMPRODUCT(B30:I30,$B$11:$I$11) -> 82
A31: 9:15-9:30 | B31: 0 | C31: 0 | D31: 74 | E31: 0 | F31: 0 | G31: 2 | H31: 10 | I31: 0 | J31: =SUMPRODUCT(B31:I31,$B$11:$I$11) -> 108 | K31: =J31+J30 -> 190
A32: 9:30-9:45 | B32: 0 | C32: 1 | D32: 64 | E32: 2 | F32: 0 | G32: 3 | H32: 8 | I32: 0 | J32: =SUMPRODUCT(B32:I32,$B$11:$I$11) -> 98.5
A33: 9:45-10:00 | B33: 0 | C33: 0 | D33: 60 | E33: 0 | F33: 0 | G33: 3 | H33: 4 | I33: 0 | J33: =SUMPRODUCT(B33:I33,$B$11:$I$11) -> 78 | K33: =J33+J32 -> 176.5 | L33: =SUM(J30:J33) -> 366.5 | M33: =SUM(C30:I33) -> 298
A34: 10:00-10:15 | B34: 0 | C34: 0 | D34: 58 | E34: 1 | F34: 0 | G34: 3 | H34: 4 | I34: 0 | J34: =SUMPRODUCT(B34:I34,$B$11:$I$11) -> 78
A35: 10:15-10:30 | B35: 0 | C35: 0 | D35: 57 | E35: 0 | F35: 0 | G35: 2 | H35: 7 | I35: 0 | J35: =SUMPRODUCT(B35:I35,$B$11:$I$11) -> 82 | K35: =J35+J34 -> 160
A36: 10:30-10:45 | B36: 0 | C36: 1 | D36: 55 | E36: 2 | F36: 0 | G36: 1 | H36: 8 | I36: 1 | J36: =SUMPRODUCT(B36:I36,$B$11:$I$11) -> 87.5
A37: 10:45-11:00 | B37: 0 | C37: 1 | D37: 65 | E37: 1 | F37: 0 | G37: 2 | H37: 4 | I37: 0 | J37: =SUMPRODUCT(B37:I37,$B$11:$I$11) -> 83.5 | K37: =J37+J36 -> 171 | L37: =SUM(J34:J37) -> 331 | M37: =SUM(C34:I37) -> 273
A38: 11:00-11:15 | B38: 0 | C38: 0 | D38: 64 | E38: 0 | F38: 0 | G38: 5 | H38: 8 | I38: 1 | J38: =SUMPRODUCT(B38:I38,$B$11:$I$11) -> 100
A39: 11:15-11:30 | B39: 0 | C39: 0 | D39: 65 | E39: 0 | F39: 0 | G39: 6 | H39: 8 | I39: 0 | J39: =SUMPRODUCT(B39:I39,$B$11:$I$11) -> 101 | K39: =J39+J38 -> 201
A40: 11:30-11:45 | B40: 0 | C40: 0 | D40: 64 | E40: 2 | F40: 0 | G40: 6 | H40: 7 | I40: 0 | J40: =SUMPRODUCT(B40:I40,$B$11:$I$11) -> 101
A41: 11:45-12:00 | B41: 0 | C41: 0 | D41: 56 | E41: 3 | F41: 0 | G41: 2 | H41: 5 | I41: 1 | J41: =SUMPRODUCT(B41:I41,$B$11:$I$11) -> 83 | K41: =J41+J40 -> 184 | L41: =SUM(J38:J41) -> 385 | M41: =SUM(C38:I41) -> 303
A42: 12:00-12:15 | B42: 0 | C42: 1 | D42: 65 | E42: 2 | F42: 0 | G42: 2 | H42: 8 | I42: 0 | J42: =SUMPRODUCT(B42:I42,$B$11:$I$11) -> 97.5
...

Sheet R9
A3: ICRA Schwap e.U.
A4: VERKEHRSZÄHLUNG - PKW-Einheiten
A5: Datum : | J5: Lfd. Nummer : | K5: 0
A6: =Deckbl.!I11 -> 45944 | J6: Wetter : | K6: =Deckbl.!I12 -> 9-14 ° sonnig
B7: Verkehrszählung : | C7: =Deckbl.!C8 -> B122 / Badhaller Straße / Holznerweg (Bad Hall)
B8: Zählstelle : | I8: Sachbearbeiter : | J8: ICRA / Schwap
B9: Richtung : | C9: R9 | I9: Uhrzeit : | J9: =Deckbl.!C11 -> 7-19 Uhr
B10: Bemerkung :
A11: Faktoren | B11: 0.3 | C11: 0.5 | D11: 1 | E11: 2 | F11: 2 | G11: 2 | H11: 3 | I11: 2
C12: einsp. | D12: PKW | E12: Linien- | F12: Reise- | G12: LKW | H12: LKW + | I12: Traktor | J12: PKW-E | K12: PKW-E | L12: PKW-E | M12: KFZ
A13: Zeit | B13: Rad | C13: KFZ | D13: Kombi | E13: bus | F13: bus | H13: Anh. | I13: Sonst. | J13: / 15 min | K13: / 30 min | L13: / 1 Std. | M13: / 1 Std.
A14: 5:00-5:15 | J14: =SUMPRODUCT(B14:I14,$B$11:$I$11) -> 0
A15: 5:15-5:30 | J15: =SUMPRODUCT(B15:I15,$B$11:$I$11) -> 0 | K15: =J15+J14 -> 0
A16: 5:30-5:45 | J16: =SUMPRODUCT(B16:I16,$B$11:$I$11) -> 0
A17: 5:45-6:00 | J17: =SUMPRODUCT(B17:I17,$B$11:$I$11) -> 0 | K17: =J17+J16 -> 0 | L17: =SUM(J14:J17) -> 0 | M17: =SUM(C14:I17) -> 0
A18: 6:00-6:15 | J18: =SUMPRODUCT(B18:I18,$B$11:$I$11) -> 0
A19: 6:15-6:30 | J19: =SUMPRODUCT(B19:I19,$B$11:$I$11) -> 0 | K19: =J19+J18 -> 0
A20: 6:30-6:45 | J20: =SUMPRODUCT(B20:I20,$B$11:$I$11) -> 0
A21: 6:45-7:00 | J21: =SUMPRODUCT(B21:I21,$B$11:$I$11) -> 0 | K21: =J21+J20 -> 0 | L21: =SUM(J18:J21) -> 0 | M21: =SUM(C18:I21) -> 0
A22: 7:00-7:15 | B22: 0 | C22: 0 | D22: 20 | E22: 0 | F22: 0 | G22: 0 | H22: 0 | I22: 0 | J22: =SUMPRODUCT(B22:I22,$B$11:$I$11) -> 20
A23: 7:15-7:30 | B23: 0 | C23: 0 | D23: 41 | E23: 1 | F23: 0 | G23: 0 | H23: 0 | I23: 0 | J23: =SUMPRODUCT(B23:I23,$B$11:$I$11) -> 43 | K23: =J23+J22 -> 63
A24: 7:30-7:45 | B24: 0 | C24: 0 | D24: 23 | E24: 1 | F24: 0 | G24: 0 | H24: 0 | I24: 0 | J24: =SUMPRODUCT(B24:I24,$B$11:$I$11) -> 25
A25: 7:45-8:00 | B25: 0 | C25: 0 | D25: 14 | E25: 0 | F25: 0 | G25: 0 | H25: 0 | I25: 0 | J25: =SUMPRODUCT(B25:I25,$B$11:$I$11) -> 14 | K25: =J25+J24 -> 39 | L25: =SUM(J22:J25) -> 102 | M25: =SUM(C22:I25) -> 100
A26: 8:00-8:15 | B26: 0 | C26: 0 | D26: 19 | E26: 0 | F26: 0 | G26: 1 | H26: 0 | I26: 0 | J26: =SUMPRODUCT(B26:I26,$B$11:$I$11) -> 21
A27: 8:15-8:30 | B27: 0 | C27: 0 | D27: 14 | E27: 0 | F27: 0 | G27: 1 | H27: 0 | I27: 0 | J27: =SUMPRODUCT(B27:I27,$B$11:$I$11) -> 16 | K27: =J27+J26 -> 37
A28: 8:30-8:45 | B28: 0 | C28: 0 | D28: 21 | E28: 1 | F28: 0 | G28: 2 | H28: 1 | I28: 0 | J28: =SUMPRODUCT(B28:I28,$B$11:$I$11) -> 30
A29: 8:45-9:00 | B29: 0 | C29: 0 | D29: 12 | E29: 0 | F29: 0 | G29: 0 | H29: 0 | I29: 0 | J29: =SUMPRODUCT(B29:I29,$B$11:$I$11) -> 12 | K29: =J29+J28 -> 42 | L29: =SUM(J26:J29) -> 79 | M29: =SUM(C26:I29) -> 72
A30: 9:00-9:15 | B30: 0 | C30: 0 | D30: 14 | E30: 0 | F30: 0 | G30: 0 | H30: 0 | I30: 0 | J30: =SUMPRODUCT(B30:I30,$B$11:$I$11) -> 14
A31: 9:15-9:30 | B31: 0 | C31: 0 | D31: 11 | E31: 0 | F31: 0 | G31: 0 | H31: 0 | I31: 0 | J31: =SUMPRODUCT(B31:I31,$B$11:$I$11) -> 11 | K31: =J31+J30 -> 25
A32: 9:30-9:45 | B32: 0 | C32: 0 | D32: 15 | E32: 1 | F32: 0 | G32: 0 | H32: 0 | I32: 0 | J32: =SUMPRODUCT(B32:I32,$B$11:$I$11) -> 17
A33: 9:45-10:00 | B33: 0 | C33: 0 | D33: 9 | E33: 0 | F33: 0 | G33: 0 | H33: 0 | I33: 0 | J33: =SUMPRODUCT(B33:I33,$B$11:$I$11) -> 9 | K33: =J33+J32 -> 26 | L33: =SUM(J30:J33) -> 51 | M33: =SUM(C30:I33) -> 50
A34: 10:00-10:15 | B34: 0 | C34: 0 | D34: 12 | E34: 0 | F34: 0 | G34: 0 | H34: 0 | I34: 0 | J34: =SUMPRODUCT(B34:I34,$B$11:$I$11) -> 12
A35: 10:15-10:30 | B35: 0 | C35: 0 | D35: 13 | E35: 0 | F35: 0 | G35: 0 | H35: 0 | I35: 0 | J35: =SUMPRODUCT(B35:I35,$B$11:$I$11) -> 13 | K35: =J35+J34 -> 25
A36: 10:30-10:45 | B36: 0 | C36: 0 | D36: 13 | E36: 0 | F36: 0 | G36: 0 | H36: 0 | I36: 0 | J36: =SUMPRODUCT(B36:I36,$B$11:$I$11) -> 13
A37: 10:45-11:00 | B37: 0 | C37: 0 | D37: 8 | E37: 0 | F37: 0 | G37: 0 | H37: 0 | I37: 0 | J37: =SUMPRODUCT(B37:I37,$B$11:$I$11) -> 8 | K37: =J37+J36 -> 21 | L37: =SUM(J34:J37) -> 46 | M37: =SUM(C34:I37) -> 46
A38: 11:00-11:15 | B38: 0 | C38: 0 | D38: 18 | E38: 0 | F38: 0 | G38: 1 | H38: 0 | I38: 0 | J38: =SUMPRODUCT(B38:I38,$B$11:$I$11) -> 20
A39: 11:15-11:30 | B39: 0 | C39: 0 | D39: 25 | E39: 1 | F39: 0 | G39: 0 | H39: 0 | I39: 0 | J39: =SUMPRODUCT(B39:I39,$B$11:$I$11) -> 27 | K39: =J39+J38 -> 47
A40: 11:30-11:45 | B40: 0 | C40: 0 | D40: 19 | E40: 0 | F40: 0 | G40: 1 | H40: 0 | I40: 0 | J40: =SUMPRODUCT(B40:I40,$B$11:$I$11) -> 21
A41: 11:45-12:00 | B41: 0 | C41: 1 | D41: 16 | E41: 0 | F41: 0 | G41: 0 | H41: 0 | I41: 0 | J41: =SUMPRODUCT(B41:I41,$B$11:$I$11) -> 16.5 | K41: =J41+J40 -> 37.5 | L41: =SUM(J38:J41) -> 84.5 | M41: =SUM(C38:I41) -> 82
A42: 12:00-12:15 | B42: 0 | C42: 0 | D42: 24 | E42: 0 | F42: 0 | G42: 0 | H42: 0 | I42: 0 | J42: =SUMPRODUCT(B42:I42,$B$11:$I$11) -> 24
...

Sheet R10
A3: ICRA Schwap e.U.
A4: VERKEHRSZÄHLUNG - PKW-Einheiten
A5: Datum : | J5: Lfd. Nummer : | K5: 0
A6: =Deckbl.!I11 -> 45944 | J6: Wetter : | K6: =Deckbl.!I12 -> 9-14 ° sonnig
B7: Verkehrszählung : | C7: =Deckbl.!C8 -> B122 / Badhaller Straße / Holznerweg (Bad Hall)
B8: Zählstelle : | I8: Sachbearbeiter : | J8: ICRA / Schwap
B9: Richtung : | C9: R10 | I9: Uhrzeit : | J9: =Deckbl.!C11 -> 7-19 Uhr
B10: Bemerkung :
A11: Faktoren | B11: 0.3 | C11: 0.5 | D11: 1 | E11: 2 | F11: 2 | G11: 2 | H11: 3 | I11: 2
C12: einsp. | D12: PKW | E12: Linien- | F12: Reise- | G12: LKW | H12: LKW + | I12: Traktor | J12: PKW-E | K12: PKW-E | L12: PKW-E | M12: KFZ
A13: Zeit | B13: Rad | C13: KFZ | D13: Kombi | E13: bus | F13: bus | H13: Anh. | I13: Sonst. | J13: / 15 min | K13: / 30 min | L13: / 1 Std. | M13: / 1 Std.
A14: 5:00-5:15 | J14: =SUMPRODUCT(B14:I14,$B$11:$I$11) -> 0
A15: 5:15-5:30 | J15: =SUMPRODUCT(B15:I15,$B$11:$I$11) -> 0 | K15: =J15+J14 -> 0
A16: 5:30-5:45 | J16: =SUMPRODUCT(B16:I16,$B$11:$I$11) -> 0
A17: 5:45-6:00 | J17: =SUMPRODUCT(B17:I17,$B$11:$I$11) -> 0 | K17: =J17+J16 -> 0 | L17: =SUM(J14:J17) -> 0 | M17: =SUM(C14:I17) -> 0
A18: 6:00-6:15 | J18: =SUMPRODUCT(B18:I18,$B$11:$I$11) -> 0
A19: 6:15-6:30 | J19: =SUMPRODUCT(B19:I19,$B$11:$I$11) -> 0 | K19: =J19+J18 -> 0
A20: 6:30-6:45 | J20: =SUMPRODUCT(B20:I20,$B$11:$I$11) -> 0
A21: 6:45-7:00 | J21: =SUMPRODUCT(B21:I21,$B$11:$I$11) -> 0 | K21: =J21+J20 -> 0 | L21: =SUM(J18:J21) -> 0 | M21: =SUM(C18:I21) -> 0
A22: 7:00-7:15 | B22: 0 | C22: 0 | D22: 22 | E22: 0 | F22: 0 | G22: 0 | H22: 0 | I22: 0 | J22: =SUMPRODUCT(B22:I22,$B$11:$I$11) -> 22
A23: 7:15-7:30 | B23: 0 | C23: 0 | D23: 29 | E23: 1 | F23: 0 | G23: 0 | H23: 0 | I23: 0 | J23: =SUMPRODUCT(B23:I23,$B$11:$I$11) -> 31 | K23: =J23+J22 -> 53
A24: 7:30-7:45 | B24: 0 | C24: 0 | D24: 24 | E24: 1 | F24: 0 | G24: 0 | H24: 0 | I24: 0 | J24: =SUMPRODUCT(B24:I24,$B$11:$I$11) -> 26
A25: 7:45-8:00 | B25: 0 | C25: 0 | D25: 24 | E25: 0 | F25: 0 | G25: 1 | H25: 0 | I25: 0 | J25: =SUMPRODUCT(B25:I25,$B$11:$I$11) -> 26 | K25: =J25+J24 -> 52 | L25: =SUM(J22:J25) -> 105 | M25: =SUM(C22:I25) -> 102
A26: 8:00-8:15 | B26: 0 | C26: 0 | D26: 16 | E26: 0 | F26: 0 | G26: 1 | H26: 0 | I26: 0 | J26: =SUMPRODUCT(B26:I26,$B$11:$I$11) -> 18
A27: 8:15-8:30 | B27: 0 | C27: 0 | D27: 20 | E27: 1 | F27: 0 | G27: 0 | H27: 0 | I27: 0 | J27: =SUMPRODUCT(B27:I27,$B$11:$I$11) -> 22 | K27: =J27+J26 -> 40
A28: 8:30-8:45 | B28: 0 | C28: 0 | D28: 19 | E28: 0 | F28: 0 | G28: 0 | H28: 0 | I28: 0 | J28: =SUMPRODUCT(B28:I28,$B$11:$I$11) -> 19
A29: 8:45-9:00 | B29: 0 | C29: 0 | D29: 12 | E29: 0 | F29: 0 | G29: 1 | H29: 0 | I29: 0 | J29: =SUMPRODUCT(B29:I29,$B$11:$I$11) -> 14 | K29: =J29+J28 -> 33 | L29: =SUM(J26:J29) -> 73 | M29: =SUM(C26:I29) -> 70
A30: 9:00-9:15 | B30: 0 | C30: 1 | D30: 18 | E30: 0 | F30: 0 | G30: 0 | H30: 0 | I30: 0 | J30: =SUMPRODUCT(B30:I30,$B$11:$I$11) -> 18.5
A31: 9:15-9:30 | B31: 0 | C31: 0 | D31: 17 | E31: 0 | F31: 0 | G31: 0 | H31: 0 | I31: 0 | J31: =SUMPRODUCT(B31:I31,$B$11:$I$11) -> 17 | K31: =J31+J30 -> 35.5
A32: 9:30-9:45 | B32: 0 | C32: 0 | D32: 12 | E32: 0 | F32: 0 | G32: 0 | H32: 0 | I32: 0 | J32: =SUMPRODUCT(B32:I32,$B$11:$I$11) -> 12
A33: 9:45-10:00 | B33: 0 | C33: 0 | D33: 16 | E33: 0 | F33: 0 | G33: 1 | H33: 0 | I33: 0 | J33: =SUMPRODUCT(B33:I33,$B$11:$I$11) -> 18 | K33: =J33+J32 -> 30 | L33: =SUM(J30:J33) -> 65.5 | M33: =SUM(C30:I33) -> 65
A34: 10:00-10:15 | B34: 0 | C34: 0 | D34: 8 | E34: 1 | F34: 0 | G34: 0 | H34: 0 | I34: 0 | J34: =SUMPRODUCT(B34:I34,$B$11:$I$11) -> 10
A35: 10:15-10:30 | B35: 0 | C35: 0 | D35: 9 | E35: 0 | F35: 0 | G35: 0 | H35: 0 | I35: 0 | J35: =SUMPRODUCT(B35:I35,$B$11:$I$11) -> 9 | K35: =J35+J34 -> 19
A36: 10:30-10:45 | B36: 0 | C36: 0 | D36: 10 | E36: 0 | F36: 0 | G36: 0 | H36: 0 | I36: 0 | J36: =SUMPRODUCT(B36:I36,$B$11:$I$11) -> 10
A37: 10:45-11:00 | B37: 0 | C37: 0 | D37: 13 | E37: 0 | F37: 0 | G37: 0 | H37: 0 | I37: 0 | J37: =SUMPRODUCT(B37:I37,$B$11:$I$11) -> 13 | K37: =J37+J36 -> 23 | L37: =SUM(J34:J37) -> 42 | M37: =SUM(C34:I37) -> 41
A38: 11:00-11:15 | B38: 0 | C38: 0 | D38: 23 | E38: 1 | F38: 0 | G38: 0 | H38: 0 | I38: 0 | J38: =SUMPRODUCT(B38:I38,$B$11:$I$11) -> 25
A39: 11:15-11:30 | B39: 0 | C39: 0 | D39: 23 | E39: 0 | F39: 0 | G39: 1 | H39: 0 | I39: 0 | J39: =SUMPRODUCT(B39:I39,$B$11:$I$11) -> 25 | K39: =J39+J38 -> 50
A40: 11:30-11:45 | B40: 0 | C40: 0 | D40: 24 | E40: 0 | F40: 0 | G40: 0 | H40: 0 | I40: 0 | J40: =SUMPRODUCT(B40:I40,$B$11:$I$11) -> 24
A41: 11:45-12:00 | B41: 0 | C41: 0 | D41: 19 | E41: 1 | F41: 0 | G41: 0 | H41: 0 | I41: 0 | J41: =SUMPRODUCT(B41:I41,$B$11:$I$11) -> 21 | K41: =J41+J40 -> 45 | L41: =SUM(J38:J41) -> 95 | M41: =SUM(C38:I41) -> 92
A42: 12:00-12:15 | B42: 0 | C42: 0 | D42: 20 | E42: 0 | F42: 0 | G42: 0 | H42: 0 | I42: 0 | J42: =SUMPRODUCT(B42:I42,$B$11:$I$11) -> 20
...

Sheet R11
A3: ICRA Schwap e.U.
A4: VERKEHRSZÄHLUNG - PKW-Einheiten
A5: Datum : | J5: Lfd. Nummer : | K5: 0
A6: =Deckbl.!I11 -> 45944 | J6: Wetter : | K6: =Deckbl.!I12 -> 9-14 ° sonnig
B7: Verkehrszählung : | C7: =Deckbl.!C8 -> B122 / Badhaller Straße / Holznerweg (Bad Hall)
B8: Zählstelle : | I8: Sachbearbeiter : | J8: ICRA / Schwap
B9: Richtung : | C9: R11 | I9: Uhrzeit : | J9: =Deckbl.!C11 -> 7-19 Uhr
B10: Bemerkung :
A11: Faktoren | B11: 0.3 | C11: 0.5 | D11: 1 | E11: 2 | F11: 2 | G11: 2 | H11: 3 | I11: 2
C12: einsp. | D12: PKW | E12: Linien- | F12: Reise- | G12: LKW | H12: LKW + | I12: Traktor | J12: PKW-E | K12: PKW-E | L12: PKW-E | M12: KFZ
A13: Zeit | B13: Rad | C13: KFZ | D13: Kombi | E13: bus | F13: bus | H13: Anh. | I13: Sonst. | J13: / 15 min | K13: / 30 min | L13: / 1 Std. | M13: / 1 Std.
A14: 5:00-5:15 | J14: =SUMPRODUCT(B14:I14,$B$11:$I$11) -> 0
A15: 5:15-5:30 | J15: =SUMPRODUCT(B15:I15,$B$11:$I$11) -> 0 | K15: =J15+J14 -> 0
A16: 5:30-5:45 | J16: =SUMPRODUCT(B16:I16,$B$11:$I$11) -> 0
A17: 5:45-6:00 | J17: =SUMPRODUCT(B17:I17,$B$11:$I$11) -> 0 | K17: =J17+J16 -> 0 | L17: =SUM(J14:J17) -> 0 | M17: =SUM(C14:I17) -> 0
A18: 6:00-6:15 | J18: =SUMPRODUCT(B18:I18,$B$11:$I$11) -> 0
A19: 6:15-6:30 | J19: =SUMPRODUCT(B19:I19,$B$11:$I$11) -> 0 | K19: =J19+J18 -> 0
A20: 6:30-6:45 | J20: =SUMPRODUCT(B20:I20,$B$11:$I$11) -> 0
A21: 6:45-7:00 | J21: =SUMPRODUCT(B21:I21,$B$11:$I$11) -> 0 | K21: =J21+J20 -> 0 | L21: =SUM(J18:J21) -> 0 | M21: =SUM(C18:I21) -> 0
A22: 7:00-7:15 | B22: 0 | C22: 0 | D22: 7 | E22: 0 | F22: 0 | G22: 0 | H22: 0 | I22: 0 | J22: =SUMPRODUCT(B22:I22,$B$11:$I$11) -> 7
A23: 7:15-7:30 | B23: 0 | C23: 0 | D23: 15 | E23: 0 | F23: 0 | G23: 0 | H23: 0 | I23: 0 | J23: =SUMPRODUCT(B23:I23,$B$11:$I$11) -> 15 | K23: =J23+J22 -> 22
A24: 7:30-7:45 | B24: 1 | C24: 0 | D24: 16 | E24: 0 | F24: 0 | G24: 0 | H24: 0 | I24: 0 | J24: =SUMPRODUCT(B24:I24,$B$11:$I$11) -> 16.3
A25: 7:45-8:00 | B25: 0 | C25: 0 | D25: 7 | E25: 0 | F25: 0 | G25: 0 | H25: 0 | I25: 0 | J25: =SUMPRODUCT(B25:I25,$B$11:$I$11) -> 7 | K25: =J25+J24 -> 23.3 | L25: =SUM(J22:J25) -> 45.3 | M25: =SUM(C22:I25) -> 45
A26: 8:00-8:15 | B26: 0 | C26: 0 | D26: 7 | E26: 0 | F26: 0 | G26: 0 | H26: 0 | I26: 0 | J26: =SUMPRODUCT(B26:I26,$B$11:$I$11) -> 7
A27: 8:15-8:30 | B27: 0 | C27: 1 | D27: 11 | E27: 0 | F27: 0 | G27: 0 | H27: 0 | I27: 0 | J27: =SUMPRODUCT(B27:I27,$B$11:$I$11) -> 11.5 | K27: =J27+J26 -> 18.5
A28: 8:30-8:45 | B28: 0 | C28: 0 | D28: 6 | E28: 0 | F28: 0 | G28: 0 | H28: 0 | I28: 0 | J28: =SUMPRODUCT(B28:I28,$B$11:$I$11) -> 6
A29: 8:45-9:00 | B29: 0 | C29: 0 | D29: 7 | E29: 0 | F29: 0 | G29: 0 | H29: 0 | I29: 0 | J29: =SUMPRODUCT(B29:I29,$B$11:$I$11) -> 7 | K29: =J29+J28 -> 13 | L29: =SUM(J26:J29) -> 31.5 | M29: =SUM(C26:I29) -> 32
A30: 9:00-9:15 | B30: 0 | C30: 1 | D30: 13 | E30: 0 | F30: 0 | G30: 0 | H30: 0 | I30: 0 | J30: =SUMPRODUCT(B30:I30,$B$11:$I$11) -> 13.5
A31: 9:15-9:30 | B31: 0 | C31: 0 | D31: 12 | E31: 0 | F31: 0 | G31: 0 | H31: 0 | I31: 0 | J31: =SUMPRODUCT(B31:I31,$B$11:$I$11) -> 12 | K31: =J31+J30 -> 25.5
A32: 9:30-9:45 | B32: 0 | C32: 0 | D32: 13 | E32: 0 | F32: 0 | G32: 1 | H32: 0 | I32: 0 | J32: =SUMPRODUCT(B32:I32,$B$11:$I$11) -> 15
A33: 9:45-10:00 | B33: 0 | C33: 0 | D33: 9 | E33: 0 | F33: 0 | G33: 0 | H33: 0 | I33: 0 | J33: =SUMPRODUCT(B33:I33,$B$11:$I$11) -> 9 | K33: =J33+J32 -> 24 | L33: =SUM(J30:J33) -> 49.5 | M33: =SUM(C30:I33) -> 49
A34: 10:00-10:15 | B34: 0 | C34: 0 | D34: 17 | E34: 0 | F34: 0 | G34: 0 | H34: 0 | I34: 0 | J34: =SUMPRODUCT(B34:I34,$B$11:$I$11) -> 17
A35: 10:15-10:30 | B35: 1 | C35: 0 | D35: 16 | E35: 0 | F35: 0 | G35: 0 | H35: 0 | I35: 0 | J35: =SUMPRODUCT(B35:I35,$B$11:$I$11) -> 16.3 | K35: =J35+J34 -> 33.3
A36: 10:30-10:45 | B36: 2 | C36: 0 | D36: 16 | E36: 0 | F36: 0 | G36: 0 | H36: 0 | I36: 0 | J36: =SUMPRODUCT(B36:I36,$B$11:$I$11) -> 16.6
A37: 10:45-11:00 | B37: 0 | C37: 0 | D37: 10 | E37: 0 | F37: 0 | G37: 0 | H37: 0 | I37: 0 | J37: =SUMPRODUCT(B37:I37,$B$11:$I$11) -> 10 | K37: =J37+J36 -> 26.6 | L37: =SUM(J34:J37) -> 59.9 | M37: =SUM(C34:I37) -> 59
A38: 11:00-11:15 | B38: 0 | C38: 1 | D38: 14 | E38: 0 | F38: 0 | G38: 0 | H38: 0 | I38: 0 | J38: =SUMPRODUCT(B38:I38,$B$11:$I$11) -> 14.5
A39: 11:15-11:30 | B39: 0 | C39: 0 | D39: 6 | E39: 0 | F39: 0 | G39: 0 | H39: 0 | I39: 0 | J39: =SUMPRODUCT(B39:I39,$B$11:$I$11) -> 6 | K39: =J39+J38 -> 20.5
A40: 11:30-11:45 | B40: 1 | C40: 0 | D40: 14 | E40: 0 | F40: 0 | G40: 0 | H40: 0 | I40: 0 | J40: =SUMPRODUCT(B40:I40,$B$11:$I$11) -> 14.3
A41: 11:45-12:00 | B41: 0 | C41: 0 | D41: 14 | E41: 0 | F41: 0 | G41: 0 | H41: 0 | I41: 0 | J41: =SUMPRODUCT(B41:I41,$B$11:$I$11) -> 14 | K41: =J41+J40 -> 28.3 | L41: =SUM(J38:J41) -> 48.8 | M41: =SUM(C38:I41) -> 49
A42: 12:00-12:15 | B42: 0 | C42: 0 | D42: 14 | E42: 0 | F42: 0 | G42: 0 | H42: 0 | I42: 0 | J42: =SUMPRODUCT(B42:I42,$B$11:$I$11) -> 14
...

Sheet R12
A3: ICRA Schwap e.U.
A4: VERKEHRSZÄHLUNG - PKW-Einheiten
A5: Datum : | J5: Lfd. Nummer : | K5: 0
A6: =Deckbl.!I11 -> 45944 | J6: Wetter : | K6: =Deckbl.!I12 -> 9-14 ° sonnig
B7: Verkehrszählung : | C7: =Deckbl.!C8 -> B122 / Badhaller Straße / Holznerweg (Bad Hall)
B8: Zählstelle : | I8: Sachbearbeiter : | J8: ICRA / Schwap
B9: Richtung : | C9: R12 | I9: Uhrzeit : | J9: =Deckbl.!C11 -> 7-19 Uhr
B10: Bemerkung :
A11: Faktoren | B11: 0.3 | C11: 0.5 | D11: 1 | E11: 2 | F11: 2 | G11: 2 | H11: 3 | I11: 2
C12: einsp. | D12: PKW | E12: Linien- | F12: Reise- | G12: LKW | H12: LKW + | I12: Traktor | J12: PKW-E | K12: PKW-E | L12: PKW-E | M12: KFZ
A13: Zeit | B13: Rad | C13: KFZ | D13: Kombi | E13: bus | F13: bus | H13: Anh. | I13: Sonst. | J13: / 15 min | K13: / 30 min | L13: / 1 Std. | M13: / 1 Std.
A14: 5:00-5:15 | J14: =SUMPRODUCT(B14:I14,$B$11:$I$11) -> 0
A15: 5:15-5:30 | J15: =SUMPRODUCT(B15:I15,$B$11:$I$11) -> 0 | K15: =J15+J14 -> 0
A16: 5:30-5:45 | J16: =SUMPRODUCT(B16:I16,$B$11:$I$11) -> 0
A17: 5:45-6:00 | J17: =SUMPRODUCT(B17:I17,$B$11:$I$11) -> 0 | K17: =J17+J16 -> 0 | L17: =SUM(J14:J17) -> 0 | M17: =SUM(C14:I17) -> 0
A18: 6:00-6:15 | J18: =SUMPRODUCT(B18:I18,$B$11:$I$11) -> 0
A19: 6:15-6:30 | J19: =SUMPRODUCT(B19:I19,$B$11:$I$11) -> 0 | K19: =J19+J18 -> 0
A20: 6:30-6:45 | J20: =SUMPRODUCT(B20:I20,$B$11:$I$11) -> 0
A21: 6:45-7:00 | J21: =SUMPRODUCT(B21:I21,$B$11:$I$11) -> 0 | K21: =J21+J20 -> 0 | L21: =SUM(J18:J21) -> 0 | M21: =SUM(C18:I21) -> 0
A22: 7:00-7:15 | B22: 0 | C22: 0 | D22: 11 | E22: 0 | F22: 0 | G22: 0 | H22: 0 | I22: 0 | J22: =SUMPRODUCT(B22:I22,$B$11:$I$11) -> 11
A23: 7:15-7:30 | B23: 0 | C23: 0 | D23: 24 | E23: 0 | F23: 0 | G23: 0 | H23: 0 | I23: 0 | J23: =SUMPRODUCT(B23:I23,$B$11:$I$11) -> 24 | K23: =J23+J22 -> 35
A24: 7:30-7:45 | B24: 0 | C24: 0 | D24: 24 | E24: 0 | F24: 0 | G24: 0 | H24: 0 | I24: 0 | J24: =SUMPRODUCT(B24:I24,$B$11:$I$11) -> 24
A25: 7:45-8:00 | B25: 0 | C25: 1 | D25: 19 | E25: 0 | F25: 0 | G25: 0 | H25: 0 | I25: 0 | J25: =SUMPRODUCT(B25:I25,$B$11:$I$11) -> 19.5 | K25: =J25+J24 -> 43.5 | L25: =SUM(J22:J25) -> 78.5 | M25: =SUM(C22:I25) -> 79
A26: 8:00-8:15 | B26: 0 | C26: 0 | D26: 12 | E26: 0 | F26: 0 | G26: 0 | H26: 0 | I26: 0 | J26: =SUMPRODUCT(B26:I26,$B$11:$I$11) -> 12
A27: 8:15-8:30 | B27: 0 | C27: 0 | D27: 6 | E27: 0 | F27: 0 | G27: 0 | H27: 0 | I27: 0 | J27: =SUMPRODUCT(B27:I27,$B$11:$I$11) -> 6 | K27: =J27+J26 -> 18
A28: 8:30-8:45 | B28: 0 | C28: 0 | D28: 8 | E28: 0 | F28: 0 | G28: 0 | H28: 0 | I28: 0 | J28: =SUMPRODUCT(B28:I28,$B$11:$I$11) -> 8
A29: 8:45-9:00 | B29: 0 | C29: 0 | D29: 7 | E29: 0 | F29: 0 | G29: 0 | H29: 0 | I29: 0 | J29: =SUMPRODUCT(B29:I29,$B$11:$I$11) -> 7 | K29: =J29+J28 -> 15 | L29: =SUM(J26:J29) -> 33 | M29: =SUM(C26:I29) -> 33
A30: 9:00-9:15 | B30: 0 | C30: 0 | D30: 12 | E30: 0 | F30: 0 | G30: 1 | H30: 0 | I30: 0 | J30: =SUMPRODUCT(B30:I30,$B$11:$I$11) -> 14
A31: 9:15-9:30 | B31: 0 | C31: 0 | D31: 9 | E31: 0 | F31: 0 | G31: 0 | H31: 0 | I31: 0 | J31: =SUMPRODUCT(B31:I31,$B$11:$I$11) -> 9 | K31: =J31+J30 -> 23
A32: 9:30-9:45 | B32: 0 | C32: 0 | D32: 13 | E32: 0 | F32: 0 | G32: 0 | H32: 0 | I32: 0 | J32: =SUMPRODUCT(B32:I32,$B$11:$I$11) -> 13
A33: 9:45-10:00 | B33: 0 | C33: 0 | D33: 11 | E33: 0 | F33: 0 | G33: 0 | H33: 0 | I33: 0 | J33: =SUMPRODUCT(B33:I33,$B$11:$I$11) -> 11 | K33: =J33+J32 -> 24 | L33: =SUM(J30:J33) -> 47 | M33: =SUM(C30:I33) -> 46
A34: 10:00-10:15 | B34: 0 | C34: 0 | D34: 12 | E34: 0 | F34: 0 | G34: 0 | H34: 0 | I34: 0 | J34: =SUMPRODUCT(B34:I34,$B$11:$I$11) -> 12
A35: 10:15-10:30 | B35: 0 | C35: 0 | D35: 11 | E35: 0 | F35: 0 | G35: 0 | H35: 0 | I35: 0 | J35: =SUMPRODUCT(B35:I35,$B$11:$I$11) -> 11 | K35: =J35+J34 -> 23
A36: 10:30-10:45 | B36: 0 | C36: 0 | D36: 9 | E36: 0 | F36: 0 | G36: 0 | H36: 0 | I36: 0 | J36: =SUMPRODUCT(B36:I36,$B$11:$I$11) -> 9
A37: 10:45-11:00 | B37: 0 | C37: 0 | D37: 11 | E37: 0 | F37: 0 | G37: 0 | H37: 0 | I37: 0 | J37: =SUMPRODUCT(B37:I37,$B$11:$I$11) -> 11 | K37: =J37+J36 -> 20 | L37: =SUM(J34:J37) -> 43 | M37: =SUM(C34:I37) -> 43
A38: 11:00-11:15 | B38: 0 | C38: 0 | D38: 9 | E38: 0 | F38: 0 | G38: 0 | H38: 0 | I38: 0 | J38: =SUMPRODUCT(B38:I38,$B$11:$I$11) -> 9
A39: 11:15-11:30 | B39: 0 | C39: 0 | D39: 14 | E39: 0 | F39: 0 | G39: 0 | H39: 0 | I39: 0 | J39: =SUMPRODUCT(B39:I39,$B$11:$I$11) -> 14 | K39: =J39+J38 -> 23
A40: 11:30-11:45 | B40: 0 | C40: 0 | D40: 11 | E40: 0 | F40: 0 | G40: 0 | H40: 0 | I40: 0 | J40: =SUMPRODUCT(B40:I40,$B$11:$I$11) -> 11
A41: 11:45-12:00 | B41: 0 | C41: 0 | D41: 7 | E41: 0 | F41: 0 | G41: 0 | H41: 0 | I41: 0 | J41: =SUMPRODUCT(B41:I41,$B$11:$I$11) -> 7 | K41: =J41+J40 -> 18 | L41: =SUM(J38:J41) -> 41 | M41: =SUM(C38:I41) -> 41
A42: 12:00-12:15 | B42: 0 | C42: 0 | D42: 12 | E42: 0 | F42: 0 | G42: 0 | H42: 0 | I42: 0 | J42: =SUMPRODUCT(B42:I42,$B$11:$I$11) -> 12
...

Sheet FG
A3: ICRA Schwap e.U.
A4: VERKEHRSZÄHLUNG – Fußgänger/Radfahrer
A5: Datum : | B5: =Deckbl.!I11 -> 45944 | J5: Lfd. Nummer : | K5: =Deckbl.!C10 -> 0
J6: Wetter : | K6: =Deckbl.!I12 -> 9-14 ° sonnig
B7: Verkehrszählung : | C7: =Deckbl.!C8 -> B122 / Badhaller Straße / Holznerweg (Bad Hall)
B8: Zählstelle : | I8: Sachbearbeiter : | J8: =Deckbl.!C12 -> Schwap
B9: Richtung : | I9: Uhrzeit : | J9: =Deckbl.!C11 -> 7-19 Uhr
B10: Bemerkung :
B11: FG A | C11: FG B | D11: FG B | E11: FG D | F11: FG D | J11: FG/R | K11: FG/R | L11: FG/R
A12: Zeit | B12: FG | C12: Rad | D12: FG | E12: Rad | F12: FG | G12: Rad | J12: / 15 min | K12: / 30 min | L12: / 1 Std.
A13: 5:00-5:15 | J13: =SUM(B13:I13) -> 0
A14: 5:15-5:30 | J14: =SUM(B14:I14) -> 0 | K14: =J14+J13 -> 0
A15: 5:30-5:45 | J15: =SUM(B15:I15) -> 0
A16: 5:45-6:00 | J16: =SUM(B16:I16) -> 0 | K16: =J16+J15 -> 0 | L16: =SUM(J13:J16) -> 0
A17: 6:00-6:15 | J17: =SUM(B17:I17) -> 0
A18: 6:15-6:30 | J18: =SUM(B18:I18) -> 0 | K18: =J18+J17 -> 0
A19: 6:30-6:45 | J19: =SUM(B19:I19) -> 0
A20: 6:45-7:00 | J20: =SUM(B20:I20) -> 0 | K20: =J20+J19 -> 0 | L20: =SUM(J17:J20) -> 0
A21: 7:00-7:15 | B21: 11 | C21: 0 | D21: 1 | E21: 0 | F21: 10 | G21: 0 | J21: =SUM(B21:I21) -> 22
A22: 7:15-7:30 | B22: 41 | C22: 0 | D22: 11 | E22: 0 | F22: 2 | G22: 0 | J22: =SUM(B22:I22) -> 54 | K22: =J22+J21 -> 76
A23: 7:30-7:45 | B23: 5 | C23: 2 | D23: 0 | E23: 2 | F23: 5 | G23: 0 | J23: =SUM(B23:I23) -> 14
A24: 7:45-8:00 | B24: 18 | C24: 0 | D24: 1 | E24: 0 | F24: 1 | G24: 0 | J24: =SUM(B24:I24) -> 20 | K24: =J24+J23 -> 34 | L24: =SUM(J21:J24) -> 110
A25: 8:00-8:15 | B25: 1 | C25: 0 | D25: 0 | E25: 0 | F25: 1 | G25: 0 | J25: =SUM(B25:I25) -> 2
A26: 8:15-8:30 | B26: 2 | C26: 0 | D26: 0 | E26: 0 | F26: 0 | G26: 0 | J26: =SUM(B26:I26) -> 2 | K26: =J26+J25 -> 4
